<?xml version="1.0"?>
<robot  name="DIVAR2V" >
 <link  name="base_link" >
  <visual >
   <origin  xyz="0.0338364901739526 -0.00033626459572959 -9.69008007512981E-05"
      rpy="0 0 0" />
   <geometry >
    <cylinder  length="0.05"  radius="0.1" />
   </geometry>
  </visual>
 </link>
 <joint  name="joint1"  type="revolute" >
  <parent  link="base_link" />
  <child  link="link1" />
  <origin  xyz="0 0 0"  rpy="0 0 0" />
  <axis  xyz="0 0 1" />
 </joint>
 <link  name="link1" >
  <inertial >
   <origin  xyz="0 0 0.0924"  rpy="0 0 0" />
   <mass  value="0.586971" />
   <inertia  ixy="0.0"  ixz="0.0"  ixx="0.0018184381145699997"  iyy="0.0002959312125"  iyz="0.0"  izz="0.0018184381145699997" />
  </inertial>
  <visual >
   <origin  xyz="0 0 0.0924"  rpy="0 0 0" />
   <material  name="blue" />
   <geometry >
    <box  size="0.055 0.055 0.1848" />
   </geometry>
  </visual>
 </link>
 <joint  name="joint-joint-1"  type="fixed" >
  <parent  link="link1" />
  <child  link="joint-link-1" />
  <origin  xyz="0 0 0.1848"  rpy="1.5707 0 0" />
  <axis  xyz="1 0 0" />
 </joint>
 <link  name="joint-link-1" >
  <inertial >
   <origin  xyz="0 0 0"  rpy="0 0 0" />
   <mass  value="0.1" />
   <inertia  ixy="0"  ixz="0"  ixx="0"  iyy="0"  iyz="0"  izz="0" />
  </inertial>
  <visual >
   <origin  xyz="0 0 0"  rpy="0 0 0" />
   <material  name="red" />
   <geometry >
    <sphere  radius="0.05" />
   </geometry>
  </visual>
 </link>
 <joint  name="joint2"  type="revolute" >
  <parent  link="link1" />
  <child  link="link2" />
  <origin  xyz="0 0 0.1848"  rpy="1.5707 0 0" />
  <axis  xyz="1 0 0" />
 </joint>
 <link  name="link2" >
  <inertial >
   <origin  xyz="0 0 0.09115"  rpy="0 0 0" />
   <mass  value="0.579030375" />
   <inertia  ixy="0.0"  ixz="0.0"  ixx="0.0017495542712965622"  iyy="0.00029192781406249996"  iyz="0.0"  izz="0.0017495542712965622" />
  </inertial>
  <visual >
   <origin  xyz="0 0 0.09115"  rpy="0 0 0" />
   <material  name="blue" />
   <geometry >
    <box  size="0.055 0.055 0.1823" />
   </geometry>
  </visual>
 </link>
 <joint  name="joint-joint-2"  type="fixed" >
  <parent  link="link2" />
  <child  link="joint-link-2" />
  <origin  xyz="0 0 0.1823"  rpy="1.5707 0 0" />
  <axis  xyz="1 0 0" />
 </joint>
 <link  name="joint-link-2" >
  <inertial >
   <origin  xyz="0 0 0"  rpy="0 0 0" />
   <mass  value="0.1" />
   <inertia  ixy="0"  ixz="0"  ixx="0"  iyy="0"  iyz="0"  izz="0" />
  </inertial>
  <visual >
   <origin  xyz="0 0 0"  rpy="0 0 0" />
   <material  name="red" />
   <geometry >
    <sphere  radius="0.05" />
   </geometry>
  </visual>
 </link>
 <joint  name="joint3"  type="revolute" >
  <parent  link="link2" />
  <child  link="link3" />
  <origin  xyz="0 0 0.1823"  rpy="0 0 0" />
  <axis  xyz="0 0 1" />
 </joint>
 <link  name="link3" >
  <inertial >
   <origin  xyz="0 0 0.09115"  rpy="0 0 0" />
   <mass  value="0.579030375" />
   <inertia  ixy="0.0"  ixz="0.0"  ixx="0.0017495542712965622"  iyy="0.00029192781406249996"  iyz="0.0"  izz="0.0017495542712965622" />
  </inertial>
  <visual >
   <origin  xyz="0 0 0.09115"  rpy="0 0 0" />
   <material  name="blue" />
   <geometry >
    <box  size="0.055 0.055 0.1823" />
   </geometry>
  </visual>
 </link>
 <joint  name="joint-joint-3"  type="fixed" >
  <parent  link="link3" />
  <child  link="joint-link-3" />
  <origin  xyz="0 0 0.1823"  rpy="1.5707 0 0" />
  <axis  xyz="1 0 0" />
 </joint>
 <link  name="joint-link-3" >
  <inertial >
   <origin  xyz="0 0 0"  rpy="0 0 0" />
   <mass  value="0.1" />
   <inertia  ixy="0"  ixz="0"  ixx="0"  iyy="0"  iyz="0"  izz="0" />
  </inertial>
  <visual >
   <origin  xyz="0 0 0"  rpy="0 0 0" />
   <material  name="red" />
   <geometry >
    <sphere  radius="0.05" />
   </geometry>
  </visual>
 </link>
 <joint  name="joint4"  type="revolute" >
  <parent  link="link3" />
  <child  link="link4" />
  <origin  xyz="0 0 0.1823"  rpy="0 0 0" />
  <axis  xyz="0 1 0" />
 </joint>
 <link  name="link4" >
  <inertial >
   <origin  xyz="0 0 0.09"  rpy="0 0 0" />
   <mass  value="0.5717249999999999" />
   <inertia  ixy="0.0"  ixz="0.0"  ixx="0.0016877798437499997"  iyy="0.00028824468749999996"  iyz="0.0"  izz="0.0016877798437499997" />
  </inertial>
  <visual >
   <origin  xyz="0 0 0.09"  rpy="0 0 0" />
   <material  name="blue" />
   <geometry >
    <box  size="0.055 0.055 0.18" />
   </geometry>
  </visual>
 </link>
 <joint  name="joint-joint-4"  type="fixed" >
  <parent  link="link4" />
  <child  link="joint-link-4" />
  <origin  xyz="0 0 0.18"  rpy="1.5707 0 0" />
  <axis  xyz="1 0 0" />
 </joint>
 <link  name="joint-link-4" >
  <inertial >
   <origin  xyz="0 0 0"  rpy="0 0 0" />
   <mass  value="0.1" />
   <inertia  ixy="0"  ixz="0"  ixx="0"  iyy="0"  iyz="0"  izz="0" />
  </inertial>
  <visual >
   <origin  xyz="0 0 0"  rpy="0 0 0" />
   <material  name="red" />
   <geometry >
    <sphere  radius="0.05" />
   </geometry>
  </visual>
 </link>
 <joint  name="joint5"  type="revolute" >
  <parent  link="link4" />
  <child  link="link5" />
  <origin  xyz="0 0 0.18"  rpy="0 0 0" />
  <axis  xyz="0 0 1" />
 </joint>
 <link  name="link5" >
  <inertial >
   <origin  xyz="0 0 0.09"  rpy="0 0 0" />
   <mass  value="0.5717249999999999" />
   <inertia  ixy="0.0"  ixz="0.0"  ixx="0.0016877798437499997"  iyy="0.00028824468749999996"  iyz="0.0"  izz="0.0016877798437499997" />
  </inertial>
  <visual >
   <origin  xyz="0 0 0.09"  rpy="0 0 0" />
   <material  name="blue" />
   <geometry >
    <box  size="0.055 0.055 0.18" />
   </geometry>
  </visual>
 </link>
 <joint  name="joint-joint-5"  type="fixed" >
  <parent  link="link5" />
  <child  link="joint-link-5" />
  <origin  xyz="0 0 0.18"  rpy="1.5707 0 0" />
  <axis  xyz="1 0 0" />
 </joint>
 <link  name="joint-link-5" >
  <inertial >
   <origin  xyz="0 0 0"  rpy="0 0 0" />
   <mass  value="0.1" />
   <inertia  ixy="0"  ixz="0"  ixx="0"  iyy="0"  iyz="0"  izz="0" />
  </inertial>
  <visual >
   <origin  xyz="0 0 0"  rpy="0 0 0" />
   <material  name="red" />
   <geometry >
    <sphere  radius="0.05" />
   </geometry>
  </visual>
 </link>
 <joint  name="joint6"  type="revolute" >
  <parent  link="link5" />
  <child  link="link6" />
  <origin  xyz="0 0 0.18"  rpy="0 0 0" />
  <axis  xyz="0 1 0" />
 </joint>
 <link  name="link6" >
  <inertial >
   <origin  xyz="0 0 0.0005"  rpy="0 0 0" />
   <mass  value="0.0031762500000000003" />
   <inertia  ixy="0.0"  ixz="0.0"  ixx="8.009443750000001e-07"  iyy="1.601359375e-06"  iyz="0.0"  izz="8.009443750000001e-07" />
  </inertial>
  <visual >
   <origin  xyz="0 0 0.0005"  rpy="0 0 0" />
   <material  name="blue" />
   <geometry >
    <box  size="0.055 0.055 0.001" />
   </geometry>
  </visual>
 </link>
 <joint  name="joint7"  type="revolute" >
  <parent  link="link6" />
  <child  link="link7" />
  <origin  xyz="0 0 0.001"  rpy="0 0 0" />
  <axis  xyz="1 0 0" />
 </joint>
 <link  name="link7" >
  <inertial >
   <origin  xyz="0 0 0.1"  rpy="0 0 0" />
   <mass  value="0.6352500000000001" />
   <inertia  ixy="0.0"  ixz="0.0"  ixx="0.0022776359375000005"  iyy="0.00032027187500000004"  iyz="0.0"  izz="0.0022776359375000005" />
  </inertial>
  <visual >
   <origin  xyz="0 0 0.1"  rpy="0 0 0" />
   <material  name="blue" />
   <geometry >
    <box  size="0.055 0.055 0.2" />
   </geometry>
  </visual>
 </link>
 <joint  name="eef_joint"  type="fixed" >
  <parent  link="link7" />
  <child  link="eef" />
  <origin  xyz="0 0 0.2"  rpy="0 0 0" />
 </joint>
 <link  name="eef" />
 <transmission  name="motor1" >
  <type  xmltext="SimpleTransmission" >
   SimpleTransmission
  </type>
  <actuator  name="motor1" >
   <mechanicalreduction  xmltext="1" >
    1
   </mechanicalreduction>
  </actuator>
  <joint  name="joint1" />
 </transmission>
 <transmission  name="motor2" >
  <type  xmltext="SimpleTransmission" >
   SimpleTransmission
  </type>
  <actuator  name="motor2" >
   <mechanicalreduction  xmltext="1" >
    1
   </mechanicalreduction>
  </actuator>
  <joint  name="joint2" />
 </transmission>
 <transmission  name="motor3" >
  <type  xmltext="SimpleTransmission" >
   SimpleTransmission
  </type>
  <actuator  name="motor3" >
   <mechanicalreduction  xmltext="1" >
    1
   </mechanicalreduction>
  </actuator>
  <joint  name="joint3" />
 </transmission>
 <transmission  name="motor4" >
  <type  xmltext="SimpleTransmission" >
   SimpleTransmission
  </type>
  <actuator  name="motor4" >
   <mechanicalreduction  xmltext="1" >
    1
   </mechanicalreduction>
  </actuator>
  <joint  name="joint4" />
 </transmission>
 <transmission  name="motor5" >
  <type  xmltext="SimpleTransmission" >
   SimpleTransmission
  </type>
  <actuator  name="motor5" >
   <mechanicalreduction  xmltext="1" >
    1
   </mechanicalreduction>
  </actuator>
  <joint  name="joint5" />
 </transmission>
 <transmission  name="motor6" >
  <type  xmltext="SimpleTransmission" >
   SimpleTransmission
  </type>
  <actuator  name="motor6" >
   <mechanicalreduction  xmltext="1" >
    1
   </mechanicalreduction>
  </actuator>
  <joint  name="joint6" />
 </transmission>
 <transmission  name="motor7" >
  <type  xmltext="SimpleTransmission" >
   SimpleTransmission
  </type>
  <actuator  name="motor7" >
   <mechanicalreduction  xmltext="1" >
    1
   </mechanicalreduction>
  </actuator>
  <joint  name="joint7" />
 </transmission>
</robot>

<!-- [1.848000e-01 3.646000e-01 5.000000e-01 3.600000e-01 5.000000e-01
 1.600000e+01 3.000000e+01 1.000000e-01 3.000000e+01 1.638995e+02
 4.520000e+00 2.000000e-01 6.460000e+02 6.900000e+07 5.600000e+07]-->
