<?xml version="1.0"?>
<robot  name="divar3v9661517381" >
 <material  name="blue" >
  <color  rgba="0 0 0.8 1.0" />
 </material>
 <material  name="red" >
  <color  rgba="0.8 0 0 1.0" />
 </material>
 <link  name="base_link" >
  <visual >
   <origin  xyz="0 0 0"  rpy="0 0 0" />
   <material  name="red" />
   <geometry >
    <cylinder  length="0.05"  radius="0.1" />
   </geometry>
  </visual>
 </link>
 <joint  name="joint1"  type="revolute" >
  <parent  link="base_link" />
  <child  link="link1" />
  <origin  xyz="0 0 0"  rpy="0 0 0" />
  <axis  xyz="0 0 1" />
 </joint>
 <link  name="link1" >
  <inertial >
   <origin  xyz="0 0 0.10790468880442484"  rpy="0 0 0" />
   <mass  value="0.6854645356301088" />
   <inertia  ixx="0.002833178439193182"  iyy="0.0003455883700468465"  iyz="0.0"  izz="0.002833178439193182"  ixz="0.0"  ixy="0.0" />
  </inertial>
  <visual >
   <origin  xyz="0 0 0.10790468880442484"  rpy="0 0 0" />
   <material  name="blue" />
   <geometry >
    <box  size="0.055 0.055 0.2158093776088497" />
   </geometry>
  </visual>
 </link>
 <joint  name="joint-joint-1"  type="fixed" >
  <parent  link="link1" />
  <child  link="joint-link-1" />
  <origin  xyz="0 0 0.2158093776088497"  rpy="1.5707 0 0" />
  <axis  xyz="1 0 0" />
 </joint>
 <link  name="joint-link-1" >
  <inertial >
   <origin  xyz="0 0 0"  rpy="0 0 0" />
   <mass  value="0.9372241716552034" />
   <inertia  ixx="0"  iyy="0"  iyz="0"  izz="0"  ixz="0"  ixy="0" />
  </inertial>
  <visual >
   <origin  xyz="0 0 0"  rpy="0 0 0" />
   <material  name="red" />
   <geometry >
    <sphere  radius="0.05" />
   </geometry>
  </visual>
 </link>
 <joint  name="joint2"  type="revolute" >
  <parent  link="link1" />
  <child  link="link2" />
  <origin  xyz="0 0 0.2158093776088497"  rpy="1.5707 0 0" />
  <axis  xyz="1 0 0" />
 </joint>
 <link  name="link2" >
  <inertial >
   <origin  xyz="0 0 0.035715301797341246"  rpy="0 0 0" />
   <mass  value="0.22688145466761028" />
   <inertia  ixx="0.00015366172577643467"  iyy="0.00011438606672825351"  iyz="0.0"  izz="0.00015366172577643467"  ixz="0.0"  ixy="0.0" />
  </inertial>
  <visual >
   <origin  xyz="0 0 0.035715301797341246"  rpy="0 0 0" />
   <material  name="blue" />
   <geometry >
    <box  size="0.055 0.055 0.07143060359468249" />
   </geometry>
  </visual>
 </link>
 <joint  name="joint-joint-2"  type="fixed" >
  <parent  link="link2" />
  <child  link="joint-link-2" />
  <origin  xyz="0 0 0.07143060359468249"  rpy="1.5707 0 0" />
  <axis  xyz="1 0 0" />
 </joint>
 <link  name="joint-link-2" >
  <inertial >
   <origin  xyz="0 0 0"  rpy="0 0 0" />
   <mass  value="0.9372241716552034" />
   <inertia  ixx="0"  iyy="0"  iyz="0"  izz="0"  ixz="0"  ixy="0" />
  </inertial>
  <visual >
   <origin  xyz="0 0 0"  rpy="0 0 0" />
   <material  name="red" />
   <geometry >
    <sphere  radius="0.05" />
   </geometry>
  </visual>
 </link>
 <joint  name="joint3"  type="revolute" >
  <parent  link="link2" />
  <child  link="link3" />
  <origin  xyz="0 0 0.07143060359468249"  rpy="0 0 0" />
  <axis  xyz="0 0 1" />
 </joint>
 <link  name="link3" >
  <inertial >
   <origin  xyz="0 0 0.12026267006495213"  rpy="0 0 0" />
   <mass  value="0.7639686115876084" />
   <inertia  ixx="0.003875704394725894"  iyy="0.0003851675083420859"  iyz="0.0"  izz="0.003875704394725894"  ixz="0.0"  ixy="0.0" />
  </inertial>
  <visual >
   <origin  xyz="0 0 0.12026267006495213"  rpy="0 0 0" />
   <material  name="blue" />
   <geometry >
    <box  size="0.055 0.055 0.24052534012990426" />
   </geometry>
  </visual>
 </link>
 <joint  name="joint-joint-3"  type="fixed" >
  <parent  link="link3" />
  <child  link="joint-link-3" />
  <origin  xyz="0 0 0.24052534012990426"  rpy="1.5707 0 0" />
  <axis  xyz="1 0 0" />
 </joint>
 <link  name="joint-link-3" >
  <inertial >
   <origin  xyz="0 0 0"  rpy="0 0 0" />
   <mass  value="0.9372241716552034" />
   <inertia  ixx="0"  iyy="0"  iyz="0"  izz="0"  ixz="0"  ixy="0" />
  </inertial>
  <visual >
   <origin  xyz="0 0 0"  rpy="0 0 0" />
   <material  name="red" />
   <geometry >
    <sphere  radius="0.05" />
   </geometry>
  </visual>
 </link>
 <joint  name="joint4"  type="revolute" >
  <parent  link="link3" />
  <child  link="link4" />
  <origin  xyz="0 0 0.24052534012990426"  rpy="0 0 0" />
  <axis  xyz="0 1 0" />
 </joint>
 <link  name="link4" >
  <inertial >
   <origin  xyz="0 0 0.18248742347492325"  rpy="0 0 0" />
   <mass  value="1.1592513576244499" />
   <inertia  ixx="0.01316055936277153"  iyy="0.0005844558928023268"  iyz="0.0"  izz="0.01316055936277153"  ixz="0.0"  ixy="0.0" />
  </inertial>
  <visual >
   <origin  xyz="0 0 0.18248742347492325"  rpy="0 0 0" />
   <material  name="blue" />
   <geometry >
    <box  size="0.055 0.055 0.3649748469498465" />
   </geometry>
  </visual>
 </link>
 <joint  name="joint-joint-4"  type="fixed" >
  <parent  link="link4" />
  <child  link="joint-link-4" />
  <origin  xyz="0 0 0.3649748469498465"  rpy="1.5707 0 0" />
  <axis  xyz="1 0 0" />
 </joint>
 <link  name="joint-link-4" >
  <inertial >
   <origin  xyz="0 0 0"  rpy="0 0 0" />
   <mass  value="0.9372241716552034" />
   <inertia  ixx="0"  iyy="0"  iyz="0"  izz="0"  ixz="0"  ixy="0" />
  </inertial>
  <visual >
   <origin  xyz="0 0 0"  rpy="0 0 0" />
   <material  name="red" />
   <geometry >
    <sphere  radius="0.05" />
   </geometry>
  </visual>
 </link>
 <joint  name="joint5"  type="revolute" >
  <parent  link="link4" />
  <child  link="link5" />
  <origin  xyz="0 0 0.3649748469498465"  rpy="0 0 0" />
  <axis  xyz="0 0 1" />
 </joint>
 <link  name="link5" >
  <inertial >
   <origin  xyz="0 0 0.03244302679323869"  rpy="0 0 0" />
   <mass  value="0.20609432770404879" />
   <inertia  ixx="0.0001242611391254355"  iyy="0.00010390589021745791"  iyz="0.0"  izz="0.0001242611391254355"  ixz="0.0"  ixy="0.0" />
  </inertial>
  <visual >
   <origin  xyz="0 0 0.03244302679323869"  rpy="0 0 0" />
   <material  name="blue" />
   <geometry >
    <box  size="0.055 0.055 0.06488605358647738" />
   </geometry>
  </visual>
 </link>
 <joint  name="joint-joint-5"  type="fixed" >
  <parent  link="link5" />
  <child  link="joint-link-5" />
  <origin  xyz="0 0 0.06488605358647738"  rpy="1.5707 0 0" />
  <axis  xyz="1 0 0" />
 </joint>
 <link  name="joint-link-5" >
  <inertial >
   <origin  xyz="0 0 0"  rpy="0 0 0" />
   <mass  value="0.9372241716552034" />
   <inertia  ixx="0"  iyy="0"  iyz="0"  izz="0"  ixz="0"  ixy="0" />
  </inertial>
  <visual >
   <origin  xyz="0 0 0"  rpy="0 0 0" />
   <material  name="red" />
   <geometry >
    <sphere  radius="0.05" />
   </geometry>
  </visual>
 </link>
 <joint  name="joint6"  type="revolute" >
  <parent  link="link5" />
  <child  link="link6" />
  <origin  xyz="0 0 0.06488605358647738"  rpy="0 0 0" />
  <axis  xyz="0 1 0" />
 </joint>
 <link  name="link6" >
  <inertial >
   <origin  xyz="0 0 0.0005"  rpy="0 0 0" />
   <mass  value="0.0031762500000000003" />
   <inertia  ixx="8.009443750000001e-07"  iyy="1.601359375e-06"  iyz="0.0"  izz="8.009443750000001e-07"  ixz="0.0"  ixy="0.0" />
  </inertial>
  <visual >
   <origin  xyz="0 0 0.0005"  rpy="0 0 0" />
   <material  name="blue" />
   <geometry >
    <box  size="0.055 0.055 0.001" />
   </geometry>
  </visual>
 </link>
 <joint  name="joint7"  type="revolute" >
  <parent  link="link6" />
  <child  link="link7" />
  <origin  xyz="0 0 0.001"  rpy="0 0 0" />
  <axis  xyz="1 0 0" />
 </joint>
 <link  name="link7" >
  <inertial >
   <origin  xyz="0 0 0.11929518287941701"  rpy="0 0 0" />
   <mass  value="0.7578226492414966" />
   <inertia  ixx="0.003785978552789884"  iyy="0.00038206891899258776"  iyz="0.0"  izz="0.003785978552789884"  ixz="0.0"  ixy="0.0" />
  </inertial>
  <visual >
   <origin  xyz="0 0 0.11929518287941701"  rpy="0 0 0" />
   <material  name="blue" />
   <geometry >
    <box  size="0.055 0.055 0.23859036575883402" />
   </geometry>
  </visual>
 </link>
 <joint  name="eef_joint"  type="fixed" >
  <parent  link="link7" />
  <child  link="eef" />
  <origin  xyz="0 0 0.23859036575883402"  rpy="0 0 0" />
 </joint>
 <link  name="eef" />
 <transmission  name="motor1" >
  <type  xmltext="SimpleTransmission" >
   SimpleTransmission
  </type>
  <actuator  name="motor1" >
   <mechanicalreduction  xmltext="1" >
    1
   </mechanicalreduction>
  </actuator>
  <joint  name="joint1" />
 </transmission>
 <transmission  name="motor2" >
  <type  xmltext="SimpleTransmission" >
   SimpleTransmission
  </type>
  <actuator  name="motor2" >
   <mechanicalreduction  xmltext="1" >
    1
   </mechanicalreduction>
  </actuator>
  <joint  name="joint2" />
 </transmission>
 <transmission  name="motor3" >
  <type  xmltext="SimpleTransmission" >
   SimpleTransmission
  </type>
  <actuator  name="motor3" >
   <mechanicalreduction  xmltext="1" >
    1
   </mechanicalreduction>
  </actuator>
  <joint  name="joint3" />
 </transmission>
 <transmission  name="motor4" >
  <type  xmltext="SimpleTransmission" >
   SimpleTransmission
  </type>
  <actuator  name="motor4" >
   <mechanicalreduction  xmltext="1" >
    1
   </mechanicalreduction>
  </actuator>
  <joint  name="joint4" />
 </transmission>
 <transmission  name="motor5" >
  <type  xmltext="SimpleTransmission" >
   SimpleTransmission
  </type>
  <actuator  name="motor5" >
   <mechanicalreduction  xmltext="1" >
    1
   </mechanicalreduction>
  </actuator>
  <joint  name="joint5" />
 </transmission>
 <transmission  name="motor6" >
  <type  xmltext="SimpleTransmission" >
   SimpleTransmission
  </type>
  <actuator  name="motor6" >
   <mechanicalreduction  xmltext="1" >
    1
   </mechanicalreduction>
  </actuator>
  <joint  name="joint6" />
 </transmission>
 <transmission  name="motor7" >
  <type  xmltext="SimpleTransmission" >
   SimpleTransmission
  </type>
  <actuator  name="motor7" >
   <mechanicalreduction  xmltext="1" >
    1
   </mechanicalreduction>
  </actuator>
  <joint  name="joint7" />
 </transmission>
</robot>

<!-- [  0.21580938   0.31195594   0.22897658   0.4298609    0.84905337
  18.97101604  22.85569175   0.93722417   3.11863433 137.12719684
   4.17731243   0.23859037]-->