<?xml version="1.0"?>
<robot  name="divar3v9127497541" >
 <material  name="blue" >
  <color  rgba="0 0 0.8 1.0" />
 </material>
 <material  name="red" >
  <color  rgba="0.8 0 0 1.0" />
 </material>
 <link  name="base_link" >
  <visual >
   <origin  xyz="0 0 0"  rpy="0 0 0" />
   <material  name="red" />
   <geometry >
    <cylinder  length="0.05"  radius="0.1" />
   </geometry>
  </visual>
 </link>
 <joint  name="joint1"  type="revolute" >
  <parent  link="base_link" />
  <child  link="link1" />
  <origin  xyz="0 0 0"  rpy="0 0 0" />
  <axis  xyz="0 0 1" />
 </joint>
 <link  name="link1" >
  <inertial >
   <origin  xyz="0 0 0.10577803326982663"  rpy="0 0 0" />
   <mass  value="0.6719549563465737" />
   <inertia  iyy="0.0003387772904913975"  iyz="0.0"  ixx="0.002675554927773136"  izz="0.002675554927773136"  ixz="0.0"  ixy="0.0" />
  </inertial>
  <visual >
   <origin  xyz="0 0 0.10577803326982663"  rpy="0 0 0" />
   <material  name="blue" />
   <geometry >
    <box  size="0.055 0.055 0.21155606653965325" />
   </geometry>
  </visual>
 </link>
 <joint  name="joint-joint-1"  type="fixed" >
  <parent  link="link1" />
  <child  link="joint-link-1" />
  <origin  xyz="0 0 0.21155606653965325"  rpy="1.5707 0 0" />
  <axis  xyz="1 0 0" />
 </joint>
 <link  name="joint-link-1" >
  <inertial >
   <origin  xyz="0 0 0"  rpy="0 0 0" />
   <mass  value="0.7537841373340421" />
   <inertia  iyy="0"  iyz="0"  ixx="0"  izz="0"  ixz="0"  ixy="0" />
  </inertial>
  <visual >
   <origin  xyz="0 0 0"  rpy="0 0 0" />
   <material  name="red" />
   <geometry >
    <sphere  radius="0.05" />
   </geometry>
  </visual>
 </link>
 <joint  name="joint2"  type="revolute" >
  <parent  link="link1" />
  <child  link="link2" />
  <origin  xyz="0 0 0.21155606653965325"  rpy="1.5707 0 0" />
  <axis  xyz="1 0 0" />
 </joint>
 <link  name="link2" >
  <inertial >
   <origin  xyz="0 0 0.02399512965293618"  rpy="0 0 0" />
   <mass  value="0.1524290611202771" />
   <inertia  iyy="7.68496516481397e-05"  iyz="0.0"  ixx="6.76793286454988e-05"  izz="6.76793286454988e-05"  ixz="0.0"  ixy="0.0" />
  </inertial>
  <visual >
   <origin  xyz="0 0 0.02399512965293618"  rpy="0 0 0" />
   <material  name="blue" />
   <geometry >
    <box  size="0.055 0.055 0.04799025930587236" />
   </geometry>
  </visual>
 </link>
 <joint  name="joint-joint-2"  type="fixed" >
  <parent  link="link2" />
  <child  link="joint-link-2" />
  <origin  xyz="0 0 0.04799025930587236"  rpy="1.5707 0 0" />
  <axis  xyz="1 0 0" />
 </joint>
 <link  name="joint-link-2" >
  <inertial >
   <origin  xyz="0 0 0"  rpy="0 0 0" />
   <mass  value="0.7537841373340421" />
   <inertia  iyy="0"  iyz="0"  ixx="0"  izz="0"  ixz="0"  ixy="0" />
  </inertial>
  <visual >
   <origin  xyz="0 0 0"  rpy="0 0 0" />
   <material  name="red" />
   <geometry >
    <sphere  radius="0.05" />
   </geometry>
  </visual>
 </link>
 <joint  name="joint3"  type="revolute" >
  <parent  link="link2" />
  <child  link="link3" />
  <origin  xyz="0 0 0.04799025930587236"  rpy="0 0 0" />
  <axis  xyz="0 0 1" />
 </joint>
 <link  name="link3" >
  <inertial >
   <origin  xyz="0 0 0.028210162043195208"  rpy="0 0 0" />
   <mass  value="0.17920505437939757" />
   <inertia  iyy="9.03492149162796e-05"  iyz="0.0"  ixx="9.271252592435789e-05"  izz="9.271252592435789e-05"  ixz="0.0"  ixy="0.0" />
  </inertial>
  <visual >
   <origin  xyz="0 0 0.028210162043195208"  rpy="0 0 0" />
   <material  name="blue" />
   <geometry >
    <box  size="0.055 0.055 0.056420324086390417" />
   </geometry>
  </visual>
 </link>
 <joint  name="joint-joint-3"  type="fixed" >
  <parent  link="link3" />
  <child  link="joint-link-3" />
  <origin  xyz="0 0 0.056420324086390417"  rpy="1.5707 0 0" />
  <axis  xyz="1 0 0" />
 </joint>
 <link  name="joint-link-3" >
  <inertial >
   <origin  xyz="0 0 0"  rpy="0 0 0" />
   <mass  value="0.7537841373340421" />
   <inertia  iyy="0"  iyz="0"  ixx="0"  izz="0"  ixz="0"  ixy="0" />
  </inertial>
  <visual >
   <origin  xyz="0 0 0"  rpy="0 0 0" />
   <material  name="red" />
   <geometry >
    <sphere  radius="0.05" />
   </geometry>
  </visual>
 </link>
 <joint  name="joint4"  type="revolute" >
  <parent  link="link3" />
  <child  link="link4" />
  <origin  xyz="0 0 0.056420324086390417"  rpy="0 0 0" />
  <axis  xyz="0 1 0" />
 </joint>
 <link  name="link4" >
  <inertial >
   <origin  xyz="0 0 0.12422282850759041"  rpy="0 0 0" />
   <mass  value="0.7891255180944681" />
   <inertia  iyy="0.00039785078203929426"  iyz="0.0"  ixx="0.0042580058524734855"  izz="0.0042580058524734855"  ixz="0.0"  ixy="0.0" />
  </inertial>
  <visual >
   <origin  xyz="0 0 0.12422282850759041"  rpy="0 0 0" />
   <material  name="blue" />
   <geometry >
    <box  size="0.055 0.055 0.24844565701518082" />
   </geometry>
  </visual>
 </link>
 <joint  name="joint-joint-4"  type="fixed" >
  <parent  link="link4" />
  <child  link="joint-link-4" />
  <origin  xyz="0 0 0.24844565701518082"  rpy="1.5707 0 0" />
  <axis  xyz="1 0 0" />
 </joint>
 <link  name="joint-link-4" >
  <inertial >
   <origin  xyz="0 0 0"  rpy="0 0 0" />
   <mass  value="0.7537841373340421" />
   <inertia  iyy="0"  iyz="0"  ixx="0"  izz="0"  ixz="0"  ixy="0" />
  </inertial>
  <visual >
   <origin  xyz="0 0 0"  rpy="0 0 0" />
   <material  name="red" />
   <geometry >
    <sphere  radius="0.05" />
   </geometry>
  </visual>
 </link>
 <joint  name="joint5"  type="revolute" >
  <parent  link="link4" />
  <child  link="link5" />
  <origin  xyz="0 0 0.24844565701518082"  rpy="0 0 0" />
  <axis  xyz="0 0 1" />
 </joint>
 <link  name="link5" >
  <inertial >
   <origin  xyz="0 0 0.08349769057866098"  rpy="0 0 0" />
   <mass  value="0.5304190794009439" />
   <inertia  iyy="0.00026741961919797585"  iyz="0.0"  ixx="0.0013663797631562223"  izz="0.0013663797631562223"  ixz="0.0"  ixy="0.0" />
  </inertial>
  <visual >
   <origin  xyz="0 0 0.08349769057866098"  rpy="0 0 0" />
   <material  name="blue" />
   <geometry >
    <box  size="0.055 0.055 0.16699538115732196" />
   </geometry>
  </visual>
 </link>
 <joint  name="joint-joint-5"  type="fixed" >
  <parent  link="link5" />
  <child  link="joint-link-5" />
  <origin  xyz="0 0 0.16699538115732196"  rpy="1.5707 0 0" />
  <axis  xyz="1 0 0" />
 </joint>
 <link  name="joint-link-5" >
  <inertial >
   <origin  xyz="0 0 0"  rpy="0 0 0" />
   <mass  value="0.7537841373340421" />
   <inertia  iyy="0"  iyz="0"  ixx="0"  izz="0"  ixz="0"  ixy="0" />
  </inertial>
  <visual >
   <origin  xyz="0 0 0"  rpy="0 0 0" />
   <material  name="red" />
   <geometry >
    <sphere  radius="0.05" />
   </geometry>
  </visual>
 </link>
 <joint  name="joint6"  type="revolute" >
  <parent  link="link5" />
  <child  link="link6" />
  <origin  xyz="0 0 0.16699538115732196"  rpy="0 0 0" />
  <axis  xyz="0 1 0" />
 </joint>
 <link  name="link6" >
  <inertial >
   <origin  xyz="0 0 0.0005"  rpy="0 0 0" />
   <mass  value="0.0031762500000000003" />
   <inertia  iyy="1.601359375e-06"  iyz="0.0"  ixx="8.009443750000001e-07"  izz="8.009443750000001e-07"  ixz="0.0"  ixy="0.0" />
  </inertial>
  <visual >
   <origin  xyz="0 0 0.0005"  rpy="0 0 0" />
   <material  name="blue" />
   <geometry >
    <box  size="0.055 0.055 0.001" />
   </geometry>
  </visual>
 </link>
 <joint  name="joint7"  type="revolute" >
  <parent  link="link6" />
  <child  link="link7" />
  <origin  xyz="0 0 0.001"  rpy="0 0 0" />
  <axis  xyz="1 0 0" />
 </joint>
 <link  name="link7" >
  <inertial >
   <origin  xyz="0 0 0.10750240823038565"  rpy="0 0 0" />
   <mass  value="0.6829090482835248" />
   <inertia  iyy="0.0003442999785096104"  iyz="0.0"  ixx="0.0028028904168168113"  izz="0.0028028904168168113"  ixz="0.0"  ixy="0.0" />
  </inertial>
  <visual >
   <origin  xyz="0 0 0.10750240823038565"  rpy="0 0 0" />
   <material  name="blue" />
   <geometry >
    <box  size="0.055 0.055 0.2150048164607713" />
   </geometry>
  </visual>
 </link>
 <joint  name="eef_joint"  type="fixed" >
  <parent  link="link7" />
  <child  link="eef" />
  <origin  xyz="0 0 0.2150048164607713"  rpy="0 0 0" />
 </joint>
 <link  name="eef" />
 <transmission  name="motor1" >
  <type  xmltext="SimpleTransmission" >
   SimpleTransmission
  </type>
  <actuator  name="motor1" >
   <mechanicalreduction  xmltext="1" >
    1
   </mechanicalreduction>
  </actuator>
  <joint  name="joint1" />
 </transmission>
 <transmission  name="motor2" >
  <type  xmltext="SimpleTransmission" >
   SimpleTransmission
  </type>
  <actuator  name="motor2" >
   <mechanicalreduction  xmltext="1" >
    1
   </mechanicalreduction>
  </actuator>
  <joint  name="joint2" />
 </transmission>
 <transmission  name="motor3" >
  <type  xmltext="SimpleTransmission" >
   SimpleTransmission
  </type>
  <actuator  name="motor3" >
   <mechanicalreduction  xmltext="1" >
    1
   </mechanicalreduction>
  </actuator>
  <joint  name="joint3" />
 </transmission>
 <transmission  name="motor4" >
  <type  xmltext="SimpleTransmission" >
   SimpleTransmission
  </type>
  <actuator  name="motor4" >
   <mechanicalreduction  xmltext="1" >
    1
   </mechanicalreduction>
  </actuator>
  <joint  name="joint4" />
 </transmission>
 <transmission  name="motor5" >
  <type  xmltext="SimpleTransmission" >
   SimpleTransmission
  </type>
  <actuator  name="motor5" >
   <mechanicalreduction  xmltext="1" >
    1
   </mechanicalreduction>
  </actuator>
  <joint  name="joint5" />
 </transmission>
 <transmission  name="motor6" >
  <type  xmltext="SimpleTransmission" >
   SimpleTransmission
  </type>
  <actuator  name="motor6" >
   <mechanicalreduction  xmltext="1" >
    1
   </mechanicalreduction>
  </actuator>
  <joint  name="joint6" />
 </transmission>
 <transmission  name="motor7" >
  <type  xmltext="SimpleTransmission" >
   SimpleTransmission
  </type>
  <actuator  name="motor7" >
   <mechanicalreduction  xmltext="1" >
    1
   </mechanicalreduction>
  </actuator>
  <joint  name="joint7" />
 </transmission>
</robot>

<!-- [ 0.21155607  0.10441058  0.45963022  0.41544104  0.59802868 12.62089596
 12.26665176  0.75378414  7.18629113 53.90103968 17.06780326  0.21500482]-->