<?xml version="1.0"?>
<robot  name="iCub" >
 <link  name="root_link" >
  <inertial >
   <origin  rpy="1.5707963267948961 0 -1.5707963267948961"  xyz="0.02488209999999999 0.00010394699999999017 -0.04408060000000001" />
   <mass  value="5.09143" />
   <inertia  iyz="-0.00170968"  izz="0.0249124"  ixz="-1.55458e-05"  ixx="0.0139679"  ixy="-5.93488e-06"  iyy="0.0202112" />
  </inertial>
  <visual >
   <origin  rpy="1.5707963267948961 0 -1.5707963267948961"  xyz="-0.036399999999999995 0 0.032" />
   <geometry >
    <mesh  filename="./iCubGenova04/meshes/simmechanics/sim_sea_2-5_root_link_prt-binary.stl"  scale="0.001 0.001 0.001" />
   </geometry>
   <material  name="green" >
    <color  rgba="0 1 0 1" />
   </material>
  </visual>
  <collision >
   <origin  rpy="1.5707963267948961 0 -1.5707963267948961"  xyz="-0.036399999999999995 0 0.032" />
   <geometry >
    <mesh  filename="./iCubGenova04/meshes/simmechanics/sim_sea_2-5_root_link_prt-binary.stl"  scale="0.001 0.001 0.001" />
   </geometry>
  </collision>
 </link>
 <link  name="r_hip_1" >
  <inertial >
   <origin  rpy="1.5707963267948961 0 1.5707963267948961"  xyz="-0.000514500000000008 -0.038075299999999986 -7.099999999998774e-05" />
   <mass  value="0.919978" />
   <inertia  iyz="-7.69474e-07"  izz="0.000580025"  ixz="1.11055e-06"  ixx="0.000404268"  ixy="-1.26852e-06"  iyy="0.000574741" />
  </inertial>
  <visual >
   <origin  rpy="1.5707963267948961 0 1.5707963267948961"  xyz="0.04285150000011214 0.025999999999999232 0.1519129999999679" />
   <geometry >
    <mesh  filename="./iCubGenova04/meshes/simmechanics/sim_sea_2-5_r_hip_1_prt-binary.stl"  scale="0.001 0.001 0.001" />
   </geometry>
   <material  name="black" >
    <color  rgba="0 0 0 1" />
   </material>
  </visual>
  <collision >
   <origin  rpy="1.5707963267948961 0 1.5707963267948961"  xyz="0.04285150000011214 0.025999999999999232 0.1519129999999679" />
   <geometry >
    <mesh  filename="./iCubGenova04/meshes/simmechanics/sim_sea_2-5_r_hip_1_prt-binary.stl"  scale="0.001 0.001 0.001" />
   </geometry>
  </collision>
 </link>
 <joint  type="revolute"  name="r_hip_pitch" >
  <origin  rpy="0 0 -3.141592653589793"  xyz="0.006451499999999992 0.025999999999999968 -0.11991299999999999" />
  <axis  xyz="-2.220446049250313e-16 -0.9999999999999998 0.0" />
  <parent  link="root_link" />
  <child  link="r_hip_1" />
  <limit  velocity="5.1"  lower="-0.7853981633974483"  upper="2.3387411976724017"  effort="55.5" />
  <dynamics  damping="0.223"  friction="0.0" />
 </joint>
 <link  name="r_hip_2" >
  <inertial >
   <origin  rpy="1.5707963267948961 0 1.5707963267948961"  xyz="-0.0009315000000000018 8.09999999998312e-06 -0.04480899999999996" />
   <mass  value="0.413242" />
   <inertia  iyz="3.3401e-06"  izz="0.000303891"  ixz="7.12496e-08"  ixx="0.00046914"  ixy="-4.76597e-08"  iyy="0.000277108" />
  </inertial>
  <visual >
   <origin  rpy="1.5707963267948961 0 1.5707963267948961"  xyz="0.04285149980937101 0.07010000000000424 0.15191299999996632" />
   <geometry >
    <mesh  filename="./iCubGenova04/meshes/simmechanics/sim_sea_2-5_r_hip_2_prt-binary.stl"  scale="0.001 0.001 0.001" />
   </geometry>
   <material  name="red" >
    <color  rgba="1 0 0 1" />
   </material>
  </visual>
  <collision >
   <origin  rpy="1.5707963267948961 0 1.5707963267948961"  xyz="0.04285149980937101 0.07010000000000424 0.15191299999996632" />
   <geometry >
    <mesh  filename="./iCubGenova04/meshes/simmechanics/sim_sea_2-5_r_hip_2_prt-binary.stl"  scale="0.001 0.001 0.001" />
   </geometry>
  </collision>
 </link>
 <joint  type="revolute"  name="r_hip_roll" >
  <origin  rpy="0 0 0"  xyz="0 -0.04409999999999998 0" />
  <axis  xyz="-0.9999999999999998 0.0 -2.220446049250313e-16" />
  <parent  link="r_hip_1" />
  <child  link="r_hip_2" />
  <limit  velocity="7.64"  lower="-0.3490658503988659"  upper="2.0943951023931953"  effort="37.0" />
  <dynamics  damping="0.223"  friction="0.0" />
 </joint>
 <link  name="r_hip_3" >
  <inertial >
   <origin  rpy="-1.5707963267948961 0 -1.5707963267948961"  xyz="-0.00012300000000000505 -0.0002822999999999992 0.008718000000000031" />
   <mass  value="0.126212" />
   <inertia  iyz="3.32338e-08"  izz="3.26449e-05"  ixz="-4.41463e-09"  ixx="3.27938e-05"  ixy="2.67901e-07"  iyy="5.69957e-05" />
  </inertial>
  <visual >
   <origin  rpy="-1.5707963267948961 0 -1.5707963267948961"  xyz="0.0437090152 -0.07009999189999992 -0.22621299999996644" />
   <geometry >
    <mesh  filename="./iCubGenova04/meshes/simmechanics/sim_sea_2-5_r_upper_thigh_prt-binary.stl"  scale="0.001 0.001 0.001" />
   </geometry>
   <material  name="blue" >
    <color  rgba="0 0 1 1" />
   </material>
  </visual>
  <collision >
   <origin  rpy="-1.5707963267948961 0 -1.5707963267948961"  xyz="0.0437090152 -0.07009999189999992 -0.22621299999996644" />
   <geometry >
    <mesh  filename="./iCubGenova04/meshes/simmechanics/sim_sea_2-5_r_upper_thigh_prt-binary.stl"  scale="0.001 0.001 0.001" />
   </geometry>
  </collision>
 </link>
 <joint  type="fixed"  name="r_leg_ft_sensor" >
  <origin  rpy="3.141592653589793 0 0"  xyz="-0.0009362999999999941 1.3899999999969492e-05 -0.07429999999999995" />
  <parent  link="r_hip_2" />
  <child  link="r_hip_3" />
  <dynamics  damping="0.1" />
 </joint>
 <link  name="r_upper_leg" >
  <inertial >
   <origin  rpy="1.5707963267948961 0 1.5707963267948961"  xyz="0.0033999999999999933 -2.9100000000018e-05 -0.078954" />
   <mass  value="1.8035" />
   <inertia  iyz="-0.0001366130868747447"  izz="0.006467208238130081"  ixz="5.482050947393938e-06"  ixx="0.006477514229987116"  ixy="0.0001295794295884975"  iyy="0.0014593786411035647" />
  </inertial>
  <visual >
   <origin  rpy="1.5707963267948961 0 1.5707963267948961"  xyz="0.0437090152 0.07009999190000003 0.24081299999999994" />
   <geometry >
    <mesh  filename="./iCubGenova04/meshes/simmechanics/sim_sea_2-5_r_thigh_prt-binary.stl"  scale="0.001 0.001 0.001" />
   </geometry>
   <material  name="yellow" >
    <color  rgba="1 1 0 1" />
   </material>
  </visual>
  <collision >
   <origin  rpy="1.5707963267948961 0 1.5707963267948961"  xyz="0.0437090152 0.07009999190000003 0.24081299999999994" />
   <geometry >
    <mesh  filename="./iCubGenova04/meshes/simmechanics/sim_sea_2-5_r_thigh_prt-binary.stl"  scale="0.001 0.001 0.001" />
   </geometry>
  </collision>
 </link>
 <joint  type="revolute"  name="r_hip_yaw" >
  <origin  rpy="-3.141592653589793 0 0"  xyz="0 0 0.014399999999999996" />
  <axis  xyz="0.0 -2.220446049250313e-16 -0.9999999999999998" />
  <parent  link="r_hip_3" />
  <child  link="r_upper_leg" />
  <limit  velocity="7.64"  lower="-1.3962634015954636"  upper="1.3962634015954636"  effort="37.0" />
  <dynamics  damping="0.223"  friction="0.0" />
 </joint>
 <link  name="r_upper_leg_back_contact" />
 <joint  type="fixed"  name="r_upper_leg_back_contact_fixed_joint" >
  <origin  rpy="0 1.5707963267948963 0"  xyz="-0.051199800000000004 0 0.014599999999999946" />
  <parent  link="r_upper_leg" />
  <child  link="r_upper_leg_back_contact" />
  <dynamics  damping="0.1" />
 </joint>
 <link  name="r_upper_leg_dh_frame" />
 <joint  type="fixed"  name="r_upper_leg_dh_frame_fixed_joint" >
  <origin  rpy="1.5707963267948966 0 0"  xyz="0 0 -0.14582499999999995" />
  <parent  link="r_upper_leg" />
  <child  link="r_upper_leg_dh_frame" />
  <dynamics  damping="0.1" />
 </joint>
 <link  name="r_lower_leg" >
  <inertial >
   <origin  rpy="1.5707963267948961 0 1.5707963267948961"  xyz="0.0012363999999999917 -0.003513100000000033 -0.08879400000000004" />
   <mass  value="1.472" />
   <inertia  iyz="-0.0002641329792432387"  izz="0.004573585842061655"  ixz="-5.556464594531433e-05"  ixx="0.00423993167477533"  ixy="0.00022881454885381036"  iyy="0.0015209504344685463" />
  </inertial>
  <visual >
   <origin  rpy="1.5707963267948961 0 1.5707963267948961"  xyz="0.0437090152 0.07009999200000007 0.38663799999999987" />
   <geometry >
    <mesh  filename="./iCubGenova04/meshes/simmechanics/sim_sea_2-5_r_shank_prt-binary.stl"  scale="0.001 0.001 0.001" />
   </geometry>
   <material  name="pink" >
    <color  rgba="1 0 1 1" />
   </material>
  </visual>
  <collision >
   <origin  rpy="1.5707963267948961 0 1.5707963267948961"  xyz="0.0437090152 0.07009999200000007 0.38663799999999987" />
   <geometry >
    <mesh  filename="./iCubGenova04/meshes/simmechanics/sim_sea_2-5_r_shank_prt-binary.stl"  scale="0.001 0.001 0.001" />
   </geometry>
  </collision>
 </link>
 <joint  type="revolute"  name="r_knee" >
  <origin  rpy="0 0 0"  xyz="0 0 -0.14582499999999995" />
  <axis  xyz="-2.220446049250313e-16 -0.9999999999999998 0.0" />
  <parent  link="r_upper_leg" />
  <child  link="r_lower_leg" />
  <limit  velocity="7.64"  lower="-2.1642082724729685"  upper="0.06981317007977318"  effort="37.0" />
  <dynamics  damping="0.223"  friction="0.0" />
 </joint>
 <link  name="r_lower_leg_skin_0" />
 <joint  type="fixed"  name="r_lower_leg_skin_0_fixed_joint" >
  <origin  rpy="2.0917380908554746e-06 -1.4153067624694633 2.48648458622082"  xyz="0.05441169999999998 -0.03121489999999999 -0.002634000000000025" />
  <parent  link="r_lower_leg" />
  <child  link="r_lower_leg_skin_0" />
  <dynamics  damping="0.1" />
 </joint>
 <link  name="r_lower_leg_skin_3" />
 <joint  type="fixed"  name="r_lower_leg_skin_3_fixed_joint" >
  <origin  rpy="0 -1.4295105408285231 -2.3039148418553874"  xyz="0.05157878999999999 0.030420499999999996 -0.0028429999999999844" />
  <parent  link="r_lower_leg" />
  <child  link="r_lower_leg_skin_3" />
  <dynamics  damping="0.1" />
 </joint>
 <link  name="r_lower_leg_skin_4" />
 <joint  type="fixed"  name="r_lower_leg_skin_4_fixed_joint" >
  <origin  rpy="-2.9863636151870843e-07 -1.256367488755018 -2.758923800870981"  xyz="0.05831029999999999 0.016783599999999996 0.007272000000000001" />
  <parent  link="r_lower_leg" />
  <child  link="r_lower_leg_skin_4" />
  <dynamics  damping="0.1" />
 </joint>
 <link  name="r_lower_leg_skin_5" />
 <joint  type="fixed"  name="r_lower_leg_skin_5_fixed_joint" >
  <origin  rpy="0 -1.3865221506831833 -3.1414716980716264"  xyz="0.06365039999999998 0.00030939999999998746 -0.0019720000000000293" />
  <parent  link="r_lower_leg" />
  <child  link="r_lower_leg_skin_5" />
  <dynamics  damping="0.1" />
 </joint>
 <link  name="r_lower_leg_skin_6" />
 <joint  type="fixed"  name="r_lower_leg_skin_6_fixed_joint" >
  <origin  rpy="-3.1415892795257605 -1.4678512341064953 0.8374928890768593"  xyz="0.05208553999999999 0.03044339999999999 -0.022148999999999974" />
  <parent  link="r_lower_leg" />
  <child  link="r_lower_leg_skin_6" />
  <dynamics  damping="0.1" />
 </joint>
 <link  name="r_lower_leg_skin_9" />
 <joint  type="fixed"  name="r_lower_leg_skin_9_fixed_joint" >
  <origin  rpy="-3.1415920235620423 -1.3422475532506952 0.37929447771782354"  xyz="0.05982139999999998 0.01679719999999999 -0.03096199999999999" />
  <parent  link="r_lower_leg" />
  <child  link="r_lower_leg_skin_9" />
  <dynamics  damping="0.1" />
 </joint>
 <link  name="r_lower_leg_skin_10" />
 <joint  type="fixed"  name="r_lower_leg_skin_10_fixed_joint" >
  <origin  rpy="3.141592653553929 -1.4709580354104241 0.00043002167526072775"  xyz="0.06446069999999998 0.00034239999999997883 -0.021204999999999974" />
  <parent  link="r_lower_leg" />
  <child  link="r_lower_leg_skin_10" />
  <dynamics  damping="0.1" />
 </joint>
 <link  name="r_lower_leg_skin_11" />
 <joint  type="fixed"  name="r_lower_leg_skin_11_fixed_joint" >
  <origin  rpy="-3.1415921825227295 -1.32811804060386 -0.27213836787954737"  xyz="0.060710799999999975 -0.016091600000000025 -0.030884999999999996" />
  <parent  link="r_lower_leg" />
  <child  link="r_lower_leg_skin_11" />
  <dynamics  damping="0.1" />
 </joint>
 <link  name="r_lower_leg_skin_14" />
 <joint  type="fixed"  name="r_lower_leg_skin_14_fixed_joint" >
  <origin  rpy="-3.141591818848249 -1.4650273563521197 -0.6540334071673023"  xyz="0.05504769999999998 -0.031175900000000006 -0.02190000000000003" />
  <parent  link="r_lower_leg" />
  <child  link="r_lower_leg_skin_14" />
  <dynamics  damping="0.1" />
 </joint>
 <link  name="r_lower_leg_skin_15" />
 <joint  type="fixed"  name="r_lower_leg_skin_15_fixed_joint" >
  <origin  rpy="4.274842569949443e-07 -1.2520363307607896 2.8679885947088186"  xyz="0.05917079999999998 -0.016178800000000007 0.0072429999999999994" />
  <parent  link="r_lower_leg" />
  <child  link="r_lower_leg_skin_15" />
  <dynamics  damping="0.1" />
 </joint>
 <link  name="r_lower_leg_skin_16" />
 <joint  type="fixed"  name="r_lower_leg_skin_16_fixed_joint" >
  <origin  rpy="1.3307591512293707e-05 -1.5326085351498482 1.9628024283508803"  xyz="0.027287599999999978 -0.050286899999999995 -0.004549000000000025" />
  <parent  link="r_lower_leg" />
  <child  link="r_lower_leg_skin_16" />
  <dynamics  damping="0.1" />
 </joint>
 <link  name="r_lower_leg_skin_17" />
 <joint  type="fixed"  name="r_lower_leg_skin_17_fixed_joint" >
  <origin  rpy="-3.141564526201752 -1.563662402374811 -1.1802250875588731"  xyz="0.027874999999999976 -0.05031190000000001 -0.023882000000000014" />
  <parent  link="r_lower_leg" />
  <child  link="r_lower_leg_skin_17" />
  <dynamics  damping="0.1" />
 </joint>
 <link  name="r_lower_leg_skin_19" />
 <joint  type="fixed"  name="r_lower_leg_skin_19_fixed_joint" >
  <origin  rpy="-8.908777174257102e-07 -1.4349869697782824 -2.1586361801672447"  xyz="0.03575341 0.041062799999999997 0.006064999999999987" />
  <parent  link="r_lower_leg" />
  <child  link="r_lower_leg_skin_19" />
  <dynamics  damping="0.1" />
 </joint>
 <link  name="r_lower_leg_skin_20" />
 <joint  type="fixed"  name="r_lower_leg_skin_20_fixed_joint" >
  <origin  rpy="-3.2055654966350685e-06 -1.5001551303072314 -1.8675509241250097"  xyz="0.0234419 0.047990799999999986 -0.004952000000000012" />
  <parent  link="r_lower_leg" />
  <child  link="r_lower_leg_skin_20" />
  <dynamics  damping="0.1" />
 </joint>
 <link  name="r_lower_leg_skin_21" />
 <joint  type="fixed"  name="r_lower_leg_skin_21_fixed_joint" >
  <origin  rpy="2.2967114955750172e-05 -1.5554551388057172 -1.8741197231626954"  xyz="0.024270400000000004 0.04853779999999998 -0.024276999999999993" />
  <parent  link="r_lower_leg" />
  <child  link="r_lower_leg_skin_21" />
  <dynamics  damping="0.1" />
 </joint>
 <link  name="r_lower_leg_skin_28" />
 <joint  type="fixed"  name="r_lower_leg_skin_28_fixed_joint" >
  <origin  rpy="3.1415808886539165 -1.5225246216918655 -0.9296810297631274"  xyz="0.04087215999999998 -0.0424399 -0.03275600000000001" />
  <parent  link="r_lower_leg" />
  <child  link="r_lower_leg_skin_28" />
  <dynamics  damping="0.1" />
 </joint>
 <link  name="r_lower_leg_skin_29" />
 <joint  type="fixed"  name="r_lower_leg_skin_29_fixed_joint" >
  <origin  rpy="3.1415801704422774 -1.5342984156258153 -0.9154363466305139"  xyz="0.03846637999999998 -0.04351590000000001 -0.05242000000000002" />
  <parent  link="r_lower_leg" />
  <child  link="r_lower_leg_skin_29" />
  <dynamics  damping="0.1" />
 </joint>
 <link  name="r_lower_leg_skin_31" />
 <joint  type="fixed"  name="r_lower_leg_skin_31_fixed_joint" >
  <origin  rpy="-6.583817471389409e-07 -1.4186494462021593 2.2085303298592955"  xyz="0.03914639999999998 -0.042270899999999986 0.006327000000000027" />
  <parent  link="r_lower_leg" />
  <child  link="r_lower_leg_skin_31" />
  <dynamics  damping="0.1" />
 </joint>
 <link  name="r_lower_leg_skin_32" />
 <joint  type="fixed"  name="r_lower_leg_skin_32_fixed_joint" >
  <origin  rpy="-3.141590149878832 -1.5223828979770995 0.6459403808870791"  xyz="0.045983029999999994 0.03258469999999997 -0.080733" />
  <parent  link="r_lower_leg" />
  <child  link="r_lower_leg_skin_32" />
  <dynamics  damping="0.1" />
 </joint>
 <link  name="r_lower_leg_skin_35" />
 <joint  type="fixed"  name="r_lower_leg_skin_35_fixed_joint" >
  <origin  rpy="-3.1415866827530436 -1.517584673322529 -0.541532486468427"  xyz="0.04774867999999998 -0.031231900000000007 -0.08011299999999999" />
  <parent  link="r_lower_leg" />
  <child  link="r_lower_leg_skin_35" />
  <dynamics  damping="0.1" />
 </joint>
 <link  name="r_lower_leg_skin_36" />
 <joint  type="fixed"  name="r_lower_leg_skin_36_fixed_joint" >
  <origin  rpy="-3.141590341443774 -1.5158726528065043 -0.20740733566009956"  xyz="0.05322409999999998 -0.015601800000000027 -0.088362" />
  <parent  link="r_lower_leg" />
  <child  link="r_lower_leg_skin_36" />
  <dynamics  damping="0.1" />
 </joint>
 <link  name="r_lower_leg_skin_37" />
 <joint  type="fixed"  name="r_lower_leg_skin_37_fixed_joint" >
  <origin  rpy="-3.1415818045233417 -1.5231833689799856 0.007524505830633038"  xyz="0.055257199999999985 0.0009643999999999764 -0.078318" />
  <parent  link="r_lower_leg" />
  <child  link="r_lower_leg_skin_37" />
  <dynamics  damping="0.1" />
 </joint>
 <link  name="r_lower_leg_skin_38" />
 <joint  type="fixed"  name="r_lower_leg_skin_38_fixed_joint" >
  <origin  rpy="3.1415866519890936 -1.515729955403707 -0.5421535995897704"  xyz="0.04880468999999998 -0.03126290000000001 -0.060757000000000005" />
  <parent  link="r_lower_leg" />
  <child  link="r_lower_leg_skin_38" />
  <dynamics  damping="0.1" />
 </joint>
 <link  name="r_lower_leg_skin_41" />
 <joint  type="fixed"  name="r_lower_leg_skin_41_fixed_joint" >
  <origin  rpy="-3.1415919882511 -1.4068134359704096 -0.24823308941290081"  xyz="0.05660089999999998 -0.015912900000000008 -0.049853999999999954" />
  <parent  link="r_lower_leg" />
  <child  link="r_lower_leg_skin_41" />
  <dynamics  damping="0.1" />
 </joint>
 <link  name="r_lower_leg_skin_42" />
 <joint  type="fixed"  name="r_lower_leg_skin_42_fixed_joint" >
  <origin  rpy="3.14158970239263 -1.4352475041611767 0.006879436515041273"  xyz="0.05701059999999998 0.000796199999999983 -0.059079999999999966" />
  <parent  link="r_lower_leg" />
  <child  link="r_lower_leg_skin_42" />
  <dynamics  damping="0.1" />
 </joint>
 <link  name="r_lower_leg_skin_43" />
 <joint  type="fixed"  name="r_lower_leg_skin_43_fixed_joint" >
  <origin  rpy="-3.1415913662061943 -1.5384303823718677 0.6242175236666732"  xyz="0.04712543999999999 0.03236529999999998 -0.06136200000000003" />
  <parent  link="r_lower_leg" />
  <child  link="r_lower_leg_skin_43" />
  <dynamics  damping="0.1" />
 </joint>
 <link  name="r_lower_leg_skin_46" />
 <joint  type="fixed"  name="r_lower_leg_skin_46_fixed_joint" >
  <origin  rpy="-3.141589878093782 -1.4275988160283246 0.3256077108756132"  xyz="0.05581569999999999 0.01721639999999998 -0.05018" />
  <parent  link="r_lower_leg" />
  <child  link="r_lower_leg_skin_46" />
  <dynamics  damping="0.1" />
 </joint>
 <link  name="r_lower_leg_skin_47" />
 <joint  type="fixed"  name="r_lower_leg_skin_47_fixed_joint" >
  <origin  rpy="3.141589635185022 -1.51690559405793 0.26264042505775587"  xyz="0.052641649999999984 0.017638799999999975 -0.08886" />
  <parent  link="r_lower_leg" />
  <child  link="r_lower_leg_skin_47" />
  <dynamics  damping="0.1" />
 </joint>
 <link  name="r_lower_leg_skin_49" />
 <joint  type="fixed"  name="r_lower_leg_skin_49_fixed_joint" >
  <origin  rpy="-3.141589347506919 -1.489961356950246 0.729763592113092"  xyz="0.04113139 0.03243849999999996 -0.138859" />
  <parent  link="r_lower_leg" />
  <child  link="r_lower_leg_skin_49" />
  <dynamics  damping="0.1" />
 </joint>
 <link  name="r_lower_leg_skin_50" />
 <joint  type="fixed"  name="r_lower_leg_skin_50_fixed_joint" >
  <origin  rpy="3.1415906959631426 -1.4990073263616448 0.6957840200808761"  xyz="0.04301696299999999 0.03252729999999997 -0.11946899999999999" />
  <parent  link="r_lower_leg" />
  <child  link="r_lower_leg_skin_50" />
  <dynamics  damping="0.1" />
 </joint>
 <link  name="r_lower_leg_skin_51" />
 <joint  type="fixed"  name="r_lower_leg_skin_51_fixed_joint" >
  <origin  rpy="-3.141588901786459 -1.5062847571686897 0.27207993571349487"  xyz="0.05141583999999999 0.01775899999999997 -0.10820600000000002" />
  <parent  link="r_lower_leg" />
  <child  link="r_lower_leg_skin_51" />
  <dynamics  damping="0.1" />
 </joint>
 <link  name="r_lower_leg_skin_52" />
 <joint  type="fixed"  name="r_lower_leg_skin_52_fixed_joint" >
  <origin  rpy="-3.1415916404202857 -1.5031867442105085 0.010871726099418466"  xyz="0.052998339999999984 0.001266399999999973 -0.11689500000000003" />
  <parent  link="r_lower_leg" />
  <child  link="r_lower_leg_skin_52" />
  <dynamics  damping="0.1" />
 </joint>
 <link  name="r_lower_leg_skin_53" />
 <joint  type="fixed"  name="r_lower_leg_skin_53_fixed_joint" >
  <origin  rpy="3.1415906398667093 -1.5059530744712215 -0.21140732289166783"  xyz="0.05207313999999998 -0.015433900000000028 -0.10765399999999997" />
  <parent  link="r_lower_leg" />
  <child  link="r_lower_leg_skin_53" />
  <dynamics  damping="0.1" />
 </joint>
 <link  name="r_lower_leg_skin_54" />
 <joint  type="fixed"  name="r_lower_leg_skin_54_fixed_joint" >
  <origin  rpy="3.141588251928216 -1.4974514557145624 -0.5751153744726872"  xyz="0.045127099999999976 -0.03074890000000001 -0.11878700000000003" />
  <parent  link="r_lower_leg" />
  <child  link="r_lower_leg_skin_54" />
  <dynamics  damping="0.1" />
 </joint>
 <link  name="r_lower_leg_skin_55" />
 <joint  type="fixed"  name="r_lower_leg_skin_55_fixed_joint" >
  <origin  rpy="3.1415890648626297 -1.4899578703820784 -0.5972199437885269"  xyz="0.04350267899999998 -0.030488900000000027 -0.13814300000000007" />
  <parent  link="r_lower_leg" />
  <child  link="r_lower_leg_skin_55" />
  <dynamics  damping="0.1" />
 </joint>
 <link  name="r_lower_leg_skin_56" />
 <joint  type="fixed"  name="r_lower_leg_skin_56_fixed_joint" >
  <origin  rpy="-3.141589204039199 -1.491248198275157 -0.22348447640041147"  xyz="0.049268409999999985 -0.015121000000000037 -0.1462179999999999" />
  <parent  link="r_lower_leg" />
  <child  link="r_lower_leg_skin_56" />
  <dynamics  damping="0.1" />
 </joint>
 <link  name="r_lower_leg_skin_60" />
 <joint  type="fixed"  name="r_lower_leg_skin_60_fixed_joint" >
  <origin  rpy="-3.141591733372508 -1.4898596852742692 0.3029518719544257"  xyz="0.04836967999999999 0.018055999999999968 -0.14693799999999996" />
  <parent  link="r_lower_leg" />
  <child  link="r_lower_leg_skin_60" />
  <dynamics  damping="0.1" />
 </joint>
 <link  name="r_lower_leg_skin_61" />
 <joint  type="fixed"  name="r_lower_leg_skin_61_fixed_joint" >
  <origin  rpy="-3.141591009251115 -1.4960209708613401 0.013201427520491136"  xyz="0.051619539999999985 0.0014265999999999723 -0.13616899999999993" />
  <parent  link="r_lower_leg" />
  <child  link="r_lower_leg_skin_61" />
  <dynamics  damping="0.1" />
 </joint>
 <link  name="r_ankle_1" >
  <inertial >
   <origin  rpy="1.5707963267948961 0 1.5707963267948961"  xyz="0.01514359999999999 -0.000868600000000011 4.199999999998649e-05" />
   <mass  value="0.6803" />
   <inertia  iyz="2.5726697409005395e-06"  izz="0.00030823593913944066"  ixz="-3.013494676905822e-05"  ixx="0.0004046188489317631"  ixy="7.498192869450776e-07"  iyy="0.00044863365466369986" />
  </inertial>
  <visual >
   <origin  rpy="1.5707963267948961 0 1.5707963267948961"  xyz="0.0437090152 0.07009999200000011 0.5871379999999998" />
   <geometry >
    <mesh  filename="./iCubGenova04/meshes/simmechanics/sim_sea_2-5_r_ankle_prt-binary.stl"  scale="0.001 0.001 0.001" />
   </geometry>
   <material  name="cyan" >
    <color  rgba="0 1 1 1" />
   </material>
  </visual>
  <collision >
   <origin  rpy="1.5707963267948961 0 1.5707963267948961"  xyz="0.0437090152 0.07009999200000011 0.5871379999999998" />
   <geometry >
    <mesh  filename="./iCubGenova04/meshes/simmechanics/sim_sea_2-5_r_ankle_prt-binary.stl"  scale="0.001 0.001 0.001" />
   </geometry>
  </collision>
 </link>
 <joint  type="revolute"  name="r_ankle_pitch" >
  <origin  rpy="0 0 0"  xyz="0 0 -0.20049999999999996" />
  <axis  xyz="2.220446049250313e-16 0.9999999999999998 0.0" />
  <parent  link="r_lower_leg" />
  <child  link="r_ankle_1" />
  <limit  velocity="7.64"  lower="-0.6108652381980153"  upper="0.6108652381980153"  effort="37.0" />
  <dynamics  damping="0.223"  friction="0.0" />
 </joint>
 <link  name="r_ankle_2" >
  <inertial >
   <origin  rpy="1.5707963267948961 0 1.5707963267948961"  xyz="0.0011445999999999956 3.599999999992498e-06 -0.03852" />
   <mass  value="0.265122" />
   <inertia  iyz="-4.29975e-06"  izz="0.000150937"  ixz="4.94571e-08"  ixx="0.000327222"  ixy="-4.74606e-08"  iyy="0.000248285" />
  </inertial>
  <visual >
   <origin  rpy="1.5707963267948961 0 1.5707963267948961"  xyz="0.043787799618642 0.07008610019070811 0.5871379999999998" />
   <geometry >
    <mesh  filename="./iCubGenova04/meshes/simmechanics/sim_sea_2-5_r_foot_prt-binary.stl"  scale="0.001 0.001 0.001" />
   </geometry>
   <material  name="green" >
    <color  rgba="0 1 0 1" />
   </material>
  </visual>
  <collision >
   <origin  rpy="1.5707963267948961 0 1.5707963267948961"  xyz="0.043787799618642 0.07008610019070811 0.5871379999999998" />
   <geometry >
    <mesh  filename="./iCubGenova04/meshes/simmechanics/sim_sea_2-5_r_foot_prt-binary.stl"  scale="0.001 0.001 0.001" />
   </geometry>
  </collision>
 </link>
 <joint  type="revolute"  name="r_ankle_roll" >
  <origin  rpy="0 0 0"  xyz="0 0 0" />
  <axis  xyz="-0.9999999999999998 0.0 -2.220446049250313e-16" />
  <parent  link="r_ankle_1" />
  <child  link="r_ankle_2" />
  <limit  velocity="7.64"  lower="-0.4363323129985824"  upper="0.4363323129985824"  effort="37.0" />
  <dynamics  damping="0.223"  friction="0.0" />
 </joint>
 <link  name="r_foot" >
  <inertial >
   <origin  rpy="-1.5707963267948961 0 -1.5707963267948961"  xyz="0.03360009999999998 0.005371899999999999 -0.001146999999999898" />
   <mass  value="0.382866" />
   <inertia  iyz="-7.80325e-06"  izz="0.000273599"  ixz="-5.78759e-05"  ixx="0.00120946"  ixy="3.74585e-07"  iyy="0.00141439" />
  </inertial>
  <visual >
   <origin  rpy="-1.5707963267948961 0 -1.5707963267948961"  xyz="0.047209015 -0.07009999199999985 -0.6474380002860779" />
   <geometry >
    <mesh  filename="./iCubGenova04/meshes/simmechanics/sim_sea_2-5_r_sole_prt-binary.stl"  scale="0.001 0.001 0.001" />
   </geometry>
   <material  name="white" >
    <color  rgba="1 1 1 1" />
   </material>
  </visual>
  <collision >
   <origin  rpy="-1.5707963267948961 0 -1.5707963267948961"  xyz="0.047209015 -0.07009999199999985 -0.6474380002860779" />
   <geometry >
    <mesh  filename="./iCubGenova04/meshes/simmechanics/sim_sea_2-5_r_sole_prt-binary.stl"  scale="0.001 0.001 0.001" />
   </geometry>
  </collision>
 </link>
 <joint  type="fixed"  name="r_foot_ft_sensor" >
  <origin  rpy="3.141592653589793 0 0"  xyz="-0.003500000000000003 0 -0.0605" />
  <parent  link="r_ankle_2" />
  <child  link="r_foot" />
  <dynamics  damping="0.1" />
 </joint>
 <link  name="r_sole" />
 <joint  type="fixed"  name="r_sole_fixed_joint" >
  <origin  rpy="-3.141592653589793 0 0"  xyz="0.003499999999999996 0 0.0040000000000000036" />
  <parent  link="r_foot" />
  <child  link="r_sole" />
  <dynamics  damping="0.1" />
 </joint>
 <link  name="r_sole_skin_0" />
 <joint  type="fixed"  name="r_sole_skin_0_fixed_joint" >
  <origin  rpy="0 0 0"  xyz="0.06047669999999999 -0.0254106 0.007500000000000062" />
  <parent  link="r_foot" />
  <child  link="r_sole_skin_0" />
  <dynamics  damping="0.1" />
 </joint>
 <link  name="r_sole_skin_1" />
 <joint  type="fixed"  name="r_sole_skin_1_fixed_joint" >
  <origin  rpy="0 0 0"  xyz="0.07885119999999998 -0.019440400000000004 0.007500000000000062" />
  <parent  link="r_foot" />
  <child  link="r_sole_skin_1" />
  <dynamics  damping="0.1" />
 </joint>
 <link  name="r_sole_skin_2" />
 <joint  type="fixed"  name="r_sole_skin_2_fixed_joint" >
  <origin  rpy="0 0 0"  xyz="0.09320869999999998 -0.032368 0.007500000000000062" />
  <parent  link="r_foot" />
  <child  link="r_sole_skin_2" />
  <dynamics  damping="0.1" />
 </joint>
 <link  name="r_sole_skin_3" />
 <joint  type="fixed"  name="r_sole_skin_3_fixed_joint" >
  <origin  rpy="0 0 0"  xyz="0.11158309999999996 -0.0263978 0.007500000000000062" />
  <parent  link="r_foot" />
  <child  link="r_sole_skin_3" />
  <dynamics  damping="0.1" />
 </joint>
 <link  name="r_sole_skin_4" />
 <joint  type="fixed"  name="r_sole_skin_4_fixed_joint" >
  <origin  rpy="0 0 0"  xyz="0.11559999999999998 -0.007499999999999993 0.007500000000000062" />
  <parent  link="r_foot" />
  <child  link="r_sole_skin_4" />
  <dynamics  damping="0.1" />
 </joint>
 <link  name="r_sole_skin_8" />
 <joint  type="fixed"  name="r_sole_skin_8_fixed_joint" >
  <origin  rpy="0 0 0"  xyz="0.10525929999999997 0.024325399999999997 0.007500000000000062" />
  <parent  link="r_foot" />
  <child  link="r_sole_skin_8" />
  <dynamics  damping="0.1" />
 </joint>
 <link  name="r_sole_skin_9" />
 <joint  type="fixed"  name="r_sole_skin_9_fixed_joint" >
  <origin  rpy="0 0 0"  xyz="0.09090169999999997 0.03725289999999999 0.007500000000000062" />
  <parent  link="r_foot" />
  <child  link="r_sole_skin_9" />
  <dynamics  damping="0.1" />
 </joint>
 <link  name="r_sole_skin_10" />
 <joint  type="fixed"  name="r_sole_skin_10_fixed_joint" >
  <origin  rpy="0 0 0"  xyz="0.07252729999999998 0.03128289999999999 0.007500000000000062" />
  <parent  link="r_foot" />
  <child  link="r_sole_skin_10" />
  <dynamics  damping="0.1" />
 </joint>
 <link  name="r_sole_skin_11" />
 <joint  type="fixed"  name="r_sole_skin_11_fixed_joint" >
  <origin  rpy="0 0 0"  xyz="0.06851049999999997 0.012385000000000007 0.007500000000000062" />
  <parent  link="r_foot" />
  <child  link="r_sole_skin_11" />
  <dynamics  damping="0.1" />
 </joint>
 <link  name="r_sole_skin_12" />
 <joint  type="fixed"  name="r_sole_skin_12_fixed_joint" >
  <origin  rpy="0 0 0"  xyz="0.08286799999999997 -0.0005426000000000042 0.007500000000000062" />
  <parent  link="r_foot" />
  <child  link="r_sole_skin_12" />
  <dynamics  damping="0.1" />
 </joint>
 <link  name="r_sole_skin_13" />
 <joint  type="fixed"  name="r_sole_skin_13_fixed_joint" >
  <origin  rpy="0 0 0"  xyz="0.10124239999999997 0.005427600000000005 0.007500000000000062" />
  <parent  link="r_foot" />
  <child  link="r_sole_skin_13" />
  <dynamics  damping="0.1" />
 </joint>
 <link  name="r_sole_skin_14" />
 <joint  type="fixed"  name="r_sole_skin_14_fixed_joint" >
  <origin  rpy="0 0 0"  xyz="0.05013603999999998 0.006414799999999998 0.007500000000000062" />
  <parent  link="r_foot" />
  <child  link="r_sole_skin_14" />
  <dynamics  damping="0.1" />
 </joint>
 <link  name="r_sole_skin_15" />
 <joint  type="fixed"  name="r_sole_skin_15_fixed_joint" >
  <origin  rpy="0 0 0"  xyz="0.046119189999999984 -0.012483000000000008 0.007500000000000062" />
  <parent  link="r_foot" />
  <child  link="r_sole_skin_15" />
  <dynamics  damping="0.1" />
 </joint>
 <link  name="r_sole_skin_17" />
 <joint  type="fixed"  name="r_sole_skin_17_fixed_joint" >
  <origin  rpy="0 0 0"  xyz="-0.029685499999999997 0.03325689999999999 0.007500000000000062" />
  <parent  link="r_foot" />
  <child  link="r_sole_skin_17" />
  <dynamics  damping="0.1" />
 </joint>
 <link  name="r_sole_skin_18" />
 <joint  type="fixed"  name="r_sole_skin_18_fixed_joint" >
  <origin  rpy="0 0 0"  xyz="-0.04805990000000001 0.027286999999999978 0.007500000000000062" />
  <parent  link="r_foot" />
  <child  link="r_sole_skin_18" />
  <dynamics  damping="0.1" />
 </joint>
 <link  name="r_sole_skin_19" />
 <joint  type="fixed"  name="r_sole_skin_19_fixed_joint" >
  <origin  rpy="0 0 0"  xyz="-0.05207670000000001 0.008389200000000013 0.007500000000000062" />
  <parent  link="r_foot" />
  <child  link="r_sole_skin_19" />
  <dynamics  damping="0.1" />
 </joint>
 <link  name="r_sole_skin_20" />
 <joint  type="fixed"  name="r_sole_skin_20_fixed_joint" >
  <origin  rpy="0 0 0"  xyz="-0.037719200000000015 -0.004538399999999984 0.007500000000000062" />
  <parent  link="r_foot" />
  <child  link="r_sole_skin_20" />
  <dynamics  damping="0.1" />
 </joint>
 <link  name="r_sole_skin_21" />
 <joint  type="fixed"  name="r_sole_skin_21_fixed_joint" >
  <origin  rpy="0 0 0"  xyz="0.03577849999999998 0.01934240000000001 0.007500000000000062" />
  <parent  link="r_foot" />
  <child  link="r_sole_skin_21" />
  <dynamics  damping="0.1" />
 </joint>
 <link  name="r_sole_skin_22" />
 <joint  type="fixed"  name="r_sole_skin_22_fixed_joint" >
  <origin  rpy="0 0 0"  xyz="0.02774479999999999 -0.018453200000000003 0.007500000000000062" />
  <parent  link="r_foot" />
  <child  link="r_sole_skin_22" />
  <dynamics  damping="0.1" />
 </joint>
 <link  name="r_sole_skin_24" />
 <joint  type="fixed"  name="r_sole_skin_24_fixed_joint" >
  <origin  rpy="0 0 0"  xyz="-0.004987200000000004 -0.011495800000000007 0.007500000000000062" />
  <parent  link="r_foot" />
  <child  link="r_sole_skin_24" />
  <dynamics  damping="0.1" />
 </joint>
 <link  name="r_sole_skin_25" />
 <joint  type="fixed"  name="r_sole_skin_25_fixed_joint" >
  <origin  rpy="0 0 0"  xyz="0.013387199999999995 -0.005525599999999992 0.007500000000000062" />
  <parent  link="r_foot" />
  <child  link="r_sole_skin_25" />
  <dynamics  damping="0.1" />
 </joint>
 <link  name="r_sole_skin_26" />
 <joint  type="fixed"  name="r_sole_skin_26_fixed_joint" >
  <origin  rpy="0 0 0"  xyz="0.017404099999999985 0.0133722 0.007500000000000062" />
  <parent  link="r_foot" />
  <child  link="r_sole_skin_26" />
  <dynamics  damping="0.1" />
 </joint>
 <link  name="r_sole_skin_27" />
 <joint  type="fixed"  name="r_sole_skin_27_fixed_joint" >
  <origin  rpy="0 0 0"  xyz="0.0030464999999999798 0.026299799999999998 0.007500000000000062" />
  <parent  link="r_foot" />
  <child  link="r_sole_skin_27" />
  <dynamics  damping="0.1" />
 </joint>
 <link  name="r_sole_skin_28" />
 <joint  type="fixed"  name="r_sole_skin_28_fixed_joint" >
  <origin  rpy="0 0 0"  xyz="-0.015327899999999998 0.020329600000000003 0.007500000000000062" />
  <parent  link="r_foot" />
  <child  link="r_sole_skin_28" />
  <dynamics  damping="0.1" />
 </joint>
 <link  name="r_sole_skin_29" />
 <joint  type="fixed"  name="r_sole_skin_29_fixed_joint" >
  <origin  rpy="0 0 0"  xyz="-0.019344800000000002 0.001431799999999997 0.007500000000000062" />
  <parent  link="r_foot" />
  <child  link="r_sole_skin_29" />
  <dynamics  damping="0.1" />
 </joint>
 <link  name="torso_1" >
  <inertial >
   <origin  rpy="0 0 0"  xyz="0.027092135899999998 0.02914798 -0.00043979999999999714" />
   <mass  value="0.67144" />
   <inertia  iyz="6.50708e-06"  izz="0.000299445"  ixz="-1.02516e-06"  ixx="0.00040911"  ixy="-1.04522e-06"  iyy="0.000384141" />
  </inertial>
  <visual >
   <origin  rpy="0 0 0"  xyz="0.027046299809264998 0.03199999999999968 0.036400000000000286" />
   <geometry >
    <mesh  filename="./iCubGenova04/meshes/simmechanics/sim_sea_2-5_lap_belt_1_prt-binary.stl"  scale="0.001 0.001 0.001" />
   </geometry>
   <material  name="dblue" >
    <color  rgba="0 0 0.8 1" />
   </material>
  </visual>
  <collision >
   <origin  rpy="0 0 0"  xyz="0.027046299809264998 0.03199999999999968 0.036400000000000286" />
   <geometry >
    <mesh  filename="./iCubGenova04/meshes/simmechanics/sim_sea_2-5_lap_belt_1_prt-binary.stl"  scale="0.001 0.001 0.001" />
   </geometry>
  </collision>
 </link>
 <joint  type="revolute"  name="torso_pitch" >
  <origin  rpy="1.5707963267948961 0 -1.5707963267948961"  xyz="0 0.027046299999999992 0" />
  <axis  xyz="1.0 0.0 0.0" />
  <parent  link="root_link" />
  <child  link="torso_1" />
  <limit  velocity="50000"  lower="-0.3490658503988659"  upper="1.2217304763960306"  effort="50000" />
  <dynamics  damping="0.06"  friction="0.0" />
 </joint>
 <link  name="torso_2" >
  <inertial >
   <origin  rpy="0 0 0"  xyz="-0.00011350780926499999 0.036152500000000004 0.05709630000000001" />
   <mass  value="0.425685" />
   <inertia  iyz="-1.74814e-07"  izz="0.000604802"  ixz="9.25231e-08"  ixx="0.000829234"  ixy="2.37006e-08"  iyy="0.000436517" />
  </inertial>
  <visual >
   <origin  rpy="0 0 0"  xyz="0 0.1433 0.03865310000000001" />
   <geometry >
    <mesh  filename="./iCubGenova04/meshes/simmechanics/sim_sea_2-5_lap_belt_2_prt-binary.stl"  scale="0.001 0.001 0.001" />
   </geometry>
   <material  name="dgreen" >
    <color  rgba="0.1 0.8 0.1 1" />
   </material>
  </visual>
  <collision >
   <origin  rpy="0 0 0"  xyz="0 0.1433 0.03865310000000001" />
   <geometry >
    <mesh  filename="./iCubGenova04/meshes/simmechanics/sim_sea_2-5_lap_belt_2_prt-binary.stl"  scale="0.001 0.001 0.001" />
   </geometry>
  </collision>
 </link>
 <joint  type="revolute"  name="torso_roll" >
  <origin  rpy="0 0 0"  xyz="0.027046299809264998 0.032 -0.05734460000000001" />
  <axis  xyz="0.0 0.0 -1.0" />
  <parent  link="torso_1" />
  <child  link="torso_2" />
  <limit  velocity="50000"  lower="-0.5235987755982988"  upper="0.5235987755982988"  effort="50000" />
  <dynamics  damping="0.06"  friction="0.0" />
 </joint>
 <link  name="chest" >
  <inertial >
   <origin  rpy="0 0 0"  xyz="0.000188619190735 0.07309099999999999 -0.047238100000000005" />
   <mass  value="7.638" />
   <inertia  iyz="-0.0004291064091076428"  izz="0.026056324991143805"  ixz="0.00018198522994852988"  ixx="0.043032487861801666"  ixy="2.9107538880437883e-05"  iyy="0.04408357255482159" />
  </inertial>
  <visual >
   <origin  rpy="0 0 0"  xyz="0 0.09280000000000001 -0.024189000000000002" />
   <geometry >
    <mesh  filename="./iCubGenova04/meshes/simmechanics/sim_sea_2-5_chest_bb_prt-binary.stl"  scale="0.001 0.001 0.001" />
   </geometry>
   <material  name="gray" >
    <color  rgba="0.5 0.5 0.5 1" />
   </material>
  </visual>
  <collision >
   <origin  rpy="0 0 0"  xyz="0 0.09280000000000001 -0.024189000000000002" />
   <geometry >
    <mesh  filename="./iCubGenova04/meshes/simmechanics/sim_sea_2-5_chest_bb_prt-binary.stl"  scale="0.001 0.001 0.001" />
   </geometry>
  </collision>
 </link>
 <joint  type="revolute"  name="torso_yaw" >
  <origin  rpy="0 0 0"  xyz="0 0.05 0.06284210000000001" />
  <axis  xyz="0.0 -1.0 0.0" />
  <parent  link="torso_2" />
  <child  link="chest" />
  <limit  velocity="50000"  lower="-0.8726646259971648"  upper="0.8726646259971648"  effort="50000" />
  <dynamics  damping="0.06"  friction="0.0" />
 </joint>
 <link  name="neck_1" >
  <inertial >
   <origin  rpy="0 0 0"  xyz="0.0143705608 0.006567000000000017 -0.006384200000000003" />
   <mass  value="0.125793" />
   <inertia  iyz="9.39717e-06"  izz="4.7535e-05"  ixz="-3.74998e-08"  ixx="4.0647e-05"  ixy="8.09156e-08"  iyy="3.881e-05" />
  </inertial>
  <visual >
   <origin  rpy="0 0 0"  xyz="0.014299999809265 -0.07999699999999998 -0.029500800000000004" />
   <geometry >
    <mesh  filename="./iCubGenova04/meshes/simmechanics/sim_sea_2-5_neck_1_prt-binary.stl"  scale="0.001 0.001 0.001" />
   </geometry>
   <material  name="green" >
    <color  rgba="0 1 0 1" />
   </material>
  </visual>
  <collision >
   <origin  rpy="0 0 0"  xyz="0.014299999809265 -0.07999699999999998 -0.029500800000000004" />
   <geometry >
    <mesh  filename="./iCubGenova04/meshes/simmechanics/sim_sea_2-5_neck_1_prt-binary.stl"  scale="0.001 0.001 0.001" />
   </geometry>
  </collision>
 </link>
 <joint  type="revolute"  name="neck_pitch" >
  <origin  rpy="0 0 0"  xyz="-0.014299999809265 0.17279699999999998 0.005311800000000002" />
  <axis  xyz="-1.0 0.0 0.0" />
  <parent  link="chest" />
  <child  link="neck_1" />
  <limit  velocity="50000"  lower="-0.6981317007977318"  upper="0.3839724354387525"  effort="50000" />
  <dynamics  damping="0.06"  friction="0.0" />
 </joint>
 <link  name="neck_2" >
  <inertial >
   <origin  rpy="0 0 0"  xyz="-8.8573009265e-05 0.03522499999999998 -0.01954527" />
   <mass  value="0.177087" />
   <inertia  iyz="9.81476e-06"  izz="0.000105186"  ixz="4.68307e-07"  ixx="0.000117943"  ixy="-5.25591e-07"  iyy="4.04013e-05" />
  </inertial>
  <visual >
   <origin  rpy="0 0 0"  xyz="0 -0.089497 -0.05030077" />
   <geometry >
    <mesh  filename="./iCubGenova04/meshes/simmechanics/sim_sea_2-5_neck_2_prt-binary.stl"  scale="0.001 0.001 0.001" />
   </geometry>
   <material  name="black" >
    <color  rgba="0 0 0 1" />
   </material>
  </visual>
  <collision >
   <origin  rpy="0 0 0"  xyz="0 -0.089497 -0.05030077" />
   <geometry >
    <mesh  filename="./iCubGenova04/meshes/simmechanics/sim_sea_2-5_neck_2_prt-binary.stl"  scale="0.001 0.001 0.001" />
   </geometry>
  </collision>
 </link>
 <joint  type="revolute"  name="neck_roll" >
  <origin  rpy="0 0 0"  xyz="0.014299999809265 0.009500000000000008 0.020799969999999997" />
  <axis  xyz="0.0 0.0 1.0" />
  <parent  link="neck_1" />
  <child  link="neck_2" />
  <limit  velocity="50000"  lower="-0.3490658503988659"  upper="0.3490658503988659"  effort="50000" />
  <dynamics  damping="0.06"  friction="0.0" />
 </joint>
 <link  name="head" >
  <inertial >
   <origin  rpy="0 0 0"  xyz="-0.000574157809265 0.11351100000000003 -0.007539199999999999" />
   <mass  value="1.50691" />
   <inertia  iyz="0.000292091"  izz="0.00478116"  ixz="7.28166e-05"  ixx="0.00680478"  ixy="-1.60267e-05"  iyy="0.00634736" />
  </inertial>
  <visual >
   <origin  rpy="0 0 0"  xyz="0 -0.06715299999999999 -0.029500800000000004" />
   <geometry >
    <mesh  filename="./iCubGenova04/meshes/simmechanics/sim_sea_2-5_head_prt-binary.stl"  scale="0.001 0.001 0.001" />
   </geometry>
   <material  name="red" >
    <color  rgba="1 0 0 1" />
   </material>
  </visual>
  <collision >
   <origin  rpy="0 0 0"  xyz="0 -0.06715299999999999 -0.029500800000000004" />
   <geometry >
    <mesh  filename="./iCubGenova04/meshes/simmechanics/sim_sea_2-5_head_prt-binary.stl"  scale="0.001 0.001 0.001" />
   </geometry>
  </collision>
 </link>
 <joint  type="revolute"  name="neck_yaw" >
  <origin  rpy="0 0 0"  xyz="0 -0.022344000000000003 -0.020799969999999997" />
  <axis  xyz="0.0 1.0 0.0" />
  <parent  link="neck_2" />
  <child  link="head" />
  <limit  velocity="50000"  lower="-0.8726646259971648"  upper="0.8726646259971648"  effort="50000" />
  <dynamics  damping="0.06"  friction="0.0" />
 </joint>
 <link  name="imu_frame" />
 <joint  type="fixed"  name="imu_frame_fixed_joint" >
  <origin  rpy="-1.5707963267948961 1.570796326794896 0"  xyz="0.009500000190735 0.133444 0.009299999999999996" />
  <parent  link="head" />
  <child  link="imu_frame" />
  <dynamics  damping="0.1" />
 </joint>
 <link  name="r_shoulder_1" >
  <inertial >
   <origin  rpy="0 0 0"  xyz="-0.012265601413295815 3.200000000000425e-05 -0.003210642904490607" />
   <mass  value="0.114862" />
   <inertia  iyz="-6.13337e-08"  izz="1.00116e-05"  ixz="-3.55626e-06"  ixx="2.24541e-05"  ixy="-1.65173e-08"  iyy="2.29582e-05" />
  </inertial>
  <visual >
   <origin  rpy="0 0 0"  xyz="0.09900792530759175 0 -0.026529248755802246" />
   <geometry >
    <mesh  filename="./iCubGenova04/meshes/simmechanics/sim_sea_2-5_r_shoulder_1_prt-binary.stl"  scale="0.001 0.001 0.001" />
   </geometry>
   <material  name="blue" >
    <color  rgba="0 0 1 1" />
   </material>
  </visual>
  <collision >
   <origin  rpy="0 0 0"  xyz="0.09900792530759175 0 -0.026529248755802246" />
   <geometry >
    <mesh  filename="./iCubGenova04/meshes/simmechanics/sim_sea_2-5_r_shoulder_1_prt-binary.stl"  scale="0.001 0.001 0.001" />
   </geometry>
  </collision>
 </link>
 <joint  type="revolute"  name="r_shoulder_pitch" >
  <origin  rpy="0 -0.523598883792035 3.141592653589793"  xyz="-0.12001599980926501 0.09280000000000001 0.007969299999999999" />
  <axis  xyz="-0.965925926173269 0.0 0.25881927552505174" />
  <parent  link="chest" />
  <child  link="r_shoulder_1" />
  <limit  velocity="50000"  lower="-1.6667894356545847"  upper="0.17453292519943295"  effort="50000" />
  <dynamics  damping="0.06"  friction="0.0" />
 </joint>
 <link  name="r_shoulder_2" >
  <inertial >
   <origin  rpy="0 0 0"  xyz="-0.021414170943809915 0.00027172527255134304 -0.019440234453461297" />
   <mass  value="0.238162" />
   <inertia  iyz="1.19785e-06"  izz="0.000104956"  ixz="1.02574e-05"  ixx="0.000158626"  ixy="-1.12091e-07"  iyy="0.000206526" />
  </inertial>
  <visual >
   <origin  rpy="0 0 0"  xyz="0.10658780856753214 2.3191471541783582e-07 -0.04073921211753291" />
   <geometry >
    <mesh  filename="./iCubGenova04/meshes/simmechanics/sim_sea_2-5_r_shoulder_2_prt-binary.stl"  scale="0.001 0.001 0.001" />
   </geometry>
   <material  name="yellow" >
    <color  rgba="1 1 0 1" />
   </material>
  </visual>
  <collision >
   <origin  rpy="0 0 0"  xyz="0.10658780856753214 2.3191471541783582e-07 -0.04073921211753291" />
   <geometry >
    <mesh  filename="./iCubGenova04/meshes/simmechanics/sim_sea_2-5_r_shoulder_2_prt-binary.stl"  scale="0.001 0.001 0.001" />
   </geometry>
  </collision>
 </link>
 <joint  type="revolute"  name="r_shoulder_roll" >
  <origin  rpy="-0.2705976115829963 -0.252680154648383 -1.5015568003498745"  xyz="-0.007580465732273667 0 0.014210246363868029" />
  <axis  xyz="-0.258819 -2.7755575615628914e-17 -0.965926" />
  <parent  link="r_shoulder_1" />
  <child  link="r_shoulder_2" />
  <limit  velocity="50000"  lower="0.0"  upper="2.8064894372068823"  effort="50000" />
  <dynamics  damping="0.06"  friction="0.0" />
 </joint>
 <link  name="r_shoulder_3" >
  <inertial >
   <origin  rpy="0 0 0"  xyz="-0.026762076687111974 -6.999999999979245e-06 0.014699920771321831" />
   <mass  value="0.35913" />
   <inertia  iyz="2.65919e-07"  izz="0.000151821"  ixz="4.94445e-05"  ixx="0.000142333"  ixy="3.60361e-07"  iyy="0.000197746" />
  </inertial>
  <visual >
   <origin  rpy="0 0 0"  xyz="0.13193387916408805 0 -0.03535156676465449" />
   <geometry >
    <mesh  filename="./iCubGenova04/meshes/simmechanics/sim_sea_2-5_r_upper_arm_prt-binary.stl"  scale="0.001 0.001 0.001" />
   </geometry>
   <material  name="pink" >
    <color  rgba="1 0 1 1" />
   </material>
  </visual>
  <collision >
   <origin  rpy="0 0 0"  xyz="0.13193387916408805 0 -0.03535156676465449" />
   <geometry >
    <mesh  filename="./iCubGenova04/meshes/simmechanics/sim_sea_2-5_r_upper_arm_prt-binary.stl"  scale="0.001 0.001 0.001" />
   </geometry>
  </collision>
 </link>
 <joint  type="revolute"  name="r_shoulder_yaw" >
  <origin  rpy="-0.2526895461750575 0.008518618321396994 0.06703988914196896"  xyz="-0.025346071323150046 2.3275042730641626e-07 -0.0053876480645656255" />
  <axis  xyz="0.9659258438815126 -2.220446049250313e-16 -0.2588189794466167" />
  <parent  link="r_shoulder_2" />
  <child  link="r_shoulder_3" />
  <limit  velocity="50000"  lower="-0.6457718232379019"  upper="1.3962634015954636"  effort="50000" />
  <dynamics  damping="0.06"  friction="0.0" />
 </joint>
 <link  name="r_upper_arm" >
  <inertial >
   <origin  rpy="0 1.30899700696774 0"  xyz="-0.006087 0.0001260000000000011 0.029312099999999987" />
   <mass  value="0.745104" />
   <inertia  iyz="1.13363e-06"  izz="0.000599254"  ixz="-1.17426e-05"  ixx="0.000509527"  ixy="1.19292e-06"  iyy="0.000668487" />
  </inertial>
  <visual >
   <origin  rpy="0 1.30899700696774 0"  xyz="-0.014999999999999994 0 -0.19329999999999997" />
   <geometry >
    <mesh  filename="./iCubGenova04/meshes/simmechanics/sim_sea_2-5_r_elbow_prt-binary.stl"  scale="0.001 0.001 0.001" />
   </geometry>
   <material  name="cyan" >
    <color  rgba="0 1 1 1" />
   </material>
  </visual>
  <collision >
   <origin  rpy="0 1.30899700696774 0"  xyz="-0.014999999999999994 0 -0.19329999999999997" />
   <geometry >
    <mesh  filename="./iCubGenova04/meshes/simmechanics/sim_sea_2-5_r_elbow_prt-binary.stl"  scale="0.001 0.001 0.001" />
   </geometry>
  </collision>
 </link>
 <joint  type="fixed"  name="r_arm_ft_sensor" >
  <origin  rpy="0 -1.3089970069677397 0"  xyz="-0.05089730176650909 0 0.029167029620599215" />
  <parent  link="r_shoulder_3" />
  <child  link="r_upper_arm" />
  <dynamics  damping="0.1" />
 </joint>
 <link  name="r_elbow_1" >
  <inertial >
   <origin  rpy="0 0 0"  xyz="-0.006739129328428656 0.01880190000000001 -0.004657692361536202" />
   <mass  value="0.267903" />
   <inertia  iyz="3.92498e-06"  izz="9.68353e-05"  ixz="-1.04536e-05"  ixx="8.13344e-05"  ixy="7.36974e-06"  iyy="5.86947e-05" />
  </inertial>
  <visual >
   <origin  rpy="0 0 0"  xyz="0.25939046331664584 0.02249989999999996 -0.08503258869619254" />
   <geometry >
    <mesh  filename="./iCubGenova04/meshes/simmechanics/sim_sea_2-5_r_elbow_prosup_prt-binary.stl"  scale="0.001 0.001 0.001" />
   </geometry>
   <material  name="green" >
    <color  rgba="0 1 0 1" />
   </material>
  </visual>
  <collision >
   <origin  rpy="0 0 0"  xyz="0.25939046331664584 0.02249989999999996 -0.08503258869619254" />
   <geometry >
    <mesh  filename="./iCubGenova04/meshes/simmechanics/sim_sea_2-5_r_elbow_prosup_prt-binary.stl"  scale="0.001 0.001 0.001" />
   </geometry>
  </collision>
 </link>
 <joint  type="revolute"  name="r_elbow" >
  <origin  rpy="0 1.3089970069677397 0"  xyz="0 -0.022499900000000003 0.07925999999999998" />
  <axis  xyz="2.220446049250313e-16 1.0000000000000002 0.0" />
  <parent  link="r_upper_arm" />
  <child  link="r_elbow_1" />
  <limit  velocity="50000"  lower="0.2617993877991494"  upper="1.8500490071139892"  effort="50000" />
  <dynamics  damping="0.06"  friction="0.0" />
 </joint>
 <link  name="r_forearm" >
  <inertial >
   <origin  rpy="0 0 0"  xyz="-0.04043911338861204 -0.00032799999999999496 0.005327334483865203" />
   <mass  value="0.6347" />
   <inertia  iyz="1.1456e-06"  izz="0.000553637"  ixz="0.00010538"  ixx="0.000370044"  ixy="-1.65419e-06"  iyy="0.000672279" />
  </inertial>
  <visual >
   <origin  rpy="0 0 0"  xyz="0.29688696737542175 0 -0.07955060152271212" />
   <geometry >
    <mesh  filename="./iCubGenova04/meshes/simmechanics/sim_sea_2-5_r_forearm_prt-binary.stl"  scale="0.001 0.001 0.001" />
   </geometry>
   <material  name="white" >
    <color  rgba="1 1 1 1" />
   </material>
  </visual>
  <collision >
   <origin  rpy="0 0 0"  xyz="0.29688696737542175 0 -0.07955060152271212" />
   <geometry >
    <mesh  filename="./iCubGenova04/meshes/simmechanics/sim_sea_2-5_r_forearm_prt-binary.stl"  scale="0.001 0.001 0.001" />
   </geometry>
  </collision>
 </link>
 <joint  type="revolute"  name="r_wrist_prosup" >
  <origin  rpy="0 0 0"  xyz="-0.0384624299026574 0.02249990000000003 -0.005223168194033808" />
  <axis  xyz="0.9659258438815126 -2.220446049250313e-16 -0.2588189794466167" />
  <parent  link="r_elbow_1" />
  <child  link="r_forearm" />
  <limit  velocity="50000"  lower="-1.0471975511965976"  upper="1.0471975511965976"  effort="50000" />
  <dynamics  damping="0.06"  friction="0.0" />
 </joint>
 <link  name="r_forearm_skin_0" />
 <joint  type="fixed"  name="r_forearm_skin_0_fixed_joint" >
  <origin  rpy="1.6918152229167889 -0.27102674434071783 -3.0688043822713253"  xyz="-0.04544932866182965 0.030076999999999993 -0.006286560379014216" />
  <parent  link="r_forearm" />
  <child  link="r_forearm_skin_0" />
  <dynamics  damping="0.1" />
 </joint>
 <link  name="r_forearm_skin_1" />
 <joint  type="fixed"  name="r_forearm_skin_1_fixed_joint" >
  <origin  rpy="1.8669402327820506 -0.2744425337639908 -3.0994697798425186"  xyz="-0.03337289358257035 0.02882600000000002 -0.019845686771095515" />
  <parent  link="r_forearm" />
  <child  link="r_forearm_skin_1" />
  <dynamics  damping="0.1" />
 </joint>
 <link  name="r_forearm_skin_2" />
 <joint  type="fixed"  name="r_forearm_skin_2_fixed_joint" >
  <origin  rpy="1.7284728701922574 -0.26401521911581066 -3.127332606870116"  xyz="-0.014698892985226357 0.031278999999999973 -0.01601173383706034" />
  <parent  link="r_forearm" />
  <child  link="r_forearm_skin_2" />
  <dynamics  damping="0.1" />
 </joint>
 <link  name="r_forearm_skin_3" />
 <joint  type="fixed"  name="r_forearm_skin_3_fixed_joint" >
  <origin  rpy="-1.694872808587699 -0.26975772710448953 3.0795974357388127"  xyz="-0.04556729362200617 -0.030891000000000002 -0.006330009293506463" />
  <parent  link="r_forearm" />
  <child  link="r_forearm_skin_3" />
  <dynamics  damping="0.1" />
 </joint>
 <link  name="r_forearm_skin_4" />
 <joint  type="fixed"  name="r_forearm_skin_4_fixed_joint" >
  <origin  rpy="-1.807349601935264 -0.03931317963272516 2.9799764363205914"  xyz="-0.06353263329961753 -0.02811630000000001 -0.008997842580659852" />
  <parent  link="r_forearm" />
  <child  link="r_forearm_skin_4" />
  <dynamics  damping="0.1" />
 </joint>
 <link  name="r_forearm_skin_5" />
 <joint  type="fixed"  name="r_forearm_skin_5_fixed_joint" >
  <origin  rpy="-2.541047580603648 -0.38562726064167885 3.0548698966694605"  xyz="-0.06882119419679653 -0.0179483 -0.023113336179072505" />
  <parent  link="r_forearm" />
  <child  link="r_forearm_skin_5" />
  <dynamics  damping="0.1" />
 </joint>
 <link  name="r_forearm_skin_6" />
 <joint  type="fixed"  name="r_forearm_skin_6_fixed_joint" >
  <origin  rpy="-1.8662816465326075 -0.27288633618099856 3.104485850211511"  xyz="-0.033394843625473715 -0.029547900000000002 -0.019832558343293956" />
  <parent  link="r_forearm" />
  <child  link="r_forearm_skin_6" />
  <dynamics  damping="0.1" />
 </joint>
 <link  name="r_forearm_skin_7" />
 <joint  type="fixed"  name="r_forearm_skin_7_fixed_joint" >
  <origin  rpy="-1.725646408570656 -0.26399290072226816 3.127212542664466"  xyz="-0.014722426007426966 -0.031942200000000004 -0.015932648270323382" />
  <parent  link="r_forearm" />
  <child  link="r_forearm_skin_7" />
  <dynamics  damping="0.1" />
 </joint>
 <link  name="r_forearm_skin_8" />
 <joint  type="fixed"  name="r_forearm_skin_8_fixed_joint" >
  <origin  rpy="-2.9480197913728667 -0.27060509051232057 3.139805572846308"  xyz="-0.0228528628554271 -0.009786200000000009 -0.041885146374950645" />
  <parent  link="r_forearm" />
  <child  link="r_forearm_skin_8" />
  <dynamics  damping="0.1" />
 </joint>
 <link  name="r_forearm_skin_9" />
 <joint  type="fixed"  name="r_forearm_skin_9_fixed_joint" >
  <origin  rpy="-2.5840651770760545 -0.2933217195995048 3.121284073962177"  xyz="-0.03760327346828466 -0.018955000000000014 -0.03401633711864639" />
  <parent  link="r_forearm" />
  <child  link="r_forearm_skin_9" />
  <dynamics  damping="0.1" />
 </joint>
 <link  name="r_forearm_skin_10" />
 <joint  type="fixed"  name="r_forearm_skin_10_fixed_joint" >
  <origin  rpy="-2.94123313405522 -0.32830447192219026 3.12762637539622"  xyz="-0.05422852108875307 -0.009786099999999992 -0.03214690828659369" />
  <parent  link="r_forearm" />
  <child  link="r_forearm_skin_10" />
  <dynamics  damping="0.1" />
 </joint>
 <link  name="r_forearm_skin_11" />
 <joint  type="fixed"  name="r_forearm_skin_11_fixed_joint" >
  <origin  rpy="2.9392983595663433 -0.3291013897448521 -3.127319164460641"  xyz="-0.05422409120236691 0.00904300000000001 -0.03214312594517525" />
  <parent  link="r_forearm" />
  <child  link="r_forearm_skin_11" />
  <dynamics  damping="0.1" />
 </joint>
 <link  name="r_forearm_skin_12" />
 <joint  type="fixed"  name="r_forearm_skin_12_fixed_joint" >
  <origin  rpy="2.5830350596406384 -0.2948305020697442 -3.120265803141759"  xyz="-0.03759946338683661 0.01821600000000001 -0.034019117996090566" />
  <parent  link="r_forearm" />
  <child  link="r_forearm_skin_12" />
  <dynamics  damping="0.1" />
 </joint>
 <link  name="r_forearm_skin_13" />
 <joint  type="fixed"  name="r_forearm_skin_13_fixed_joint" >
  <origin  rpy="2.948966791979468 -0.27058394718877915 -3.1398188035221444"  xyz="-0.022855086840518728 0.009047999999999987 -0.04189190092085042" />
  <parent  link="r_forearm" />
  <child  link="r_forearm_skin_13" />
  <dynamics  damping="0.1" />
 </joint>
 <link  name="r_forearm_skin_14" />
 <joint  type="fixed"  name="r_forearm_skin_14_fixed_joint" >
  <origin  rpy="2.480449918677725 -0.29554256628052245 -2.918773491387445"  xyz="-0.06877032763640067 0.01716000000000001 -0.02302395585107192" />
  <parent  link="r_forearm" />
  <child  link="r_forearm_skin_14" />
  <dynamics  damping="0.1" />
 </joint>
 <link  name="r_forearm_skin_15" />
 <joint  type="fixed"  name="r_forearm_skin_15_fixed_joint" >
  <origin  rpy="1.8049276974140638 -0.289783281915754 -3.027658914283702"  xyz="-0.06337864196616988 0.027145000000000002 -0.008794054555439964" />
  <parent  link="r_forearm" />
  <child  link="r_forearm_skin_15" />
  <dynamics  damping="0.1" />
 </joint>
 <link  name="r_forearm_skin_16" />
 <joint  type="fixed"  name="r_forearm_skin_16_fixed_joint" >
  <origin  rpy="1.4128000702560044 -0.25082462138972744 -3.0657274234313623"  xyz="-0.03792482186997503 0.030487000000000014 0.02063695036047393" />
  <parent  link="r_forearm" />
  <child  link="r_forearm_skin_16" />
  <dynamics  damping="0.1" />
 </joint>
 <link  name="r_forearm_skin_17" />
 <joint  type="fixed"  name="r_forearm_skin_17_fixed_joint" >
  <origin  rpy="1.2722371620529929 -0.23059304703026898 -3.031955428370696"  xyz="-0.05431705488213744 0.027725000000000027 0.03032912401786229" />
  <parent  link="r_forearm" />
  <child  link="r_forearm_skin_17" />
  <dynamics  damping="0.1" />
 </joint>
 <link  name="r_forearm_skin_19" />
 <joint  type="fixed"  name="r_forearm_skin_19_fixed_joint" >
  <origin  rpy="-1.415608887032208 -0.2525692902263516 3.0771521788870553"  xyz="-0.038126610713769264 -0.03129409999999999 0.020690605393044834" />
  <parent  link="r_forearm" />
  <child  link="r_forearm_skin_19" />
  <dynamics  damping="0.1" />
 </joint>
 <link  name="r_forearm_skin_22" />
 <joint  type="fixed"  name="r_forearm_skin_22_fixed_joint" >
  <origin  rpy="-1.26582427279506 -0.23432815137878316 3.0478831797095465"  xyz="-0.05441739504212798 -0.028722300000000006 0.030603751660850168" />
  <parent  link="r_forearm" />
  <child  link="r_forearm_skin_22" />
  <dynamics  damping="0.1" />
 </joint>
 <link  name="r_forearm_skin_24" />
 <joint  type="fixed"  name="r_forearm_skin_24_fixed_joint" >
  <origin  rpy="-0.23489327644017136 -0.03881729939817664 3.0867634545899256"  xyz="-0.07003453195640522 -0.009716399999999986 0.05006910871401307" />
  <parent  link="r_forearm" />
  <child  link="r_forearm_skin_24" />
  <dynamics  damping="0.1" />
 </joint>
 <link  name="r_forearm_skin_25" />
 <joint  type="fixed"  name="r_forearm_skin_25_fixed_joint" >
  <origin  rpy="-0.5642955277146758 -0.13698027219744066 3.05963182792421"  xyz="-0.053599921629492835 -0.018223800000000012 0.04546981250452139" />
  <parent  link="r_forearm" />
  <child  link="r_forearm_skin_25" />
  <dynamics  damping="0.1" />
 </joint>
 <link  name="r_forearm_skin_28" />
 <joint  type="fixed"  name="r_forearm_skin_28_fixed_joint" >
  <origin  rpy="0.5907706440800042 -0.05316072260629339 3.1059708116712708"  xyz="-0.05358592721475829 0.01741200000000001 0.04535203739698063" />
  <parent  link="r_forearm" />
  <child  link="r_forearm_skin_28" />
  <dynamics  damping="0.1" />
 </joint>
 <link  name="r_forearm_skin_29" />
 <joint  type="fixed"  name="r_forearm_skin_29_fixed_joint" >
  <origin  rpy="0.24863098220864202 -0.03831365567858803 -3.0832899911631824"  xyz="-0.07003558050313372 0.008954000000000018 0.05001110362329029" />
  <parent  link="r_forearm" />
  <child  link="r_forearm_skin_29" />
  <dynamics  damping="0.1" />
 </joint>
 <link  name="r_forearm_dh_frame" />
 <joint  type="fixed"  name="r_forearm_dh_frame_fixed_joint" >
  <origin  rpy="-0.26179931982715643 0 -1.5707963267948968"  xyz="-0.1028711023733811 7.000000000020878e-06 0.027564221311064677" />
  <parent  link="r_forearm" />
  <child  link="r_forearm_dh_frame" />
  <dynamics  damping="0.1" />
 </joint>
 <link  name="r_wrist_1" >
  <inertial >
   <origin  rpy="0 0 0"  xyz="0.0009861019555474082 -0.0011759999999999965 0.004101327367239241" />
   <mass  value="0.0362615" />
   <inertia  iyz="-1.59685e-07"  izz="1.87724e-06"  ixz="-9.44554e-07"  ixx="5.57722e-06"  ixy="-3.10462e-08"  iyy="5.29845e-06" />
  </inertial>
  <visual >
   <origin  rpy="0 0 0"  xyz="0.40039217624844703 -7.000000000090267e-06 -0.1047483045162671" />
   <geometry >
    <mesh  filename="./iCubGenova04/meshes/simmechanics/sim_sea_2-5_r_wrist_pitch_prt-binary.stl"  scale="0.001 0.001 0.001" />
   </geometry>
   <material  name="dblue" >
    <color  rgba="0 0 0.8 1" />
   </material>
  </visual>
  <collision >
   <origin  rpy="0 0 0"  xyz="0.40039217624844703 -7.000000000090267e-06 -0.1047483045162671" />
   <geometry >
    <mesh  filename="./iCubGenova04/meshes/simmechanics/sim_sea_2-5_r_wrist_pitch_prt-binary.stl"  scale="0.001 0.001 0.001" />
   </geometry>
  </collision>
 </link>
 <joint  type="revolute"  name="r_wrist_pitch" >
  <origin  rpy="0 0 0"  xyz="-0.1035052088730253 7.000000000020878e-06 0.025197702993554973" />
  <axis  xyz="0.2588189794466167 0.0 0.9659258438815124" />
  <parent  link="r_forearm" />
  <child  link="r_wrist_1" />
  <limit  velocity="50000"  lower="-1.3962634015954636"  upper="0.4363323129985824"  effort="50000" />
  <dynamics  damping="0.06"  friction="0.0" />
 </joint>
 <link  name="r_hand" >
  <inertial >
   <origin  rpy="0 0 0"  xyz="-0.0646681637170268 0.005600200000000041 0.022681294091780244" />
   <mass  value="0.248289" />
   <inertia  iyz="2.07146e-05"  izz="0.00030575"  ixz="3.61526e-05"  ixx="0.000162381"  ixy="-2.3536e-06"  iyy="0.00043138" />
  </inertial>
  <visual >
   <origin  rpy="0 0 0"  xyz="0.39975806974880285 0.019492899999999924 -0.1071148228337768" />
   <geometry >
    <mesh  filename="./iCubGenova04/meshes/simmechanics/sim_sea_2-5_r_hand_prt-binary.stl"  scale="0.001 0.001 0.001" />
   </geometry>
   <material  name="dgreen" >
    <color  rgba="0.1 0.8 0.1 1" />
   </material>
  </visual>
  <collision >
   <origin  rpy="0 0 0"  xyz="0.39975806974880285 0.019492899999999924 -0.1071148228337768" />
   <geometry >
    <mesh  filename="./iCubGenova04/meshes/simmechanics/sim_sea_2-5_r_hand_prt-binary.stl"  scale="0.001 0.001 0.001" />
   </geometry>
  </collision>
 </link>
 <joint  type="revolute"  name="r_wrist_yaw" >
  <origin  rpy="0 0 0"  xyz="0.0006341064996442103 -0.019499900000000014 0.002366518317509704" />
  <axis  xyz="2.220446049250313e-16 1.0000000000000002 0.0" />
  <parent  link="r_wrist_1" />
  <child  link="r_hand" />
  <limit  velocity="50000"  lower="-0.3490658503988659"  upper="0.4363323129985824"  effort="50000" />
  <dynamics  damping="0.06"  friction="0.0" />
 </joint>
 <link  name="r_hand_dh_frame" />
 <joint  type="fixed"  name="r_hand_dh_frame_fixed_joint" >
  <origin  rpy="-1.5707963267948963 -0.2617993198271562 3.141592653589793"  xyz="-0.05765429784284365 -0.005556799999999987 0.013693832308330513" />
  <parent  link="r_hand" />
  <child  link="r_hand_dh_frame" />
  <dynamics  damping="0.1" />
 </joint>
 <link  name="l_shoulder_1" >
  <inertial >
   <origin  rpy="0 0 0"  xyz="-0.008985000000000007 -3.300000000000525e-05 -0.0088998" />
   <mass  value="0.114882" />
   <inertia  iyz="6.57597e-08"  izz="1.00139e-05"  ixz="3.55951e-06"  ixx="2.24676e-05"  ixy="-1.77064e-08"  iyy="2.29712e-05" />
  </inertial>
  <visual >
   <origin  rpy="0 0 0"  xyz="-0.12025748200000001 0 -0.032223" />
   <geometry >
    <mesh  filename="./iCubGenova04/meshes/simmechanics/sim_sea_2-5_l_shoulder_1_prt-binary.stl"  scale="0.001 0.001 0.001" />
   </geometry>
   <material  name="gray" >
    <color  rgba="0.5 0.5 0.5 1" />
   </material>
  </visual>
  <collision >
   <origin  rpy="0 0 0"  xyz="-0.12025748200000001 0 -0.032223" />
   <geometry >
    <mesh  filename="./iCubGenova04/meshes/simmechanics/sim_sea_2-5_l_shoulder_1_prt-binary.stl"  scale="0.001 0.001 0.001" />
   </geometry>
  </collision>
 </link>
 <joint  type="revolute"  name="l_shoulder_pitch" >
  <origin  rpy="0 0 0"  xyz="0.12001600019073501 0.09280000000000001 0.007969299999999999" />
  <axis  xyz="0.965926 0.0 0.258819" />
  <parent  link="chest" />
  <child  link="l_shoulder_1" />
  <limit  velocity="50000"  lower="-1.6667894356545847"  upper="0.17453292519943295"  effort="50000" />
  <dynamics  damping="0.06"  friction="0.0" />
 </joint>
 <link  name="l_shoulder_2" >
  <inertial >
   <origin  rpy="0 0 0"  xyz="0.021474595127247476 0.00026895789968721384 -0.01941073615345372" />
   <mass  value="0.238162" />
   <inertia  iyz="1.20112e-06"  izz="0.000120056"  ixz="-1.29687e-05"  ixx="0.000159621"  ixy="1.19701e-07"  iyy="0.000222574" />
  </inertial>
  <visual >
   <origin  rpy="0 0 0"  xyz="-0.10658669158059955 1.108009343442351e-07 -0.04074338077098992" />
   <geometry >
    <mesh  filename="./iCubGenova04/meshes/simmechanics/sim_sea_2-5_l_shoulder_2_prt-binary.stl"  scale="0.001 0.001 0.001" />
   </geometry>
   <material  name="green" >
    <color  rgba="0 1 0 1" />
   </material>
  </visual>
  <collision >
   <origin  rpy="0 0 0"  xyz="-0.10658669158059955 1.108009343442351e-07 -0.04074338077098992" />
   <geometry >
    <mesh  filename="./iCubGenova04/meshes/simmechanics/sim_sea_2-5_l_shoulder_2_prt-binary.stl"  scale="0.001 0.001 0.001" />
   </geometry>
  </collision>
 </link>
 <joint  type="revolute"  name="l_shoulder_roll" >
  <origin  rpy="0.2705973179159596 0.25268017754236044 -1.5015568855866173"  xyz="-0.013671000000000016 0 0.0085204" />
  <axis  xyz="-0.258819 2.7755575615628914e-17 0.965926" />
  <parent  link="l_shoulder_1" />
  <child  link="l_shoulder_2" />
  <limit  velocity="50000"  lower="0.0"  upper="2.8064894372068823"  effort="50000" />
  <dynamics  damping="0.06"  friction="0.0" />
 </joint>
 <link  name="l_shoulder_3" >
  <inertial >
   <origin  rpy="0 0 0"  xyz="0.026798412222026474 -1.5999999999988246e-05 0.014695680617730612" />
   <mass  value="0.35913" />
   <inertia  iyz="1.07538e-07"  izz="0.000151706"  ixz="-4.95846e-05"  ixx="0.00014245"  ixy="-2.22441e-07"  iyy="0.000197807" />
  </inertial>
  <visual >
   <origin  rpy="0 0 0"  xyz="-0.1319010376853961 0 -0.03534276691935331" />
   <geometry >
    <mesh  filename="./iCubGenova04/meshes/simmechanics/sim_sea_2-5_l_upper_arm_prt-binary.stl"  scale="0.001 0.001 0.001" />
   </geometry>
   <material  name="black" >
    <color  rgba="0 0 0 1" />
   </material>
  </visual>
  <collision >
   <origin  rpy="0 0 0"  xyz="-0.1319010376853961 0 -0.03534276691935331" />
   <geometry >
    <mesh  filename="./iCubGenova04/meshes/simmechanics/sim_sea_2-5_l_upper_arm_prt-binary.stl"  scale="0.001 0.001 0.001" />
   </geometry>
  </collision>
 </link>
 <joint  type="revolute"  name="l_shoulder_yaw" >
  <origin  rpy="-0.2526895461750575 -0.008518618321396994 -0.06703988914196896"  xyz="0.025314346831209797 1.1163643820477631e-07 -0.005400616562648813" />
  <axis  xyz="0.9659258438815126 2.220446049250313e-16 0.2588189794466167" />
  <parent  link="l_shoulder_2" />
  <child  link="l_shoulder_3" />
  <limit  velocity="50000"  lower="-0.6457718232379019"  upper="1.3962634015954636"  effort="50000" />
  <dynamics  damping="0.06"  friction="0.0" />
 </joint>
 <link  name="l_upper_arm" >
  <inertial >
   <origin  rpy="0 -1.30899700696774 -3.1415926535897922"  xyz="-0.006120999999999996 -0.00018899999999999473 0.02936839999999999" />
   <mass  value="0.746799" />
   <inertia  iyz="3.11833e-06"  izz="0.000601202"  ixz="1.20048e-05"  ixx="0.000509731"  ixy="-6.90767e-07"  iyy="0.00067086" />
  </inertial>
  <visual >
   <origin  rpy="0 -1.30899700696774 -3.1415926535897922"  xyz="-0.014999999999999994 0 -0.19329999999999997" />
   <geometry >
    <mesh  filename="./iCubGenova04/meshes/simmechanics/sim_sea_2-5_l_elbow_prt-binary.stl"  scale="0.001 0.001 0.001" />
   </geometry>
   <material  name="red" >
    <color  rgba="1 0 0 1" />
   </material>
  </visual>
  <collision >
   <origin  rpy="0 -1.30899700696774 -3.1415926535897922"  xyz="-0.014999999999999994 0 -0.19329999999999997" />
   <geometry >
    <mesh  filename="./iCubGenova04/meshes/simmechanics/sim_sea_2-5_l_elbow_prt-binary.stl"  scale="0.001 0.001 0.001" />
   </geometry>
  </collision>
 </link>
 <joint  type="fixed"  name="l_arm_ft_sensor" >
  <origin  rpy="0 -1.3089970069677395 3.1415926535897927"  xyz="0.05093014324520106 0 0.029175829465900395" />
  <parent  link="l_shoulder_3" />
  <child  link="l_upper_arm" />
  <dynamics  damping="0.1" />
 </joint>
 <link  name="l_elbow_1" >
  <inertial >
   <origin  rpy="0 0 0"  xyz="0.006739129328428652 0.030301900000000007 -0.004657692361536202" />
   <mass  value="0.267903" />
   <inertia  iyz="3.9319e-06"  izz="9.68469e-05"  ixz="1.04505e-05"  ixx="8.13352e-05"  ixy="-7.37159e-06"  iyy="5.86823e-05" />
  </inertial>
  <visual >
   <origin  rpy="0 0 0"  xyz="-0.25939046331664584 0.03399989999999996 -0.08503258869619254" />
   <geometry >
    <mesh  filename="./iCubGenova04/meshes/simmechanics/sim_sea_2-5_l_elbow_prosup_prt-binary.stl"  scale="0.001 0.001 0.001" />
   </geometry>
   <material  name="blue" >
    <color  rgba="0 0 1 1" />
   </material>
  </visual>
  <collision >
   <origin  rpy="0 0 0"  xyz="-0.25939046331664584 0.03399989999999996 -0.08503258869619254" />
   <geometry >
    <mesh  filename="./iCubGenova04/meshes/simmechanics/sim_sea_2-5_l_elbow_prosup_prt-binary.stl"  scale="0.001 0.001 0.001" />
   </geometry>
  </collision>
 </link>
 <joint  type="revolute"  name="l_elbow" >
  <origin  rpy="0 -1.3089970069677395 -3.141592653589793"  xyz="0 0.03399989999999997 0.07925999999999998" />
  <axis  xyz="2.220446049250313e-16 -1.0000000000000002 0.0" />
  <parent  link="l_upper_arm" />
  <child  link="l_elbow_1" />
  <limit  velocity="50000"  lower="0.2617993877991494"  upper="1.8500490071139892"  effort="50000" />
  <dynamics  damping="0.06"  friction="0.0" />
 </joint>
 <link  name="l_forearm" >
  <inertial >
   <origin  rpy="0 0 0"  xyz="0.040451182882303864 -0.000686000000000006 0.005323632143791274" />
   <mass  value="0.636185" />
   <inertia  iyz="4.05222e-06"  izz="0.000557115"  ixz="-0.000105871"  ixx="0.000371447"  ixy="4.34562e-06"  iyy="0.000674229" />
  </inertial>
  <visual >
   <origin  rpy="0 0 0"  xyz="-0.29688696737542175 0 -0.07955060152271212" />
   <geometry >
    <mesh  filename="./iCubGenova04/meshes/simmechanics/sim_sea_2-5_l_forearm_prt-binary.stl"  scale="0.001 0.001 0.001" />
   </geometry>
   <material  name="yellow" >
    <color  rgba="1 1 0 1" />
   </material>
  </visual>
  <collision >
   <origin  rpy="0 0 0"  xyz="-0.29688696737542175 0 -0.07955060152271212" />
   <geometry >
    <mesh  filename="./iCubGenova04/meshes/simmechanics/sim_sea_2-5_l_forearm_prt-binary.stl"  scale="0.001 0.001 0.001" />
   </geometry>
  </collision>
 </link>
 <joint  type="revolute"  name="l_wrist_prosup" >
  <origin  rpy="0 0 0"  xyz="0.03846242990265739 0.03399990000000003 -0.005223168194033808" />
  <axis  xyz="0.9659258438815126 2.220446049250313e-16 0.2588189794466167" />
  <parent  link="l_elbow_1" />
  <child  link="l_forearm" />
  <limit  velocity="50000"  lower="-1.0471975511965976"  upper="1.0471975511965976"  effort="50000" />
  <dynamics  damping="0.06"  friction="0.0" />
 </joint>
 <link  name="l_forearm_skin_0" />
 <joint  type="fixed"  name="l_forearm_skin_0_fixed_joint" >
  <origin  rpy="1.6918152229167884 -0.2710267443407179 0.07278827131846853"  xyz="0.045449328661829665 -0.032316899999999996 -0.006286560379014216" />
  <parent  link="l_forearm" />
  <child  link="l_forearm_skin_0" />
  <dynamics  damping="0.1" />
 </joint>
 <link  name="l_forearm_skin_1" />
 <joint  type="fixed"  name="l_forearm_skin_1_fixed_joint" >
  <origin  rpy="1.8669402327820506 -0.27444253376399064 0.04212287374727489"  xyz="0.03337289358257036 -0.031066200000000016 -0.019845686771095515" />
  <parent  link="l_forearm" />
  <child  link="l_forearm_skin_1" />
  <dynamics  damping="0.1" />
 </joint>
 <link  name="l_forearm_skin_2" />
 <joint  type="fixed"  name="l_forearm_skin_2_fixed_joint" >
  <origin  rpy="1.7284728701922578 -0.2640152191158104 0.014260046719677696"  xyz="0.01469889298522637 -0.033518400000000004 -0.01601173383706034" />
  <parent  link="l_forearm" />
  <child  link="l_forearm_skin_2" />
  <dynamics  damping="0.1" />
 </joint>
 <link  name="l_forearm_skin_3" />
 <joint  type="fixed"  name="l_forearm_skin_3_fixed_joint" >
  <origin  rpy="-1.6948728085876998 -0.2697577271044896 -0.061995217850980305"  xyz="0.04556729362200616 0.02865100000000001 -0.006330009293506463" />
  <parent  link="l_forearm" />
  <child  link="l_forearm_skin_3" />
  <dynamics  damping="0.1" />
 </joint>
 <link  name="l_forearm_skin_4" />
 <joint  type="fixed"  name="l_forearm_skin_4_fixed_joint" >
  <origin  rpy="-1.8174787010829498 -0.28740688488516286 -0.09983161528264395"  xyz="0.0635326332996175 0.02587700000000001 -0.008997842580659852" />
  <parent  link="l_forearm" />
  <child  link="l_forearm_skin_4" />
  <dynamics  damping="0.1" />
 </joint>
 <link  name="l_forearm_skin_5" />
 <joint  type="fixed"  name="l_forearm_skin_5_fixed_joint" >
  <origin  rpy="-2.541047580603648 -0.38562726064167896 -0.08672275692033206"  xyz="0.06882119419679653 0.015709 -0.023113336179072505" />
  <parent  link="l_forearm" />
  <child  link="l_forearm_skin_5" />
  <dynamics  damping="0.1" />
 </joint>
 <link  name="l_forearm_skin_6" />
 <joint  type="fixed"  name="l_forearm_skin_6_fixed_joint" >
  <origin  rpy="-1.866281646532607 -0.27288633618099856 -0.037106803378281816"  xyz="0.0333948436254737 0.027308000000000027 -0.019832558343293956" />
  <parent  link="l_forearm" />
  <child  link="l_forearm_skin_6" />
  <dynamics  damping="0.1" />
 </joint>
 <link  name="l_forearm_skin_7" />
 <joint  type="fixed"  name="l_forearm_skin_7_fixed_joint" >
  <origin  rpy="-1.7256464085706567 -0.2639929007222682 -0.014380110925327112"  xyz="0.014722426007426952 0.02970199999999998 -0.015932648270323382" />
  <parent  link="l_forearm" />
  <child  link="l_forearm_skin_7" />
  <dynamics  damping="0.1" />
 </joint>
 <link  name="l_forearm_skin_8" />
 <joint  type="fixed"  name="l_forearm_skin_8_fixed_joint" >
  <origin  rpy="-2.9480197913728667 -0.27060509051232073 -0.0017870807434848186"  xyz="0.0228528628554271 0.007545999999999997 -0.041885146374950645" />
  <parent  link="l_forearm" />
  <child  link="l_forearm_skin_8" />
  <dynamics  damping="0.1" />
 </joint>
 <link  name="l_forearm_skin_9" />
 <joint  type="fixed"  name="l_forearm_skin_9_fixed_joint" >
  <origin  rpy="-2.5840651770760545 -0.29332171959950476 -0.020308579627615755"  xyz="0.03760327346828466 0.016715000000000008 -0.03401633711864639" />
  <parent  link="l_forearm" />
  <child  link="l_forearm_skin_9" />
  <dynamics  damping="0.1" />
 </joint>
 <link  name="l_forearm_skin_10" />
 <joint  type="fixed"  name="l_forearm_skin_10_fixed_joint" >
  <origin  rpy="-2.9412331340552202 -0.3283044719221903 -0.01396627819357275"  xyz="0.05422852108875307 0.007546000000000011 -0.03214690828659369" />
  <parent  link="l_forearm" />
  <child  link="l_forearm_skin_10" />
  <dynamics  damping="0.1" />
 </joint>
 <link  name="l_forearm_skin_11" />
 <joint  type="fixed"  name="l_forearm_skin_11_fixed_joint" >
  <origin  rpy="2.9392983595663433 -0.3291013897448523 0.01427348912915269"  xyz="0.05422409120236691 -0.011283199999999993 -0.03214312594517525" />
  <parent  link="l_forearm" />
  <child  link="l_forearm_skin_11" />
  <dynamics  damping="0.1" />
 </joint>
 <link  name="l_forearm_skin_12" />
 <joint  type="fixed"  name="l_forearm_skin_12_fixed_joint" >
  <origin  rpy="2.5830350596406384 -0.29483050206974426 0.02132685044803458"  xyz="0.037599463386836625 -0.020455600000000018 -0.034019117996090566" />
  <parent  link="l_forearm" />
  <child  link="l_forearm_skin_12" />
  <dynamics  damping="0.1" />
 </joint>
 <link  name="l_forearm_skin_13" />
 <joint  type="fixed"  name="l_forearm_skin_13_fixed_joint" >
  <origin  rpy="2.948966791979468 -0.2705839471887793 0.0017738500676491309"  xyz="0.022855086840518728 -0.0112878 -0.04189190092085042" />
  <parent  link="l_forearm" />
  <child  link="l_forearm_skin_13" />
  <dynamics  damping="0.1" />
 </joint>
 <link  name="l_forearm_skin_14" />
 <joint  type="fixed"  name="l_forearm_skin_14_fixed_joint" >
  <origin  rpy="2.5246225036344367 -0.3877945117708607 0.09129241116830253"  xyz="0.06877032763640067 -0.019399899999999998 -0.02302395585107192" />
  <parent  link="l_forearm" />
  <child  link="l_forearm_skin_14" />
  <dynamics  damping="0.1" />
 </joint>
 <link  name="l_forearm_skin_15" />
 <joint  type="fixed"  name="l_forearm_skin_15_fixed_joint" >
  <origin  rpy="1.8049276974140638 -0.28978328191575403 0.11393373930609194"  xyz="0.06337864196616988 -0.029384300000000002 -0.008794054555439964" />
  <parent  link="l_forearm" />
  <child  link="l_forearm_skin_15" />
  <dynamics  damping="0.1" />
 </joint>
 <link  name="l_forearm_skin_16" />
 <joint  type="fixed"  name="l_forearm_skin_16_fixed_joint" >
  <origin  rpy="1.4128000702560044 -0.25082462138972744 0.0758652301584316"  xyz="0.03792482186997504 -0.0327268 0.02063695036047393" />
  <parent  link="l_forearm" />
  <child  link="l_forearm_skin_16" />
  <dynamics  damping="0.1" />
 </joint>
 <link  name="l_forearm_skin_17" />
 <joint  type="fixed"  name="l_forearm_skin_17_fixed_joint" >
  <origin  rpy="1.2722371620529929 -0.23059304703026898 0.10963722521909765"  xyz="0.05431705488213746 -0.029964599999999994 0.03032912401786229" />
  <parent  link="l_forearm" />
  <child  link="l_forearm_skin_17" />
  <dynamics  damping="0.1" />
 </joint>
 <link  name="l_forearm_skin_19" />
 <joint  type="fixed"  name="l_forearm_skin_19_fixed_joint" >
  <origin  rpy="-1.415608887032208 -0.2525692902263517 -0.06444047470273734"  xyz="0.03812661071376925 0.029053999999999996 0.020690605393044834" />
  <parent  link="l_forearm" />
  <child  link="l_forearm_skin_19" />
  <dynamics  damping="0.1" />
 </joint>
 <link  name="l_forearm_skin_22" />
 <joint  type="fixed"  name="l_forearm_skin_22_fixed_joint" >
  <origin  rpy="-1.2658242727950597 -0.23432815137878313 -0.09370947388024636"  xyz="0.05441739504212797 0.026483000000000007 0.030603751660850168" />
  <parent  link="l_forearm" />
  <child  link="l_forearm_skin_22" />
  <dynamics  damping="0.1" />
 </joint>
 <link  name="l_forearm_skin_24" />
 <joint  type="fixed"  name="l_forearm_skin_24_fixed_joint" >
  <origin  rpy="-0.23489327644017152 -0.03881729939817665 -0.054829198999867323"  xyz="0.07003453195640522 0.007477000000000011 0.05006910871401307" />
  <parent  link="l_forearm" />
  <child  link="l_forearm_skin_24" />
  <dynamics  damping="0.1" />
 </joint>
 <link  name="l_forearm_skin_25" />
 <joint  type="fixed"  name="l_forearm_skin_25_fixed_joint" >
  <origin  rpy="-0.5642955277146758 -0.1369802721974407 -0.08196082566558262"  xyz="0.05359992162949282 0.015984000000000026 0.04546981250452139" />
  <parent  link="l_forearm" />
  <child  link="l_forearm_skin_25" />
  <dynamics  damping="0.1" />
 </joint>
 <link  name="l_forearm_skin_28" />
 <joint  type="fixed"  name="l_forearm_skin_28_fixed_joint" >
  <origin  rpy="0.5793111069492733 -0.13399430677809196 0.08675978583118527"  xyz="0.05358592721475831 -0.01965220000000001 0.04535203739698063" />
  <parent  link="l_forearm" />
  <child  link="l_forearm_skin_28" />
  <dynamics  damping="0.1" />
 </joint>
 <link  name="l_forearm_skin_29" />
 <joint  type="fixed"  name="l_forearm_skin_29_fixed_joint" >
  <origin  rpy="0.24863098220864197 -0.03831365567858803 0.05830266242661145"  xyz="0.07003558050313372 -0.011193599999999984 0.05001110362329029" />
  <parent  link="l_forearm" />
  <child  link="l_forearm_skin_29" />
  <dynamics  damping="0.1" />
 </joint>
 <link  name="l_forearm_dh_frame" />
 <joint  type="fixed"  name="l_forearm_dh_frame_fixed_joint" >
  <origin  rpy="2.879793333762637 0 1.5707963267948968"  xyz="0.1028711023733811 7.000000000020878e-06 0.027564221311064677" />
  <parent  link="l_forearm" />
  <child  link="l_forearm_dh_frame" />
  <dynamics  damping="0.1" />
 </joint>
 <link  name="l_wrist_1" >
  <inertial >
   <origin  rpy="0 0 0"  xyz="-0.000981313804427647 -0.0011779999999999985 0.0040834577391274315" />
   <mass  value="0.0362152" />
   <inertia  iyz="-1.58924e-07"  izz="1.87579e-06"  ixz="9.42153e-07"  ixx="5.56774e-06"  ixy="3.08362e-08"  iyy="5.28838e-06" />
  </inertial>
  <visual >
   <origin  rpy="0 0 0"  xyz="-0.4003145305546131 -7.000000000090267e-06 -0.10503808226943155" />
   <geometry >
    <mesh  filename="./iCubGenova04/meshes/simmechanics/sim_sea_2-5_l_wrist_pitch_prt-binary.stl"  scale="0.001 0.001 0.001" />
   </geometry>
   <material  name="pink" >
    <color  rgba="1 0 1 1" />
   </material>
  </visual>
  <collision >
   <origin  rpy="0 0 0"  xyz="-0.4003145305546131 -7.000000000090267e-06 -0.10503808226943155" />
   <geometry >
    <mesh  filename="./iCubGenova04/meshes/simmechanics/sim_sea_2-5_l_wrist_pitch_prt-binary.stl"  scale="0.001 0.001 0.001" />
   </geometry>
  </collision>
 </link>
 <joint  type="revolute"  name="l_wrist_pitch" >
  <origin  rpy="0 0 0"  xyz="0.10342756317919133 7.000000000020878e-06 0.02548748074671943" />
  <axis  xyz="0.2588189794466167 0.0 -0.9659258438815124" />
  <parent  link="l_forearm" />
  <child  link="l_wrist_1" />
  <limit  velocity="50000"  lower="-1.3962634015954636"  upper="0.4363323129985824"  effort="50000" />
  <dynamics  damping="0.06"  friction="0.0" />
 </joint>
 <link  name="l_hand" >
  <inertial >
   <origin  rpy="0 0 0"  xyz="0.0647680204056704 0.005630400000000035 0.02266022084492256" />
   <mass  value="0.247806" />
   <inertia  iyz="2.06885e-05"  izz="0.000304729"  ixz="-3.68906e-05"  ixx="0.000162491"  ixy="2.96453e-06"  iyy="0.000430657" />
  </inertial>
  <visual >
   <origin  rpy="0 0 0"  xyz="-0.39968042405496884 0.019492899999999924 -0.10740460058694125" />
   <geometry >
    <mesh  filename="./iCubGenova04/meshes/simmechanics/sim_sea_2-5_l_hand_prt-binary.stl"  scale="0.001 0.001 0.001" />
   </geometry>
   <material  name="cyan" >
    <color  rgba="0 1 1 1" />
   </material>
  </visual>
  <collision >
   <origin  rpy="0 0 0"  xyz="-0.39968042405496884 0.019492899999999924 -0.10740460058694125" />
   <geometry >
    <mesh  filename="./iCubGenova04/meshes/simmechanics/sim_sea_2-5_l_hand_prt-binary.stl"  scale="0.001 0.001 0.001" />
   </geometry>
  </collision>
 </link>
 <joint  type="revolute"  name="l_wrist_yaw" >
  <origin  rpy="0 0 0"  xyz="-0.0006341064996442103 -0.019499900000000014 0.0023665183175097006" />
  <axis  xyz="-2.220446049250313e-16 1.0000000000000002 0.0" />
  <parent  link="l_wrist_1" />
  <child  link="l_hand" />
  <limit  velocity="50000"  lower="-0.3490658503988659"  upper="0.4363323129985824"  effort="50000" />
  <dynamics  damping="0.06"  friction="0.0" />
 </joint>
 <link  name="l_hand_dh_frame" />
 <joint  type="fixed"  name="l_hand_dh_frame_fixed_joint" >
  <origin  rpy="-1.5707963267948963 -0.2617993198271562 0"  xyz="0.05765429784284365 -0.005556799999999987 0.013693832308330513" />
  <parent  link="l_hand" />
  <child  link="l_hand_dh_frame" />
  <dynamics  damping="0.1" />
 </joint>
 <link  name="l_hip_1" >
  <inertial >
   <origin  rpy="1.5707963267948961 0 1.5707963267948961"  xyz="-0.0005107999999999918 0.03809229999999999 -8.299999999999974e-05" />
   <mass  value="0.919725" />
   <inertia  iyz="-1.06028e-06"  izz="0.000578982"  ixz="-9.64514e-07"  ixx="0.000404539"  ixy="1.18502e-06"  iyy="0.000573315" />
  </inertial>
  <visual >
   <origin  rpy="1.5707963267948961 0 1.5707963267948961"  xyz="0.04285150000005946 -0.02599999999999967 0.15191299999998345" />
   <geometry >
    <mesh  filename="./iCubGenova04/meshes/simmechanics/sim_sea_2-5_l_hip_1_prt-binary.stl"  scale="0.001 0.001 0.001" />
   </geometry>
   <material  name="green" >
    <color  rgba="0 1 0 1" />
   </material>
  </visual>
  <collision >
   <origin  rpy="1.5707963267948961 0 1.5707963267948961"  xyz="0.04285150000005946 -0.02599999999999967 0.15191299999998345" />
   <geometry >
    <mesh  filename="./iCubGenova04/meshes/simmechanics/sim_sea_2-5_l_hip_1_prt-binary.stl"  scale="0.001 0.001 0.001" />
   </geometry>
  </collision>
 </link>
 <joint  type="revolute"  name="l_hip_pitch" >
  <origin  rpy="0 0 -3.141592653589793"  xyz="0.006451499999999999 -0.026000000000000023 -0.11991299999999999" />
  <axis  xyz="-2.220446049250313e-16 -0.9999999999999998 0.0" />
  <parent  link="root_link" />
  <child  link="l_hip_1" />
  <limit  velocity="5.1"  lower="-0.7853981633974483"  upper="2.3387411976724017"  effort="55.5" />
  <dynamics  damping="0.223"  friction="0.0" />
 </joint>
 <link  name="l_hip_2" >
  <inertial >
   <origin  rpy="1.5707963267948961 0 1.5707963267948961"  xyz="-0.0011062999999999906 1.7299999999997873e-05 -0.04457399999999995" />
   <mass  value="0.415987" />
   <inertia  iyz="6.7417e-06"  izz="0.000307828"  ixz="-6.72876e-08"  ixx="0.000475741"  ixy="2.89355e-07"  iyy="0.000279828" />
  </inertial>
  <visual >
   <origin  rpy="1.5707963267948961 0 1.5707963267948961"  xyz="0.04285149980932398 -0.0701000000000088 0.15191299999997981" />
   <geometry >
    <mesh  filename="./iCubGenova04/meshes/simmechanics/sim_sea_2-5_l_hip_2_prt-binary.stl"  scale="0.001 0.001 0.001" />
   </geometry>
   <material  name="white" >
    <color  rgba="1 1 1 1" />
   </material>
  </visual>
  <collision >
   <origin  rpy="1.5707963267948961 0 1.5707963267948961"  xyz="0.04285149980932398 -0.0701000000000088 0.15191299999997981" />
   <geometry >
    <mesh  filename="./iCubGenova04/meshes/simmechanics/sim_sea_2-5_l_hip_2_prt-binary.stl"  scale="0.001 0.001 0.001" />
   </geometry>
  </collision>
 </link>
 <joint  type="revolute"  name="l_hip_roll" >
  <origin  rpy="0 0 0"  xyz="0 0.04409999999999999 0" />
  <axis  xyz="0.9999999999999998 0.0 2.220446049250313e-16" />
  <parent  link="l_hip_1" />
  <child  link="l_hip_2" />
  <limit  velocity="7.64"  lower="-0.3490658503988659"  upper="2.0943951023931953"  effort="37.0" />
  <dynamics  damping="0.223"  friction="0.0" />
 </joint>
 <link  name="l_hip_3" >
  <inertial >
   <origin  rpy="-1.5707963267948961 0 -1.5707963267948961"  xyz="-0.00012289999999999524 -0.00028229999999998534 0.008718000000000031" />
   <mass  value="0.126212" />
   <inertia  iyz="3.32338e-08"  izz="3.26449e-05"  ixz="-4.41463e-09"  ixx="3.27938e-05"  ixy="2.67901e-07"  iyy="5.69957e-05" />
  </inertial>
  <visual >
   <origin  rpy="-1.5707963267948961 0 -1.5707963267948961"  xyz="0.04370906139999998 0.07010002460000005 -0.22621299999998065" />
   <geometry >
    <mesh  filename="./iCubGenova04/meshes/simmechanics/sim_sea_2-5_l_upper_thigh_prt-binary.stl"  scale="0.001 0.001 0.001" />
   </geometry>
   <material  name="dblue" >
    <color  rgba="0 0 0.8 1" />
   </material>
  </visual>
  <collision >
   <origin  rpy="-1.5707963267948961 0 -1.5707963267948961"  xyz="0.04370906139999998 0.07010002460000005 -0.22621299999998065" />
   <geometry >
    <mesh  filename="./iCubGenova04/meshes/simmechanics/sim_sea_2-5_l_upper_thigh_prt-binary.stl"  scale="0.001 0.001 0.001" />
   </geometry>
  </collision>
 </link>
 <joint  type="fixed"  name="l_leg_ft_sensor" >
  <origin  rpy="3.141592653589793 0 0"  xyz="-0.0008301999999999893 7.519999999998361e-05 -0.07429999999999995" />
  <parent  link="l_hip_2" />
  <child  link="l_hip_3" />
  <dynamics  damping="0.1" />
 </joint>
 <link  name="l_upper_leg" >
  <inertial >
   <origin  rpy="1.5707963267948961 0 1.5707963267948961"  xyz="0.0033868999999999982 0.00010179999999998524 -0.07891600000000001" />
   <mass  value="1.8084" />
   <inertia  iyz="-0.00013681806887964204"  izz="0.006476192420462333"  ixz="-3.973994214790893e-06"  ixx="0.0064851267308372795"  ixy="-0.00012421121423996344"  iyy="0.0014625052983306384" />
  </inertial>
  <visual >
   <origin  rpy="1.5707963267948961 0 1.5707963267948961"  xyz="0.04370906139999998 -0.07010002459999994 0.24081299999999994" />
   <geometry >
    <mesh  filename="./iCubGenova04/meshes/simmechanics/sim_sea_2-5_l_thigh_prt-binary.stl"  scale="0.001 0.001 0.001" />
   </geometry>
   <material  name="dgreen" >
    <color  rgba="0.1 0.8 0.1 1" />
   </material>
  </visual>
  <collision >
   <origin  rpy="1.5707963267948961 0 1.5707963267948961"  xyz="0.04370906139999998 -0.07010002459999994 0.24081299999999994" />
   <geometry >
    <mesh  filename="./iCubGenova04/meshes/simmechanics/sim_sea_2-5_l_thigh_prt-binary.stl"  scale="0.001 0.001 0.001" />
   </geometry>
  </collision>
 </link>
 <joint  type="revolute"  name="l_hip_yaw" >
  <origin  rpy="-3.141592653589793 0 0"  xyz="0 0 0.014399999999999996" />
  <axis  xyz="0.0 2.220446049250313e-16 0.9999999999999998" />
  <parent  link="l_hip_3" />
  <child  link="l_upper_leg" />
  <limit  velocity="7.64"  lower="-1.3962634015954636"  upper="1.3962634015954636"  effort="37.0" />
  <dynamics  damping="0.223"  friction="0.0" />
 </joint>
 <link  name="l_upper_leg_back_contact" />
 <joint  type="fixed"  name="l_upper_leg_back_contact_fixed_joint" >
  <origin  rpy="0 1.5707963267948963 0"  xyz="-0.05125669999999999 0 0.014599999999999946" />
  <parent  link="l_upper_leg" />
  <child  link="l_upper_leg_back_contact" />
  <dynamics  damping="0.1" />
 </joint>
 <link  name="l_upper_leg_dh_frame" />
 <joint  type="fixed"  name="l_upper_leg_dh_frame_fixed_joint" >
  <origin  rpy="1.5707963267948966 0 0"  xyz="0 0 -0.14582499999999995" />
  <parent  link="l_upper_leg" />
  <child  link="l_upper_leg_dh_frame" />
  <dynamics  damping="0.1" />
 </joint>
 <link  name="l_lower_leg" >
  <inertial >
   <origin  rpy="1.5707963267948961 0 1.5707963267948961"  xyz="0.000999800000000002 0.0034968999999999695 -0.088567" />
   <mass  value="1.4724" />
   <inertia  iyz="-0.00023314283575035712"  izz="0.004570071832070392"  ixz="6.76166218238396e-05"  ixx="0.0042369860649861665"  ixy="-0.00023961518142281364"  iyy="0.0015222131363604985" />
  </inertial>
  <visual >
   <origin  rpy="1.5707963267948961 0 1.5707963267948961"  xyz="0.04370906139999998 -0.07010002479999991 0.38663799999999987" />
   <geometry >
    <mesh  filename="./iCubGenova04/meshes/simmechanics/sim_sea_2-5_l_shank_prt-binary.stl"  scale="0.001 0.001 0.001" />
   </geometry>
   <material  name="gray" >
    <color  rgba="0.5 0.5 0.5 1" />
   </material>
  </visual>
  <collision >
   <origin  rpy="1.5707963267948961 0 1.5707963267948961"  xyz="0.04370906139999998 -0.07010002479999991 0.38663799999999987" />
   <geometry >
    <mesh  filename="./iCubGenova04/meshes/simmechanics/sim_sea_2-5_l_shank_prt-binary.stl"  scale="0.001 0.001 0.001" />
   </geometry>
  </collision>
 </link>
 <joint  type="revolute"  name="l_knee" >
  <origin  rpy="0 0 0"  xyz="0 0 -0.14582499999999995" />
  <axis  xyz="-2.220446049250313e-16 -0.9999999999999998 0.0" />
  <parent  link="l_upper_leg" />
  <child  link="l_lower_leg" />
  <limit  velocity="7.64"  lower="-2.1642082724729685"  upper="0.06981317007977318"  effort="37.0" />
  <dynamics  damping="0.223"  friction="0.0" />
 </joint>
 <link  name="l_ankle_1" >
  <inertial >
   <origin  rpy="1.5707963267948961 0 1.5707963267948961"  xyz="0.015153099999999996 0.000902 4.199999999998649e-05" />
   <mass  value="0.6798" />
   <inertia  iyz="2.5726583414130826e-06"  izz="0.0003076030453774591"  ixz="3.046651057758992e-05"  ixx="0.00040447429734460005"  ixy="-1.1322603878053663e-06"  iyy="0.0004478873540695352" />
  </inertial>
  <visual >
   <origin  rpy="1.5707963267948961 0 1.5707963267948961"  xyz="0.04370906139999998 -0.07010002479999987 0.5871379999999998" />
   <geometry >
    <mesh  filename="./iCubGenova04/meshes/simmechanics/sim_sea_2-5_l_ankle_prt-binary.stl"  scale="0.001 0.001 0.001" />
   </geometry>
   <material  name="green" >
    <color  rgba="0 1 0 1" />
   </material>
  </visual>
  <collision >
   <origin  rpy="1.5707963267948961 0 1.5707963267948961"  xyz="0.04370906139999998 -0.07010002479999987 0.5871379999999998" />
   <geometry >
    <mesh  filename="./iCubGenova04/meshes/simmechanics/sim_sea_2-5_l_ankle_prt-binary.stl"  scale="0.001 0.001 0.001" />
   </geometry>
  </collision>
 </link>
 <joint  type="revolute"  name="l_ankle_pitch" >
  <origin  rpy="0 0 0"  xyz="0 0 -0.20049999999999996" />
  <axis  xyz="2.220446049250313e-16 0.9999999999999998 0.0" />
  <parent  link="l_lower_leg" />
  <child  link="l_ankle_1" />
  <limit  velocity="7.64"  lower="-0.6108652381980153"  upper="0.6108652381980153"  effort="37.0" />
  <dynamics  damping="0.223"  friction="0.0" />
 </joint>
 <link  name="l_ankle_2" >
  <inertial >
   <origin  rpy="1.5707963267948961 0 1.5707963267948961"  xyz="0.0011447000000000054 3.5999999999786203e-06 -0.03852" />
   <mass  value="0.265122" />
   <inertia  iyz="-4.29975e-06"  izz="0.000150937"  ixz="4.94571e-08"  ixx="0.000327222"  ixy="-4.74606e-08"  iyy="0.000248285" />
  </inertial>
  <visual >
   <origin  rpy="1.5707963267948961 0 1.5707963267948961"  xyz="0.043681699618582974 -0.07017520019076887 0.5871379999999998" />
   <geometry >
    <mesh  filename="./iCubGenova04/meshes/simmechanics/sim_sea_2-5_l_foot_prt-binary.stl"  scale="0.001 0.001 0.001" />
   </geometry>
   <material  name="black" >
    <color  rgba="0 0 0 1" />
   </material>
  </visual>
  <collision >
   <origin  rpy="1.5707963267948961 0 1.5707963267948961"  xyz="0.043681699618582974 -0.07017520019076887 0.5871379999999998" />
   <geometry >
    <mesh  filename="./iCubGenova04/meshes/simmechanics/sim_sea_2-5_l_foot_prt-binary.stl"  scale="0.001 0.001 0.001" />
   </geometry>
  </collision>
 </link>
 <joint  type="revolute"  name="l_ankle_roll" >
  <origin  rpy="0 0 0"  xyz="0 0 0" />
  <axis  xyz="0.9999999999999998 0.0 2.220446049250313e-16" />
  <parent  link="l_ankle_1" />
  <child  link="l_ankle_2" />
  <limit  velocity="7.64"  lower="-0.4363323129985824"  upper="0.4363323129985824"  effort="37.0" />
  <dynamics  damping="0.223"  friction="0.0" />
 </joint>
 <link  name="l_foot" >
  <inertial >
   <origin  rpy="-1.5707963267948961 0 -1.5707963267948961"  xyz="0.03366689999999999 -0.005373499999999989 -0.0011639999999999429" />
   <mass  value="0.382968" />
   <inertia  iyz="-7.64972e-06"  izz="0.000273846"  ixz="5.79273e-05"  ixx="0.00121242"  ixy="-3.69533e-07"  iyy="0.00141712" />
  </inertial>
  <visual >
   <origin  rpy="-1.5707963267948961 0 -1.5707963267948961"  xyz="0.04720906119999997 0.07010002480000013 -0.6474380002860819" />
   <geometry >
    <mesh  filename="./iCubGenova04/meshes/simmechanics/sim_sea_2-5_l_sole_prt-binary.stl"  scale="0.001 0.001 0.001" />
   </geometry>
   <material  name="red" >
    <color  rgba="1 0 0 1" />
   </material>
  </visual>
  <collision >
   <origin  rpy="-1.5707963267948961 0 -1.5707963267948961"  xyz="0.04720906119999997 0.07010002480000013 -0.6474380002860819" />
   <geometry >
    <mesh  filename="./iCubGenova04/meshes/simmechanics/sim_sea_2-5_l_sole_prt-binary.stl"  scale="0.001 0.001 0.001" />
   </geometry>
  </collision>
 </link>
 <joint  type="fixed"  name="l_foot_ft_sensor" >
  <origin  rpy="3.141592653589793 0 0"  xyz="-0.003499999999999996 0 -0.0605" />
  <parent  link="l_ankle_2" />
  <child  link="l_foot" />
  <dynamics  damping="0.1" />
 </joint>
 <link  name="l_sole" />
 <joint  type="fixed"  name="l_sole_fixed_joint" >
  <origin  rpy="-3.141592653589793 0 0"  xyz="0.003500000000000003 0 0.0040000000000000036" />
  <parent  link="l_foot" />
  <child  link="l_sole" />
  <dynamics  damping="0.1" />
 </joint>
 <link  name="l_sole_skin_0" />
 <joint  type="fixed"  name="l_sole_skin_0_fixed_joint" >
  <origin  rpy="0 0 0"  xyz="0.09320879999999998 0.032367999999999994 0.007500000000000062" />
  <parent  link="l_foot" />
  <child  link="l_sole_skin_0" />
  <dynamics  damping="0.1" />
 </joint>
 <link  name="l_sole_skin_1" />
 <joint  type="fixed"  name="l_sole_skin_1_fixed_joint" >
  <origin  rpy="0 0 0"  xyz="0.07885119999999998 0.019439899999999996 0.007500000000000062" />
  <parent  link="l_foot" />
  <child  link="l_sole_skin_1" />
  <dynamics  damping="0.1" />
 </joint>
 <link  name="l_sole_skin_2" />
 <joint  type="fixed"  name="l_sole_skin_2_fixed_joint" >
  <origin  rpy="0 0 0"  xyz="0.06047679999999998 0.02541059999999999 0.007500000000000062" />
  <parent  link="l_foot" />
  <child  link="l_sole_skin_2" />
  <dynamics  damping="0.1" />
 </joint>
 <link  name="l_sole_skin_3" />
 <joint  type="fixed"  name="l_sole_skin_3_fixed_joint" >
  <origin  rpy="0 0 0"  xyz="0.04611922999999998 0.012482499999999994 0.007500000000000062" />
  <parent  link="l_foot" />
  <child  link="l_sole_skin_3" />
  <dynamics  damping="0.1" />
 </joint>
 <link  name="l_sole_skin_4" />
 <joint  type="fixed"  name="l_sole_skin_4_fixed_joint" >
  <origin  rpy="0 0 0"  xyz="0.05013608999999999 -0.006414799999999998 0.007500000000000062" />
  <parent  link="l_foot" />
  <child  link="l_sole_skin_4" />
  <dynamics  damping="0.1" />
 </joint>
 <link  name="l_sole_skin_8" />
 <joint  type="fixed"  name="l_sole_skin_8_fixed_joint" >
  <origin  rpy="0 0 0"  xyz="0.07252739999999999 -0.031282799999999986 0.007500000000000062" />
  <parent  link="l_foot" />
  <child  link="l_sole_skin_8" />
  <dynamics  damping="0.1" />
 </joint>
 <link  name="l_sole_skin_9" />
 <joint  type="fixed"  name="l_sole_skin_9_fixed_joint" >
  <origin  rpy="0 0 0"  xyz="0.09090179999999999 -0.03725379999999999 0.007500000000000062" />
  <parent  link="l_foot" />
  <child  link="l_sole_skin_9" />
  <dynamics  damping="0.1" />
 </joint>
 <link  name="l_sole_skin_10" />
 <joint  type="fixed"  name="l_sole_skin_10_fixed_joint" >
  <origin  rpy="0 0 0"  xyz="0.10525929999999997 -0.024325399999999983 0.007500000000000062" />
  <parent  link="l_foot" />
  <child  link="l_sole_skin_10" />
  <dynamics  damping="0.1" />
 </joint>
 <link  name="l_sole_skin_11" />
 <joint  type="fixed"  name="l_sole_skin_11_fixed_joint" >
  <origin  rpy="0 0 0"  xyz="0.10124249999999999 -0.005428100000000005 0.007500000000000062" />
  <parent  link="l_foot" />
  <child  link="l_sole_skin_11" />
  <dynamics  damping="0.1" />
 </joint>
 <link  name="l_sole_skin_12" />
 <joint  type="fixed"  name="l_sole_skin_12_fixed_joint" >
  <origin  rpy="0 0 0"  xyz="0.08286809999999997 0.0005426000000000042 0.007500000000000062" />
  <parent  link="l_foot" />
  <child  link="l_sole_skin_12" />
  <dynamics  damping="0.1" />
 </joint>
 <link  name="l_sole_skin_13" />
 <joint  type="fixed"  name="l_sole_skin_13_fixed_joint" >
  <origin  rpy="0 0 0"  xyz="0.06851049999999999 -0.012385499999999994 0.007500000000000062" />
  <parent  link="l_foot" />
  <child  link="l_sole_skin_13" />
  <dynamics  damping="0.1" />
 </joint>
 <link  name="l_sole_skin_14" />
 <joint  type="fixed"  name="l_sole_skin_14_fixed_joint" >
  <origin  rpy="0 0 0"  xyz="0.11559999999999998 0.007499500000000006 0.007500000000000062" />
  <parent  link="l_foot" />
  <child  link="l_sole_skin_14" />
  <dynamics  damping="0.1" />
 </joint>
 <link  name="l_sole_skin_15" />
 <joint  type="fixed"  name="l_sole_skin_15_fixed_joint" >
  <origin  rpy="0 0 0"  xyz="0.11158319999999997 0.02639729999999999 0.007500000000000062" />
  <parent  link="l_foot" />
  <child  link="l_sole_skin_15" />
  <dynamics  damping="0.1" />
 </joint>
 <link  name="l_sole_skin_17" />
 <joint  type="fixed"  name="l_sole_skin_17_fixed_joint" >
  <origin  rpy="0 0 0"  xyz="-0.03771910000000001 0.004538500000000001 0.007500000000000062" />
  <parent  link="l_foot" />
  <child  link="l_sole_skin_17" />
  <dynamics  damping="0.1" />
 </joint>
 <link  name="l_sole_skin_18" />
 <joint  type="fixed"  name="l_sole_skin_18_fixed_joint" >
  <origin  rpy="0 0 0"  xyz="-0.05207669999999998 -0.008389699999999986 0.007500000000000062" />
  <parent  link="l_foot" />
  <child  link="l_sole_skin_18" />
  <dynamics  damping="0.1" />
 </joint>
 <link  name="l_sole_skin_19" />
 <joint  type="fixed"  name="l_sole_skin_19_fixed_joint" >
  <origin  rpy="0 0 0"  xyz="-0.04805979999999999 -0.027286999999999978 0.007500000000000062" />
  <parent  link="l_foot" />
  <child  link="l_sole_skin_19" />
  <dynamics  damping="0.1" />
 </joint>
 <link  name="l_sole_skin_20" />
 <joint  type="fixed"  name="l_sole_skin_20_fixed_joint" >
  <origin  rpy="0 0 0"  xyz="-0.02968539999999998 -0.03325779999999999 0.007500000000000062" />
  <parent  link="l_foot" />
  <child  link="l_sole_skin_20" />
  <dynamics  damping="0.1" />
 </joint>
 <link  name="l_sole_skin_21" />
 <joint  type="fixed"  name="l_sole_skin_21_fixed_joint" >
  <origin  rpy="0 0 0"  xyz="0.027744799999999986 0.0184533 0.007500000000000062" />
  <parent  link="l_foot" />
  <child  link="l_sole_skin_21" />
  <dynamics  damping="0.1" />
 </joint>
 <link  name="l_sole_skin_22" />
 <joint  type="fixed"  name="l_sole_skin_22_fixed_joint" >
  <origin  rpy="0 0 0"  xyz="0.03577849999999999 -0.019342899999999996 0.007500000000000062" />
  <parent  link="l_foot" />
  <child  link="l_sole_skin_22" />
  <dynamics  damping="0.1" />
 </joint>
 <link  name="l_sole_skin_24" />
 <joint  type="fixed"  name="l_sole_skin_24_fixed_joint" >
  <origin  rpy="0 0 0"  xyz="0.0030465999999999965 -0.02630029999999997 0.007500000000000062" />
  <parent  link="l_foot" />
  <child  link="l_sole_skin_24" />
  <dynamics  damping="0.1" />
 </joint>
 <link  name="l_sole_skin_25" />
 <joint  type="fixed"  name="l_sole_skin_25_fixed_joint" >
  <origin  rpy="0 0 0"  xyz="0.017404099999999995 -0.013372199999999987 0.007500000000000062" />
  <parent  link="l_foot" />
  <child  link="l_sole_skin_25" />
  <dynamics  damping="0.1" />
 </joint>
 <link  name="l_sole_skin_26" />
 <joint  type="fixed"  name="l_sole_skin_26_fixed_joint" >
  <origin  rpy="0 0 0"  xyz="0.013387299999999991 0.005525100000000005 0.007500000000000062" />
  <parent  link="l_foot" />
  <child  link="l_sole_skin_26" />
  <dynamics  damping="0.1" />
 </joint>
 <link  name="l_sole_skin_27" />
 <joint  type="fixed"  name="l_sole_skin_27_fixed_joint" >
  <origin  rpy="0 0 0"  xyz="-0.004987100000000001 0.011495900000000003 0.007500000000000062" />
  <parent  link="l_foot" />
  <child  link="l_sole_skin_27" />
  <dynamics  damping="0.1" />
 </joint>
 <link  name="l_sole_skin_28" />
 <joint  type="fixed"  name="l_sole_skin_28_fixed_joint" >
  <origin  rpy="0 0 0"  xyz="-0.0193447 -0.0014322999999999975 0.007500000000000062" />
  <parent  link="l_foot" />
  <child  link="l_sole_skin_28" />
  <dynamics  damping="0.1" />
 </joint>
 <link  name="l_sole_skin_29" />
 <joint  type="fixed"  name="l_sole_skin_29_fixed_joint" >
  <origin  rpy="0 0 0"  xyz="-0.015327899999999998 -0.020329600000000003 0.007500000000000062" />
  <parent  link="l_foot" />
  <child  link="l_sole_skin_29" />
  <dynamics  damping="0.1" />
 </joint>
 <link  name="base_link" />
 <joint  type="fixed"  name="base_link_fixed_joint" >
  <origin  rpy="0 -0 0"  xyz="0 0 0" />
  <axis  xyz="0 0 0" />
  <parent  link="root_link" />
  <child  link="base_link" />
 </joint>
 <link  name="l_foot_dh_frame" />
 <joint  type="fixed"  name="l_foot_dh_frame_fixed_joint" >
  <origin  rpy="0 1.5708 0"  xyz="0.0 0 0.004" />
  <axis  xyz="0 0 0" />
  <parent  link="l_foot" />
  <child  link="l_foot_dh_frame" />
 </joint>
 <link  name="r_foot_dh_frame" />
 <joint  type="fixed"  name="r_foot_dh_frame_fixed_joint" >
  <origin  rpy="0 1.5708 0"  xyz="0.0 0 0.004" />
  <axis  xyz="0 0 0" />
  <parent  link="r_foot" />
  <child  link="r_foot_dh_frame" />
 </joint>
 <transmission  name="actuator_r_hip_pitch" >
  <type  xmltext="SimpleTransmission" >
 SimpleTransmission
</type>
  <actuator  name="actuator_r_hip_pitch" >
   <mechanicalreduction  xmltext="1" >
 1
</mechanicalreduction>
  </actuator>
  <joint  name="r_hip_pitch" />
 </transmission>
 <transmission  name="actuator_r_hip_roll" >
  <type  xmltext="SimpleTransmission" >
 SimpleTransmission
</type>
  <actuator  name="actuator_r_hip_roll" >
   <mechanicalreduction  xmltext="1" >
 1
</mechanicalreduction>
  </actuator>
  <joint  name="r_hip_roll" />
 </transmission>
 <transmission  name="actuator_r_hip_yaw" >
  <type  xmltext="SimpleTransmission" >
 SimpleTransmission
</type>
  <actuator  name="actuator_r_hip_yaw" >
   <mechanicalreduction  xmltext="1" >
 1
</mechanicalreduction>
  </actuator>
  <joint  name="r_hip_yaw" />
 </transmission>
 <transmission  name="actuator_r_knee" >
  <type  xmltext="SimpleTransmission" >
 SimpleTransmission
</type>
  <actuator  name="actuator_r_knee" >
   <mechanicalreduction  xmltext="1" >
 1
</mechanicalreduction>
  </actuator>
  <joint  name="r_knee" />
 </transmission>
 <transmission  name="actuator_r_ankle_pitch" >
  <type  xmltext="SimpleTransmission" >
 SimpleTransmission
</type>
  <actuator  name="actuator_r_ankle_pitch" >
   <mechanicalreduction  xmltext="1" >
 1
</mechanicalreduction>
  </actuator>
  <joint  name="r_ankle_pitch" />
 </transmission>
 <transmission  name="actuator_r_ankle_roll" >
  <type  xmltext="SimpleTransmission" >
 SimpleTransmission
</type>
  <actuator  name="actuator_r_ankle_roll" >
   <mechanicalreduction  xmltext="1" >
 1
</mechanicalreduction>
  </actuator>
  <joint  name="r_ankle_roll" />
 </transmission>
 <transmission  name="actuator_torso_pitch" >
  <type  xmltext="SimpleTransmission" >
 SimpleTransmission
</type>
  <actuator  name="actuator_torso_pitch" >
   <mechanicalreduction  xmltext="1" >
 1
</mechanicalreduction>
  </actuator>
  <joint  name="torso_pitch" />
 </transmission>
 <transmission  name="actuator_torso_roll" >
  <type  xmltext="SimpleTransmission" >
 SimpleTransmission
</type>
  <actuator  name="actuator_torso_roll" >
   <mechanicalreduction  xmltext="1" >
 1
</mechanicalreduction>
  </actuator>
  <joint  name="torso_roll" />
 </transmission>
 <transmission  name="actuator_torso_yaw" >
  <type  xmltext="SimpleTransmission" >
 SimpleTransmission
</type>
  <actuator  name="actuator_torso_yaw" >
   <mechanicalreduction  xmltext="1" >
 1
</mechanicalreduction>
  </actuator>
  <joint  name="torso_yaw" />
 </transmission>
 <transmission  name="actuator_neck_pitch" >
  <type  xmltext="SimpleTransmission" >
 SimpleTransmission
</type>
  <actuator  name="actuator_neck_pitch" >
   <mechanicalreduction  xmltext="1" >
 1
</mechanicalreduction>
  </actuator>
  <joint  name="neck_pitch" />
 </transmission>
 <transmission  name="actuator_neck_roll" >
  <type  xmltext="SimpleTransmission" >
 SimpleTransmission
</type>
  <actuator  name="actuator_neck_roll" >
   <mechanicalreduction  xmltext="1" >
 1
</mechanicalreduction>
  </actuator>
  <joint  name="neck_roll" />
 </transmission>
 <transmission  name="actuator_neck_yaw" >
  <type  xmltext="SimpleTransmission" >
 SimpleTransmission
</type>
  <actuator  name="actuator_neck_yaw" >
   <mechanicalreduction  xmltext="1" >
 1
</mechanicalreduction>
  </actuator>
  <joint  name="neck_yaw" />
 </transmission>
 <transmission  name="actuator_r_shoulder_pitch" >
  <type  xmltext="SimpleTransmission" >
 SimpleTransmission
</type>
  <actuator  name="actuator_r_shoulder_pitch" >
   <mechanicalreduction  xmltext="1" >
 1
</mechanicalreduction>
  </actuator>
  <joint  name="r_shoulder_pitch" />
 </transmission>
 <transmission  name="actuator_r_shoulder_roll" >
  <type  xmltext="SimpleTransmission" >
 SimpleTransmission
</type>
  <actuator  name="actuator_r_shoulder_roll" >
   <mechanicalreduction  xmltext="1" >
 1
</mechanicalreduction>
  </actuator>
  <joint  name="r_shoulder_roll" />
 </transmission>
 <transmission  name="actuator_r_shoulder_yaw" >
  <type  xmltext="SimpleTransmission" >
 SimpleTransmission
</type>
  <actuator  name="actuator_r_shoulder_yaw" >
   <mechanicalreduction  xmltext="1" >
 1
</mechanicalreduction>
  </actuator>
  <joint  name="r_shoulder_yaw" />
 </transmission>
 <transmission  name="actuator_r_elbow" >
  <type  xmltext="SimpleTransmission" >
 SimpleTransmission
</type>
  <actuator  name="actuator_r_elbow" >
   <mechanicalreduction  xmltext="1" >
 1
</mechanicalreduction>
  </actuator>
  <joint  name="r_elbow" />
 </transmission>
 <transmission  name="actuator_r_wrist_prosup" >
  <type  xmltext="SimpleTransmission" >
 SimpleTransmission
</type>
  <actuator  name="actuator_r_wrist_prosup" >
   <mechanicalreduction  xmltext="1" >
 1
</mechanicalreduction>
  </actuator>
  <joint  name="r_wrist_prosup" />
 </transmission>
 <transmission  name="actuator_r_wrist_pitch" >
  <type  xmltext="SimpleTransmission" >
 SimpleTransmission
</type>
  <actuator  name="actuator_r_wrist_pitch" >
   <mechanicalreduction  xmltext="1" >
 1
</mechanicalreduction>
  </actuator>
  <joint  name="r_wrist_pitch" />
 </transmission>
 <transmission  name="actuator_r_wrist_yaw" >
  <type  xmltext="SimpleTransmission" >
 SimpleTransmission
</type>
  <actuator  name="actuator_r_wrist_yaw" >
   <mechanicalreduction  xmltext="1" >
 1
</mechanicalreduction>
  </actuator>
  <joint  name="r_wrist_yaw" />
 </transmission>
 <transmission  name="actuator_l_shoulder_pitch" >
  <type  xmltext="SimpleTransmission" >
 SimpleTransmission
</type>
  <actuator  name="actuator_l_shoulder_pitch" >
   <mechanicalreduction  xmltext="1" >
 1
</mechanicalreduction>
  </actuator>
  <joint  name="l_shoulder_pitch" />
 </transmission>
 <transmission  name="actuator_l_shoulder_roll" >
  <type  xmltext="SimpleTransmission" >
 SimpleTransmission
</type>
  <actuator  name="actuator_l_shoulder_roll" >
   <mechanicalreduction  xmltext="1" >
 1
</mechanicalreduction>
  </actuator>
  <joint  name="l_shoulder_roll" />
 </transmission>
 <transmission  name="actuator_l_shoulder_yaw" >
  <type  xmltext="SimpleTransmission" >
 SimpleTransmission
</type>
  <actuator  name="actuator_l_shoulder_yaw" >
   <mechanicalreduction  xmltext="1" >
 1
</mechanicalreduction>
  </actuator>
  <joint  name="l_shoulder_yaw" />
 </transmission>
 <transmission  name="actuator_l_elbow" >
  <type  xmltext="SimpleTransmission" >
 SimpleTransmission
</type>
  <actuator  name="actuator_l_elbow" >
   <mechanicalreduction  xmltext="1" >
 1
</mechanicalreduction>
  </actuator>
  <joint  name="l_elbow" />
 </transmission>
 <transmission  name="actuator_l_wrist_prosup" >
  <type  xmltext="SimpleTransmission" >
 SimpleTransmission
</type>
  <actuator  name="actuator_l_wrist_prosup" >
   <mechanicalreduction  xmltext="1" >
 1
</mechanicalreduction>
  </actuator>
  <joint  name="l_wrist_prosup" />
 </transmission>
 <transmission  name="actuator_l_wrist_pitch" >
  <type  xmltext="SimpleTransmission" >
 SimpleTransmission
</type>
  <actuator  name="actuator_l_wrist_pitch" >
   <mechanicalreduction  xmltext="1" >
 1
</mechanicalreduction>
  </actuator>
  <joint  name="l_wrist_pitch" />
 </transmission>
 <transmission  name="actuator_l_wrist_yaw" >
  <type  xmltext="SimpleTransmission" >
 SimpleTransmission
</type>
  <actuator  name="actuator_l_wrist_yaw" >
   <mechanicalreduction  xmltext="1" >
 1
</mechanicalreduction>
  </actuator>
  <joint  name="l_wrist_yaw" />
 </transmission>
 <transmission  name="actuator_l_hip_pitch" >
  <type  xmltext="SimpleTransmission" >
 SimpleTransmission
</type>
  <actuator  name="actuator_l_hip_pitch" >
   <mechanicalreduction  xmltext="1" >
 1
</mechanicalreduction>
  </actuator>
  <joint  name="l_hip_pitch" />
 </transmission>
 <transmission  name="actuator_l_hip_roll" >
  <type  xmltext="SimpleTransmission" >
 SimpleTransmission
</type>
  <actuator  name="actuator_l_hip_roll" >
   <mechanicalreduction  xmltext="1" >
 1
</mechanicalreduction>
  </actuator>
  <joint  name="l_hip_roll" />
 </transmission>
 <transmission  name="actuator_l_hip_yaw" >
  <type  xmltext="SimpleTransmission" >
 SimpleTransmission
</type>
  <actuator  name="actuator_l_hip_yaw" >
   <mechanicalreduction  xmltext="1" >
 1
</mechanicalreduction>
  </actuator>
  <joint  name="l_hip_yaw" />
 </transmission>
 <transmission  name="actuator_l_knee" >
  <type  xmltext="SimpleTransmission" >
 SimpleTransmission
</type>
  <actuator  name="actuator_l_knee" >
   <mechanicalreduction  xmltext="1" >
 1
</mechanicalreduction>
  </actuator>
  <joint  name="l_knee" />
 </transmission>
 <transmission  name="actuator_l_ankle_pitch" >
  <type  xmltext="SimpleTransmission" >
 SimpleTransmission
</type>
  <actuator  name="actuator_l_ankle_pitch" >
   <mechanicalreduction  xmltext="1" >
 1
</mechanicalreduction>
  </actuator>
  <joint  name="l_ankle_pitch" />
 </transmission>
 <transmission  name="actuator_l_ankle_roll" >
  <type  xmltext="SimpleTransmission" >
 SimpleTransmission
</type>
  <actuator  name="actuator_l_ankle_roll" >
   <mechanicalreduction  xmltext="1" >
 1
</mechanicalreduction>
  </actuator>
  <joint  name="l_ankle_roll" />
 </transmission>
</robot>
