<?xml version="1.0"?>
<robot  name="DIVA_1_Hardware_URDF" >
 <material  name="blue" >
  <color  rgba="0 0 0.8 1.0" />
 </material>
 <material  name="red" >
  <color  rgba="0.8 0 0 1.0" />
 </material>
  <material  name="green" >
  <color  rgba="0 0.8 0 1.0" />
 </material>

 <link  name="base_link" >
  <visual >
   <origin  xyz="0 0 0.015"  rpy="0 0 0" />
   <material  name="red" />
   <geometry >
    <cylinder  radius="0.1"  length="0.03" />
   </geometry>
  </visual>
 </link>

 <link  name="link1" >
  <visual>
   <origin  xyz="0 0 0.1105"  rpy="0 0 0" />
   <material  name="blue" />
   <geometry >
    <cylinder  radius="0.02"  length="0.161" />
   </geometry>
  </visual>
 </link>

<joint  type="continuous"  name="joint1" >
  <parent  link="base_link" />
  <child  link="link1" />
  <origin  xyz="0 0 0"  rpy="0 0 0" />
  <axis  xyz="0 0 1" />
 </joint>

 <link  name="link2" >
  <visual >
   <origin  xyz="0 0 0.041"  rpy="0 0 0" />
   <material  name="green" />
   <geometry >
    <cylinder  radius="0.02"  length="0.082" />
   </geometry>
  </visual>
 </link>

<joint  type="continuous"  name="joint2" >
  <parent  link="link1" />
  <child  link="link2" />
  <origin  xyz="0 0 0.191"  rpy="1.5707 0 0" />
  <axis  xyz="1 0 0" />
 </joint>

 <link  name="link3" >
  <visual >
   <origin  xyz="0 0 0.107"  rpy="0 0 0" />
   <material  name="blue" />
   <geometry >
    <cylinder  radius="0.02"  length="0.214" />
   </geometry>
  </visual>
 </link>

 <joint  type="continuous"  name="joint3" >
  <parent  link="link2" />
  <child  link="link3" />
  <origin  xyz="0 0 0.082"  rpy="0 0 0" />
  <axis  xyz="0 0 1" />
 </joint>

<link  name="link4" >
  <visual >
   <origin  xyz="0 0 0.05"  rpy="0 0 0" />
   <material  name="green" />
   <geometry >
    <cylinder  radius="0.02"  length="0.1" />
   </geometry>
  </visual>
 </link>

 <joint  type="continuous"  name="joint4" >
  <parent  link="link3" />
  <child  link="link4" />
  <origin  xyz="0 0 0.214"  rpy="0 0 0" />
  <axis  xyz="0 1 0" />
 </joint>

<link  name="link5" >
  <visual >
   <origin  xyz="0 0 0.0375"  rpy="0 0 0" />
   <material  name="blue" />
   <geometry >
    <cylinder  radius="0.02"  length="0.075" />
   </geometry>
  </visual>
 </link>

 <joint  type="continuous"  name="joint5" >
  <parent  link="link4" />
  <child  link="link5" />
  <origin  xyz="0 0 0.1"  rpy="0 0 0" />
  <axis  xyz="0 0 1" />
 </joint>

<link  name="bottle" >
  <visual >
   <origin  xyz="0 0 0.0875"  rpy="0 1.5708 0" />
   <material  name="blue" />
   <geometry >
    <cylinder  radius="0.02"  length="0.175" />
   </geometry>
  </visual>
 </link>

 <joint  type="fixed"  name="grip" >
  <parent  link="link5" />
  <child  link="bottle" />
  <origin  xyz="0 0 0"  rpy="0 0 0" />
  <axis  xyz="0 0 1" />
 </joint>

</robot>
