<?xml version="1.0"?>
<robot  name="twolink130893178" >
 <material  name="blue" >
  <color  rgba="0 0 0.8 1.0" />
 </material>
 <material  name="red" >
  <color  rgba="0.8 0 0 1.0" />
 </material>
 <link  name="base_link" >
  <visual >
   <origin  rpy="0 1.5707 0"  xyz="0 0 0" />
   <material  name="red" />
   <geometry >
    <cylinder  radius="0.1"  length="0.05" />
   </geometry>
  </visual>
 </link>
 <joint  name="joint1"  type="revolute" >
  <parent  link="base_link" />
  <child  link="link1" />
  <origin  xyz="0 0 0"  rpy="0 0 0" />
  <axis  xyz="1 0 0" />
 </joint>
 <link  name="link1" >
  <inertial >
   <origin  rpy="0 0 0"  xyz="0 0 0.18" />
   <mass  value="0.37362875461578365" />
   <inertia  ixy="0.0"  iyy="0.00015567864775657654"  iyz="0.0"  ixz="0.0"  izz="0.0041130298737287515"  ixx="0.0041130298737287515" />
  </inertial>
  <visual >
   <origin  rpy="0 0 0"  xyz="0 0 0.18" />
   <material  name="blue" />
   <geometry >
    <box  size="0.05 0.05 0.36" />
   </geometry>
  </visual>
 </link>
 <joint  name="joint-joint-1"  type="fixed" >
  <parent  link="link1" />
  <child  link="joint-link-1" />
  <origin  xyz="0 0 0.36"  rpy="1.5707 0 0" />
  <axis  xyz="1 0 0" />
 </joint>
 <link  name="joint-link-1" >
  <inertial >
   <origin  rpy="0 0 0"  xyz="0 0 0" />
   <mass  value="0.4523" />
   <inertia  ixy="0"  iyy="0"  iyz="0"  ixz="0"  izz="0"  ixx="0" />
  </inertial>
  <visual >
   <origin  rpy="0 0 0"  xyz="0 0 0" />
   <material  name="red" />
   <geometry >
    <sphere  radius="0.05" />
   </geometry>
  </visual>
 </link>
 <joint  name="joint2"  type="revolute" >
  <parent  link="link1" />
  <child  link="link2" />
  <origin  xyz="0 0 0.36"  rpy="1.5707 0 0" />
  <axis  xyz="1 0 0" />
 </joint>
 <link  name="link2" >
  <inertial >
   <origin  rpy="0 0 0"  xyz="0 0 0.18" />
   <mass  value="0.37362875461578365" />
   <inertia  ixy="0.0"  iyy="0.00015567864775657654"  iyz="0.0"  ixz="0.0"  izz="0.0041130298737287515"  ixx="0.0041130298737287515" />
  </inertial>
  <visual >
   <origin  rpy="0 0 0"  xyz="0 0 0.18" />
   <material  name="blue" />
   <geometry >
    <box  size="0.05 0.05 0.36" />
   </geometry>
  </visual>
 </link>
 <joint  name="eef_joint"  type="fixed" >
  <parent  link="link2" />
  <child  link="eef" />
  <origin  xyz="0 0 0.36"  rpy="0 0 0" />
 </joint>
 <!-- Add corresponding load at the eef -->
 <link  name="eef">
   <inertial >
    <origin  rpy="0 0 0"  xyz="0 0 0" />
    <mass  value="1" />
    <inertia  ixy="0"  iyy="0"  iyz="0"  ixz="0"  izz="0"  ixx="0" />
   </inertial>
 </link>
 <transmission  name="motor1" >
  <type  xmltext="SimpleTransmission" >
   SimpleTransmission
  </type>
  <actuator  name="motor1" >
   <mechanicalreduction  xmltext="1" >
    1
   </mechanicalreduction>
  </actuator>
  <joint  name="joint1" />
 </transmission>
 <transmission  name="motor2" >
  <type  xmltext="SimpleTransmission" >
   SimpleTransmission
  </type>
  <actuator  name="motor2" >
   <mechanicalreduction  xmltext="1" >
    1
   </mechanicalreduction>
  </actuator>
  <joint  name="joint2" />
 </transmission>
</robot>

<!-- [3.600000e-01 3.600000e-01 5.000000e+01 1.577070e+01 4.523000e-01
 1.200320e+01 1.742067e+02 9.929800e+00 6.462338e+02 6.942400e+07
 5.610200e+07]-->
