<?xml version="1.0"?>
<robot  name="divar3v3880924534" >
 <material  name="blue" >
  <color  rgba="0 0 0.8 1.0" />
 </material>
 <material  name="red" >
  <color  rgba="0.8 0 0 1.0" />
 </material>
 <link  name="base_link" >
  <visual >
   <origin  xyz="0 0 0"  rpy="0 0 0" />
   <material  name="red" />
   <geometry >
    <cylinder  radius="0.1"  length="0.05" />
   </geometry>
  </visual>
 </link>
 <joint  name="joint1"  type="revolute" >
  <parent  link="base_link" />
  <child  link="link1" />
  <origin  xyz="0 0 0"  rpy="0 0 0" />
  <axis  xyz="0 0 1" />
 </joint>
 <link  name="link1" >
  <inertial >
   <origin  xyz="0 0 0.019581355806081446"  rpy="0 0 0" />
   <mass  value="0.41120847192771043" />
   <inertia  ixx="0.0003952302122114247"  izz="0.0003952302122114247"  iyz="0.0"  ixz="0.0"  ixy="0.0"  iyy="0.0006853474532128507" />
  </inertial>
  <visual >
   <origin  xyz="0 0 0.019581355806081446"  rpy="0 0 0" />
   <material  name="blue" />
   <geometry >
    <box  size="0.05 0.1 0.03916271161216289" />
   </geometry>
  </visual>
 </link>
 <joint  name="joint-joint-1"  type="fixed" >
  <parent  link="link1" />
  <child  link="joint-link-1" />
  <origin  xyz="0 0 0.03916271161216289"  rpy="1.5707 0 0" />
  <axis  xyz="1 0 0" />
 </joint>
 <link  name="joint-link-1" >
  <inertial >
   <origin  xyz="0 0 0"  rpy="0 0 0" />
   <mass  value="1.127682365903618" />
   <inertia  ixx="0"  izz="0"  iyz="0"  ixz="0"  ixy="0"  iyy="0" />
  </inertial>
  <visual >
   <origin  xyz="0 0 0"  rpy="0 0 0" />
   <material  name="red" />
   <geometry >
    <sphere  radius="0.05" />
   </geometry>
  </visual>
 </link>
 <joint  name="joint2"  type="revolute" >
  <parent  link="link1" />
  <child  link="link2" />
  <origin  xyz="0 0 0.03916271161216289"  rpy="1.5707 0 0" />
  <axis  xyz="1 0 0" />
 </joint>
 <link  name="link2" >
  <inertial >
   <origin  xyz="0 0 0.15033984773613931"  rpy="0 0 0" />
   <mass  value="3.1571368024589264" />
   <inertia  ixx="0.02641688947939064"  izz="0.02641688947939064"  iyz="0.0"  ixz="0.0"  ixy="0.0"  iyy="0.005261894670764878" />
  </inertial>
  <visual >
   <origin  xyz="0 0 0.15033984773613931"  rpy="0 0 0" />
   <material  name="blue" />
   <geometry >
    <box  size="0.05 0.1 0.30067969547227863" />
   </geometry>
  </visual>
 </link>
 <joint  name="joint-joint-2"  type="fixed" >
  <parent  link="link2" />
  <child  link="joint-link-2" />
  <origin  xyz="0 0 0.30067969547227863"  rpy="1.5707 0 0" />
  <axis  xyz="1 0 0" />
 </joint>
 <link  name="joint-link-2" >
  <inertial >
   <origin  xyz="0 0 0"  rpy="0 0 0" />
   <mass  value="1.127682365903618" />
   <inertia  ixx="0"  izz="0"  iyz="0"  ixz="0"  ixy="0"  iyy="0" />
  </inertial>
  <visual >
   <origin  xyz="0 0 0"  rpy="0 0 0" />
   <material  name="red" />
   <geometry >
    <sphere  radius="0.05" />
   </geometry>
  </visual>
 </link>
 <joint  name="joint3"  type="revolute" >
  <parent  link="link2" />
  <child  link="link3" />
  <origin  xyz="0 0 0.30067969547227863"  rpy="0 0 0" />
  <axis  xyz="0 0 1" />
 </joint>
 <link  name="link3" >
  <inertial >
   <origin  xyz="0 0 0.0885078629850526"  rpy="0 0 0" />
   <mass  value="1.8586651226861048" />
   <inertia  ixx="0.006402259874304681"  izz="0.006402259874304681"  iyz="0.0"  ixz="0.0"  ixy="0.0"  iyy="0.003097775204476842" />
  </inertial>
  <visual >
   <origin  xyz="0 0 0.0885078629850526"  rpy="0 0 0" />
   <material  name="blue" />
   <geometry >
    <box  size="0.05 0.1 0.1770157259701052" />
   </geometry>
  </visual>
 </link>
 <joint  name="joint-joint-3"  type="fixed" >
  <parent  link="link3" />
  <child  link="joint-link-3" />
  <origin  xyz="0 0 0.1770157259701052"  rpy="1.5707 0 0" />
  <axis  xyz="1 0 0" />
 </joint>
 <link  name="joint-link-3" >
  <inertial >
   <origin  xyz="0 0 0"  rpy="0 0 0" />
   <mass  value="1.127682365903618" />
   <inertia  ixx="0"  izz="0"  iyz="0"  ixz="0"  ixy="0"  iyy="0" />
  </inertial>
  <visual >
   <origin  xyz="0 0 0"  rpy="0 0 0" />
   <material  name="red" />
   <geometry >
    <sphere  radius="0.05" />
   </geometry>
  </visual>
 </link>
 <joint  name="joint4"  type="revolute" >
  <parent  link="link3" />
  <child  link="link4" />
  <origin  xyz="0 0 0.1770157259701052"  rpy="0 0 0" />
  <axis  xyz="0 1 0" />
 </joint>
 <link  name="link4" >
  <inertial >
   <origin  xyz="0 0 0.039171970118870116"  rpy="0 0 0" />
   <mass  value="0.8226113724962726" />
   <inertia  ixx="0.0011062596311257739"  izz="0.0011062596311257739"  iyz="0.0"  ixz="0.0"  ixy="0.0"  iyy="0.0013710189541604545" />
  </inertial>
  <visual >
   <origin  xyz="0 0 0.039171970118870116"  rpy="0 0 0" />
   <material  name="blue" />
   <geometry >
    <box  size="0.05 0.1 0.07834394023774023" />
   </geometry>
  </visual>
 </link>
 <joint  name="joint-joint-4"  type="fixed" >
  <parent  link="link4" />
  <child  link="joint-link-4" />
  <origin  xyz="0 0 0.07834394023774023"  rpy="1.5707 0 0" />
  <axis  xyz="1 0 0" />
 </joint>
 <link  name="joint-link-4" >
  <inertial >
   <origin  xyz="0 0 0"  rpy="0 0 0" />
   <mass  value="1.127682365903618" />
   <inertia  ixx="0"  izz="0"  iyz="0"  ixz="0"  ixy="0"  iyy="0" />
  </inertial>
  <visual >
   <origin  xyz="0 0 0"  rpy="0 0 0" />
   <material  name="red" />
   <geometry >
    <sphere  radius="0.05" />
   </geometry>
  </visual>
 </link>
 <joint  name="joint5"  type="revolute" >
  <parent  link="link4" />
  <child  link="link5" />
  <origin  xyz="0 0 0.07834394023774023"  rpy="0 0 0" />
  <axis  xyz="0 0 1" />
 </joint>
 <link  name="link5" >
  <inertial >
   <origin  xyz="0 0 0.04623688162957905"  rpy="0 0 0" />
   <mass  value="0.9709745142211602" />
   <inertia  ixx="0.0015010777987220388"  izz="0.0015010777987220388"  iyz="0.0"  ixz="0.0"  ixy="0.0"  iyy="0.0016182908570352673" />
  </inertial>
  <visual >
   <origin  xyz="0 0 0.04623688162957905"  rpy="0 0 0" />
   <material  name="blue" />
   <geometry >
    <box  size="0.05 0.1 0.0924737632591581" />
   </geometry>
  </visual>
 </link>
 <joint  name="joint-joint-5"  type="fixed" >
  <parent  link="link5" />
  <child  link="joint-link-5" />
  <origin  xyz="0 0 0.0924737632591581"  rpy="1.5707 0 0" />
  <axis  xyz="1 0 0" />
 </joint>
 <link  name="joint-link-5" >
  <inertial >
   <origin  xyz="0 0 0"  rpy="0 0 0" />
   <mass  value="1.127682365903618" />
   <inertia  ixx="0"  izz="0"  iyz="0"  ixz="0"  ixy="0"  iyy="0" />
  </inertial>
  <visual >
   <origin  xyz="0 0 0"  rpy="0 0 0" />
   <material  name="red" />
   <geometry >
    <sphere  radius="0.05" />
   </geometry>
  </visual>
 </link>
 <joint  name="joint6"  type="revolute" >
  <parent  link="link5" />
  <child  link="link6" />
  <origin  xyz="0 0 0.0924737632591581"  rpy="0 0 0" />
  <axis  xyz="0 1 0" />
 </joint>
 <link  name="link6" >
  <inertial >
   <origin  xyz="0 0 0.0005"  rpy="0 0 0" />
   <mass  value="0.010500000000000002" />
   <inertia  ixx="8.750875000000003e-06"  izz="8.750875000000003e-06"  iyz="0.0"  ixz="0.0"  ixy="0.0"  iyy="1.7500000000000005e-05" />
  </inertial>
  <visual >
   <origin  xyz="0 0 0.0005"  rpy="0 0 0" />
   <material  name="blue" />
   <geometry >
    <box  size="0.05 0.1 0.001" />
   </geometry>
  </visual>
 </link>
 <joint  name="joint7"  type="revolute" >
  <parent  link="link6" />
  <child  link="link7" />
  <origin  xyz="0 0 0.001"  rpy="0 0 0" />
  <axis  xyz="1 0 0" />
 </joint>
 <link  name="link7" >
  <inertial >
   <origin  xyz="0 0 0.1219888471315587"  rpy="0 0 0" />
   <mass  value="2.5617657897627333" />
   <inertia  ixx="0.014842255158299232"  izz="0.014842255158299232"  iyz="0.0"  ixz="0.0"  ixy="0.0"  iyy="0.0042696096496045565" />
  </inertial>
  <visual >
   <origin  xyz="0 0 0.1219888471315587"  rpy="0 0 0" />
   <material  name="blue" />
   <geometry >
    <box  size="0.05 0.1 0.2439776942631174" />
   </geometry>
  </visual>
 </link>
 <joint  name="eef_joint"  type="fixed" >
  <parent  link="link7" />
  <child  link="eef" />
  <origin  xyz="0 0 0.2439776942631174"  rpy="0 0 0" />
 </joint>
 <link  name="eef" >
  <inertial >
   <origin  xyz="0 0 0"  rpy="0 0 0" />
   <mass  value="1" />
   <inertia  ixx="0"  izz="0"  iyz="0"  ixz="0"  ixy="0"  iyy="0" />
  </inertial>
 </link>
 <transmission  name="motor1" >
  <type  xmltext="SimpleTransmission" >
   SimpleTransmission
  </type>
  <actuator  name="motor1" >
   <mechanicalreduction  xmltext="1" >
    1
   </mechanicalreduction>
  </actuator>
  <joint  name="joint1" />
 </transmission>
 <transmission  name="motor2" >
  <type  xmltext="SimpleTransmission" >
   SimpleTransmission
  </type>
  <actuator  name="motor2" >
   <mechanicalreduction  xmltext="1" >
    1
   </mechanicalreduction>
  </actuator>
  <joint  name="joint2" />
 </transmission>
 <transmission  name="motor3" >
  <type  xmltext="SimpleTransmission" >
   SimpleTransmission
  </type>
  <actuator  name="motor3" >
   <mechanicalreduction  xmltext="1" >
    1
   </mechanicalreduction>
  </actuator>
  <joint  name="joint3" />
 </transmission>
 <transmission  name="motor4" >
  <type  xmltext="SimpleTransmission" >
   SimpleTransmission
  </type>
  <actuator  name="motor4" >
   <mechanicalreduction  xmltext="1" >
    1
   </mechanicalreduction>
  </actuator>
  <joint  name="joint4" />
 </transmission>
 <transmission  name="motor5" >
  <type  xmltext="SimpleTransmission" >
   SimpleTransmission
  </type>
  <actuator  name="motor5" >
   <mechanicalreduction  xmltext="1" >
    1
   </mechanicalreduction>
  </actuator>
  <joint  name="joint5" />
 </transmission>
 <transmission  name="motor6" >
  <type  xmltext="SimpleTransmission" >
   SimpleTransmission
  </type>
  <actuator  name="motor6" >
   <mechanicalreduction  xmltext="1" >
    1
   </mechanicalreduction>
  </actuator>
  <joint  name="joint6" />
 </transmission>
 <transmission  name="motor7" >
  <type  xmltext="SimpleTransmission" >
   SimpleTransmission
  </type>
  <actuator  name="motor7" >
   <mechanicalreduction  xmltext="1" >
    1
   </mechanicalreduction>
  </actuator>
  <joint  name="joint7" />
 </transmission>
</robot>

ot>


/robot>

ot>

