<?xml version="1.0" encoding="utf-8"?>
<!-- This URDF was automatically created by SolidWorks to URDF Exporter! Originally created by Stephen Brawner (brawner@gmail.com)
     Commit Version: 1.6.0-1-g15f4949  Build Version: 1.6.7594.29634
     For more information, please see http://wiki.ros.org/sw_urdf_exporter -->
<robot
  name="DIVAR2V">
  <link
    name="base_link">
    <inertial>
      <origin
        xyz="0.0338364901739526 -0.00033626459572959 -9.69008007512981E-05"
        rpy="0 0 0" />
      <mass
        value="0.298766922776314" />
      <inertia
        ixx="0.000318637899977369"
        ixy="-3.60356780952487E-06"
        ixz="-8.01985345093479E-06"
        iyy="0.000243715324843074"
        iyz="-3.99019261867312E-05"
        izz="0.000150326005973297" />
    </inertial>
    <visual>
      <origin
        xyz="0 0 0"
        rpy="0 0 0" />
      <geometry>
        <mesh
          filename="../meshes/base_link.obj" />
      </geometry>
      <material
        name="">
        <color
          rgba="0.627450980392157 0.627450980392157 0.627450980392157 1" />
      </material>
    </visual>
    <collision>
      <origin
        xyz="0 0 0"
        rpy="0 0 0" />
      <geometry>
        <mesh
          filename="../meshes/base_link.obj" />
      </geometry>
    </collision>
  </link>
  <link
    name="should1">
    <inertial>
      <origin
        xyz="0.0015605 0.00039961 0.1303"
        rpy="0 0 0" />
      <mass
        value="0.49149" />
      <inertia
        ixx="0.00063086"
        ixy="1.0188E-07"
        ixz="-4.5061E-06"
        iyy="0.00036201"
        iyz="2.3142E-08"
        izz="0.00060371" />
    </inertial>
    <visual>
      <origin
        xyz="0 0 0"
        rpy="0 0 0" />
      <geometry>
        <mesh
          filename="../meshes/should1.obj" />
      </geometry>
      <material
        name="">
        <color
          rgba="0.3451 0.3451 0.3451 1" />
      </material>
    </visual>
    <collision>
      <origin
        xyz="0 0 0"
        rpy="0 0 0" />
      <geometry>
        <mesh
          filename="../meshes/should1.obj" />
      </geometry>
    </collision>
  </link>
  <joint
    name="should1"
    type="revolute">
    <origin
      xyz="0.025 0 0"
      rpy="0 -1.5708 0" />
    <parent
      link="base_link" />
    <child
      link="should1" />
    <axis
      xyz="0 0 1" />
  </joint>
  <link
    name="shoud2">
    <inertial>
      <origin
        xyz="-8.9718E-05 -0.06338 0.0072056"
        rpy="0 0 0" />
      <mass
        value="0.49737" />
      <inertia
        ixx="0.0002988"
        ixy="-1.088E-06"
        ixz="-1.2272E-05"
        iyy="0.00032243"
        iyz="-1.6792E-06"
        izz="0.00027812" />
    </inertial>
    <visual>
      <origin
        xyz="0 0 0"
        rpy="0 0 0" />
      <geometry>
        <mesh
          filename="../meshes/shoud2.obj" />
      </geometry>
      <material
        name="">
        <color
          rgba="0.3451 0.3451 0.3451 1" />
      </material>
    </visual>
    <collision>
      <origin
        xyz="0 0 0"
        rpy="0 0 0" />
      <geometry>
        <mesh
          filename="../meshes/shoud2.obj" />
      </geometry>
    </collision>
  </link>
  <joint
    name="shoud2"
    type="revolute">
    <origin
      xyz="0.00465 0 0.16275"
      rpy="3.1416 -1.5708 0" />
    <parent
      link="should1" />
    <child
      link="shoud2" />
    <axis
      xyz="0 0 1" />
  </joint>
  <link
    name="upper arm">
    <inertial>
      <origin
        xyz="-0.0027038 -0.00048992 0.18137"
        rpy="0 0 0" />
      <mass
        value="0.3387" />
      <inertia
        ixx="0.00023922"
        ixy="-2.8245E-06"
        ixz="2.5833E-06"
        iyy="0.00017088"
        iyz="1.3582E-05"
        izz="0.00018722" />
    </inertial>
    <visual>
      <origin
        xyz="0 0 0"
        rpy="0 0 0" />
      <geometry>
        <mesh
          filename="../meshes/upper arm.obj" />
      </geometry>
      <material
        name="">
        <color
          rgba="0.3451 0.3451 0.3451 1" />
      </material>
    </visual>
    <collision>
      <origin
        xyz="0 0 0"
        rpy="0 0 0" />
      <geometry>
        <mesh
          filename="../meshes/upper arm.obj" />
      </geometry>
    </collision>
  </link>
  <joint
    name="upper arm"
    type="revolute">
    <origin
      xyz="0 -0.088176 0.0044"
      rpy="1.5708 -1.4835 0" />
    <parent
      link="shoud2" />
    <child
      link="upper arm" />
    <axis
      xyz="0 0 1" />
  </joint>
  <link
    name="elbow">
    <inertial>
      <origin
        xyz="-0.046076 -0.00066572 0.010386"
        rpy="0 0 0" />
      <mass
        value="0.24525" />
      <inertia
        ixx="0.0001459"
        ixy="2.3566E-06"
        ixz="2.0693E-06"
        iyy="0.00010742"
        iyz="-1.0243E-05"
        izz="0.00015654" />
    </inertial>
    <visual>
      <origin
        xyz="0 0 0"
        rpy="0 0 0" />
      <geometry>
        <mesh
          filename="../meshes/elbow.obj" />
      </geometry>
      <material
        name="">
        <color
          rgba="0.3451 0.3451 0.3451 1" />
      </material>
    </visual>
    <collision>
      <origin
        xyz="0 0 0"
        rpy="0 0 0" />
      <geometry>
        <mesh
          filename="../meshes/elbow.obj" />
      </geometry>
    </collision>
  </link>
  <joint
    name="elbow"
    type="revolute">
    <origin
      xyz="-0.0083238 0.00013216 0.21184"
      rpy="1.5708 0.2618 1.5708" />
    <parent
      link="upper arm" />
    <child
      link="elbow" />
    <axis
      xyz="0 0 1" />
  </joint>
  <link
    name="under arm">
    <inertial>
      <origin
        xyz="6.9412E-07 -8.0151E-06 0.096764"
        rpy="0 0 0" />
      <mass
        value="0.1834" />
      <inertia
        ixx="0.00048569"
        ixy="-3.3211E-09"
        ixz="-1.2569E-08"
        iyy="0.00048571"
        iyz="2.0111E-10"
        izz="0.000142" />
    </inertial>
    <visual>
      <origin
        xyz="0 0 0"
        rpy="0 0 0" />
      <geometry>
        <mesh
          filename="../meshes/under arm.obj" />
      </geometry>
      <material
        name="">
        <color
          rgba="0.054902 0.47059 0.9098 1" />
      </material>
    </visual>
    <collision>
      <origin
        xyz="0 0 0"
        rpy="0 0 0" />
      <geometry>
        <mesh
          filename="../meshes/under arm.obj" />
      </geometry>
    </collision>
  </link>
  <joint
    name="under arm"
    type="revolute">
    <origin
      xyz="-0.070176 0.00013216 0.0070738"
      rpy="1.1947 -1.5708 -1.1926" />
    <parent
      link="elbow" />
    <child
      link="under arm" />
    <axis
      xyz="0 0 1" />
  </joint>
  <joint  name="eef_joint"  type="fixed" >
   <parent  link="under arm" />
   <child  link="eef" />
   <origin  xyz="0 0 0.25"  rpy="0 0 0" />
  </joint>
  <link  name="eef" />
  <transmission  name="motor1" >
   <type  xmltext="SimpleTransmission" >
    SimpleTransmission
   </type>
   <actuator  name="motor1" >
    <mechanicalreduction  xmltext="1" >
     1
    </mechanicalreduction>
   </actuator>
   <joint  name="should1" />
  </transmission>

  <transmission  name="motor1" >
   <type  xmltext="SimpleTransmission" >
    SimpleTransmission
   </type>
   <actuator  name="motor2" >
    <mechanicalreduction  xmltext="1" >
     1
    </mechanicalreduction>
   </actuator>
   <joint  name="shoud2" />
  </transmission>

  <transmission  name="motor1" >
   <type  xmltext="SimpleTransmission" >
    SimpleTransmission
   </type>
   <actuator  name="motor3" >
    <mechanicalreduction  xmltext="1" >
     1
    </mechanicalreduction>
   </actuator>
   <joint  name="upper arm" />
  </transmission>

  <transmission  name="motor1" >
   <type  xmltext="SimpleTransmission" >
    SimpleTransmission
   </type>
   <actuator  name="motor4" >
    <mechanicalreduction  xmltext="1" >
     1
    </mechanicalreduction>
   </actuator>
   <joint  name="elbow" />
  </transmission>

  <transmission  name="motor1" >
   <type  xmltext="SimpleTransmission" >
    SimpleTransmission
   </type>
   <actuator  name="motor5" >
    <mechanicalreduction  xmltext="1" >
     1
    </mechanicalreduction>
   </actuator>
   <joint  name="upper arm" />
  </transmission>
</robot>
