<?xml version="1.0"?>
<robot  name="TwoLinkStruct9950925552" >
 <material  name="blue" >
  <color  rgba="0 0 0.8 1.0" />
 </material>
 <material  name="red" >
  <color  rgba="0.8 0 0 1.0" />
 </material>
 <link  name="base_link" >
  <visual >
   <origin  rpy="0 1.5707 0"  xyz="0 0 0" />
   <material  name="red" />
   <geometry >
    <cylinder  length="0.05"  radius="0.1" />
   </geometry>
  </visual>
 </link>
 <joint  type="revolute"  name="joint1" >
  <parent  link="base_link" />
  <child  link="link1" />
  <origin  xyz="0 0 0"  rpy="0 0 0" />
  <axis  xyz="1 0 0" />
 </joint>
 <link  name="link1" >
  <inertial >
   <origin  rpy="0 0 0"  xyz="0 0 0.20309054734340581" />
   <mass  value="0.8249618000611944" />
   <inertia  ixy="0.0"  iyy="0.000343734083358831"  izz="0.011513928711944543"  ixz="0.0"  ixx="0.011513928711944543"  iyz="0.0" />
  </inertial>
  <visual >
   <origin  rpy="0 0 0"  xyz="0 0 0.20309054734340581" />
   <material  name="blue" />
   <geometry >
    <box  size="0.05 0.1 0.40618109468681163" />
   </geometry>
  </visual>
 </link>
 <joint  type="fixed"  name="joint-joint-1" >
  <parent  link="link1" />
  <child  link="joint-link-1" />
  <origin  xyz="0 0 0.40618109468681163"  rpy="1.5707 0 0" />
  <axis  xyz="1 0 0" />
 </joint>
 <link  name="joint-link-1" >
  <inertial >
   <origin  rpy="0 0 0"  xyz="0 0 0" />
   <mass  value="3.666744796099898" />
   <inertia  ixy="0"  iyy="0"  izz="0"  ixz="0"  ixx="0"  iyz="0" />
  </inertial>
  <visual >
   <origin  rpy="0 0 0"  xyz="0 0 0" />
   <material  name="red" />
   <geometry >
    <sphere  radius="0.05" />
   </geometry>
  </visual>
 </link>
 <joint  type="revolute"  name="joint2" >
  <parent  link="link1" />
  <child  link="link2" />
  <origin  xyz="0 0 0.40618109468681163"  rpy="1.5707 0 0" />
  <axis  xyz="1 0 0" />
 </joint>
 <link  name="link2" >
  <inertial >
   <origin  rpy="0 0 0"  xyz="0 0 0.8346573503978983" />
   <mass  value="9.978702676228266" />
   <inertia  ixy="0.0"  iyy="0.000343734083358831"  izz="0.19174254180003203"  ixz="0.0"  ixx="0.19174254180003203"  iyz="0.0" />
  </inertial>
  <visual >
   <origin  rpy="0 0 0"  xyz="0 0 0.8346573503978983" />
   <material  name="blue" />
   <geometry >
    <box  size="0.05 0.1 1.6693147007957967" />
   </geometry>
  </visual>
 </link>
 <joint  type="fixed"  name="eef_joint" >
  <parent  link="link2" />
  <child  link="eef" />
  <origin  xyz="0 0 1.6693147007957967"  rpy="0 0 0" />
 </joint>
 <link  name="eef" >
  <inertial >
   <origin  rpy="0 0 0"  xyz="0 0 0" />
   <mass  value="1" />
   <inertia  ixy="0"  iyy="0"  izz="0"  ixz="0"  ixx="0"  iyz="0" />
  </inertial>
 </link>
 <transmission  name="motor1" >
  <type  xmltext="SimpleTransmission" >
   SimpleTransmission
  </type>
  <actuator  name="motor1" >
   <mechanicalreduction  xmltext="1" >
    1
   </mechanicalreduction>
  </actuator>
  <joint  name="joint1" />
 </transmission>
 <transmission  name="motor2" >
  <type  xmltext="SimpleTransmission" >
   SimpleTransmission
  </type>
  <actuator  name="motor2" >
   <mechanicalreduction  xmltext="1" >
    1
   </mechanicalreduction>
  </actuator>
  <joint  name="joint2" />
 </transmission>
</robot>

<!-- {'carti': array([-0.1 ,  0.14,  0.85]), 'cartd': array([-0.1 ,  0.32,  1.29]), 'tau_mu': 0.26092339347458854, 'b0': 0.09183913760659915, 'Km': 1.5129112871499997, 'k_velocity': 1.7161274767375496, 'tau_max_m': 2.1239911323917178, 'omega_max_m': 4333.957606062724, 'gear_ratio': 2.5621022556275057, 'Kp': 33.8910439937958, 'Kd': 82.62433642615828, 'm_m': 3.666744796099898, 'l1': 0.40618109468681163, 'l2': 1.6693147007957967, 'k1': 14726.999199375548, 'k2': 207132578.58559546, 'k3': 69440391.10415913}-->