<?xml version="1.0"?>
<robot  name="TwoLinkStruct9893566314" >
 <material  name="blue" >
  <color  rgba="0 0 0.8 1.0" />
 </material>
 <material  name="red" >
  <color  rgba="0.8 0 0 1.0" />
 </material>
 <link  name="base_link" >
  <visual >
   <origin  rpy="0 1.5707 0"  xyz="0 0 0" />
   <material  name="red" />
   <geometry >
    <cylinder  length="0.05"  radius="0.1" />
   </geometry>
  </visual>
 </link>
 <joint  type="revolute"  name="joint1" >
  <parent  link="base_link" />
  <child  link="link1" />
  <origin  xyz="0 0 0"  rpy="0 0 0" />
  <axis  xyz="1 0 0" />
 </joint>
 <link  name="link1" >
  <inertial >
   <origin  rpy="0 0 0"  xyz="0 0 0.451324795773446" />
   <mass  value="3.3800234053997675" />
   <inertia  ixy="0.0"  iyy="0.0014083430855832365"  izz="0.23020108103191655"  ixz="0.0"  ixx="0.23020108103191655"  iyz="0.0" />
  </inertial>
  <visual >
   <origin  rpy="0 0 0"  xyz="0 0 0.451324795773446" />
   <material  name="blue" />
   <geometry >
    <box  size="0.05 0.1 0.902649591546892" />
   </geometry>
  </visual>
 </link>
 <joint  type="fixed"  name="joint-joint-1" >
  <parent  link="link1" />
  <child  link="joint-link-1" />
  <origin  xyz="0 0 0.902649591546892"  rpy="1.5707 0 0" />
  <axis  xyz="1 0 0" />
 </joint>
 <link  name="joint-link-1" >
  <inertial >
   <origin  rpy="0 0 0"  xyz="0 0 0" />
   <mass  value="0.5831892031698777" />
   <inertia  ixy="0"  iyy="0"  izz="0"  ixz="0"  ixx="0"  iyz="0" />
  </inertial>
  <visual >
   <origin  rpy="0 0 0"  xyz="0 0 0" />
   <material  name="red" />
   <geometry >
    <sphere  radius="0.05" />
   </geometry>
  </visual>
 </link>
 <joint  type="revolute"  name="joint2" >
  <parent  link="link1" />
  <child  link="link2" />
  <origin  xyz="0 0 0.902649591546892"  rpy="1.5707 0 0" />
  <axis  xyz="1 0 0" />
 </joint>
 <link  name="link2" >
  <inertial >
   <origin  rpy="0 0 0"  xyz="0 0 0.04350011854713876" />
   <mass  value="0.24089163052608087" />
   <inertia  ixy="0.0"  iyy="0.0014083430855832365"  izz="0.0028361329258343613"  ixz="0.0"  ixx="0.0028361329258343613"  iyz="0.0" />
  </inertial>
  <visual >
   <origin  rpy="0 0 0"  xyz="0 0 0.04350011854713876" />
   <material  name="blue" />
   <geometry >
    <box  size="0.05 0.1 0.08700023709427752" />
   </geometry>
  </visual>
 </link>
 <joint  type="fixed"  name="eef_joint" >
  <parent  link="link2" />
  <child  link="eef" />
  <origin  xyz="0 0 0.08700023709427752"  rpy="0 0 0" />
 </joint>
 <link  name="eef" >
  <inertial >
   <origin  rpy="0 0 0"  xyz="0 0 0" />
   <mass  value="1" />
   <inertia  ixy="0"  iyy="0"  izz="0"  ixz="0"  ixx="0"  iyz="0" />
  </inertial>
 </link>
 <transmission  name="motor1" >
  <type  xmltext="SimpleTransmission" >
   SimpleTransmission
  </type>
  <actuator  name="motor1" >
   <mechanicalreduction  xmltext="1" >
    1
   </mechanicalreduction>
  </actuator>
  <joint  name="joint1" />
 </transmission>
 <transmission  name="motor2" >
  <type  xmltext="SimpleTransmission" >
   SimpleTransmission
  </type>
  <actuator  name="motor2" >
   <mechanicalreduction  xmltext="1" >
    1
   </mechanicalreduction>
  </actuator>
  <joint  name="joint2" />
 </transmission>
</robot>

<!-- {'carti': array([-0.1 ,  0.14,  0.85]), 'cartd': array([-0.1 ,  0.32,  1.29]), 'tau_mu': 0.8155583288451599, 'b0': 0.29134609248009385, 'Km': 2.5978006710225583, 'k_velocity': 87.4456905751743, 'tau_max_m': 1.683921235794866, 'omega_max_m': 7047.5366830931525, 'gear_ratio': 17.009118209694225, 'Kp': 48.67326597011073, 'Kd': 58.42217823966938, 'm_m': 0.5831892031698777, 'l1': 0.902649591546892, 'l2': 0.08700023709427752, 'k1': 22522.08829694393, 'k2': 347354241.2369216, 'k3': 8425661.197591903}-->