<?xml version="1.0"?>
<robot  name="TwoLinkStruct6911138478" >
 <material  name="blue" >
  <color  rgba="0 0 0.8 1.0" />
 </material>
 <material  name="red" >
  <color  rgba="0.8 0 0 1.0" />
 </material>
 <link  name="base_link" >
  <visual >
   <origin  rpy="0 1.5707 0"  xyz="0 0 0" />
   <material  name="red" />
   <geometry >
    <cylinder  length="0.05"  radius="0.1" />
   </geometry>
  </visual>
 </link>
 <joint  type="revolute"  name="joint1" >
  <parent  link="base_link" />
  <child  link="link1" />
  <origin  xyz="0 0 0"  rpy="0 0 0" />
  <axis  xyz="1 0 0" />
 </joint>
 <link  name="link1" >
  <inertial >
   <origin  rpy="0 0 0"  xyz="0 0 0.7078970657544321" />
   <mass  value="7.351611105165597" />
   <inertia  ixy="0.0"  iyy="0.0030631712938189995"  izz="1.2295404301911728"  ixz="0.0"  ixx="1.2295404301911728"  iyz="0.0" />
  </inertial>
  <visual >
   <origin  rpy="0 0 0"  xyz="0 0 0.7078970657544321" />
   <material  name="blue" />
   <geometry >
    <box  size="0.05 0.1 1.4157941315088642" />
   </geometry>
  </visual>
 </link>
 <joint  type="fixed"  name="joint-joint-1" >
  <parent  link="link1" />
  <child  link="joint-link-1" />
  <origin  xyz="0 0 1.4157941315088642"  rpy="1.5707 0 0" />
  <axis  xyz="1 0 0" />
 </joint>
 <link  name="joint-link-1" >
  <inertial >
   <origin  rpy="0 0 0"  xyz="0 0 0" />
   <mass  value="0.23648673445926244" />
   <inertia  ixy="0"  iyy="0"  izz="0"  ixz="0"  ixx="0"  iyz="0" />
  </inertial>
  <visual >
   <origin  rpy="0 0 0"  xyz="0 0 0" />
   <material  name="red" />
   <geometry >
    <sphere  radius="0.05" />
   </geometry>
  </visual>
 </link>
 <joint  type="revolute"  name="joint2" >
  <parent  link="link1" />
  <child  link="link2" />
  <origin  xyz="0 0 1.4157941315088642"  rpy="1.5707 0 0" />
  <axis  xyz="1 0 0" />
 </joint>
 <link  name="link2" >
  <inertial >
   <origin  rpy="0 0 0"  xyz="0 0 0.305048893956017" />
   <mass  value="1.6908825956834697" />
   <inertia  ixy="0.0"  iyy="0.0030631712938189995"  izz="0.22956588722572568"  ixz="0.0"  ixx="0.22956588722572568"  iyz="0.0" />
  </inertial>
  <visual >
   <origin  rpy="0 0 0"  xyz="0 0 0.305048893956017" />
   <material  name="blue" />
   <geometry >
    <box  size="0.05 0.1 0.610097787912034" />
   </geometry>
  </visual>
 </link>
 <joint  type="fixed"  name="eef_joint" >
  <parent  link="link2" />
  <child  link="eef" />
  <origin  xyz="0 0 0.610097787912034"  rpy="0 0 0" />
 </joint>
 <link  name="eef" >
  <inertial >
   <origin  rpy="0 0 0"  xyz="0 0 0" />
   <mass  value="1" />
   <inertia  ixy="0"  iyy="0"  izz="0"  ixz="0"  ixx="0"  iyz="0" />
  </inertial>
 </link>
 <transmission  name="motor1" >
  <type  xmltext="SimpleTransmission" >
   SimpleTransmission
  </type>
  <actuator  name="motor1" >
   <mechanicalreduction  xmltext="1" >
    1
   </mechanicalreduction>
  </actuator>
  <joint  name="joint1" />
 </transmission>
 <transmission  name="motor2" >
  <type  xmltext="SimpleTransmission" >
   SimpleTransmission
  </type>
  <actuator  name="motor2" >
   <mechanicalreduction  xmltext="1" >
    1
   </mechanicalreduction>
  </actuator>
  <joint  name="joint2" />
 </transmission>
</robot>

<!-- {'carti': array([-0.1 ,  0.14,  0.85]), 'cartd': array([-0.1 ,  0.32,  1.29]), 'tau_mu': 0.6553986654919903, 'b0': 0.6318248684361778, 'Km': 4.962370885194611, 'k_velocity': 20.273279931788178, 'tau_max_m': 3.731805394269443, 'omega_max_m': 4564.296420959521, 'gear_ratio': 9.303089694251677, 'Kp': 92.32745312296606, 'Kd': 62.03258042350392, 'm_m': 0.23648673445926244, 'l1': 1.4157941315088642, 'l2': 0.610097787912034, 'k1': 20379.27208001047, 'k2': 113935204.5384497, 'k3': 329917835.5303244}-->