<?xml version="1.0"?>
<robot  name="TwoLink7164546714" >
 <material  name="blue" >
  <color  rgba="0 0 0.8 1.0" />
 </material>
 <material  name="red" >
  <color  rgba="0.8 0 0 1.0" />
 </material>
 <link  name="base_link" >
  <visual >
   <origin  xyz="0 0 0"  rpy="0 1.5707 0" />
   <material  name="red" />
   <geometry >
    <cylinder  length="0.05"  radius="0.1" />
   </geometry>
  </visual>
 </link>
 <joint  type="revolute"  name="joint1" >
  <parent  link="base_link" />
  <child  link="link1" />
  <origin  xyz="0 0 0"  rpy="0 0 0" />
  <axis  xyz="1 0 0" />
 </joint>
 <link  name="link1" >
  <inertial >
   <origin  xyz="0 0 0.181739025"  rpy="0 0 0" />
   <mass  value="1.9082597625" />
   <inertia  izz="0.021406904582320484"  iyy="0.0007951082343750001"  iyz="0.0"  ixz="0.0"  ixx="0.021406904582320484"  ixy="0.0" />
  </inertial>
  <visual >
   <origin  xyz="0 0 0.181739025"  rpy="0 0 0" />
   <material  name="blue" />
   <geometry >
    <box  size="0.05 0.1 0.36347805" />
   </geometry>
  </visual>
 </link>
 <joint  type="fixed"  name="joint-joint-1" >
  <parent  link="link1" />
  <child  link="joint-link-1" />
  <origin  xyz="0 0 0.36347805"  rpy="1.5707 0 0" />
  <axis  xyz="1 0 0" />
 </joint>
 <link  name="joint-link-1" >
  <inertial >
   <origin  xyz="0 0 0"  rpy="0 0 0" />
   <mass  value="3.11411655" />
   <inertia  izz="0"  iyy="0"  iyz="0"  ixz="0"  ixx="0"  ixy="0" />
  </inertial>
  <visual >
   <origin  xyz="0 0 0"  rpy="0 0 0" />
   <material  name="red" />
   <geometry >
    <sphere  radius="0.05" />
   </geometry>
  </visual>
 </link>
 <joint  type="revolute"  name="joint2" >
  <parent  link="link1" />
  <child  link="link2" />
  <origin  xyz="0 0 0.36347805"  rpy="1.5707 0 0" />
  <axis  xyz="1 0 0" />
 </joint>
 <link  name="link2" >
  <inertial >
   <origin  xyz="0 0 0.2138370115"  rpy="0 0 0" />
   <mass  value="1.9082597625" />
   <inertia  izz="0.029483419562265273"  iyy="0.0007951082343750001"  iyz="0.0"  ixz="0.0"  ixx="0.029483419562265273"  ixy="0.0" />
  </inertial>
  <visual >
   <origin  xyz="0 0 0.2138370115"  rpy="0 0 0" />
   <material  name="blue" />
   <geometry >
    <box  size="0.05 0.1 0.427674023" />
   </geometry>
  </visual>
 </link>
 <joint  type="fixed"  name="eef_joint" >
  <parent  link="link2" />
  <child  link="eef" />
  <origin  xyz="0 0 0.427674023"  rpy="0 0 0" />
 </joint>
 <link  name="eef" >
  <inertial >
   <origin  xyz="0 0 0"  rpy="0 0 0" />
   <mass  value="1" />
   <inertia  izz="0"  iyy="0"  iyz="0"  ixz="0"  ixx="0"  ixy="0" />
  </inertial>
 </link>
 <transmission  name="motor1" >
  <type  xmltext="SimpleTransmission" >
   SimpleTransmission
  </type>
  <actuator  name="motor1" >
   <mechanicalreduction  xmltext="1" >
    1
   </mechanicalreduction>
  </actuator>
  <joint  name="joint1" />
 </transmission>
 <transmission  name="motor2" >
  <type  xmltext="SimpleTransmission" >
   SimpleTransmission
  </type>
  <actuator  name="motor2" >
   <mechanicalreduction  xmltext="1" >
    1
   </mechanicalreduction>
  </actuator>
  <joint  name="joint2" />
 </transmission>
</robot>

<!-- {'carti': array([-0.1 ,  0.14,  0.85]), 'cartd': array([-0.1 ,  0.32,  1.29]), 'tau_mu': 0.680677339, 'b0': 0.391456772, 'Km': 5.0, 'k_velocity': 0.01, 'tau_max_m': 3.45911489, 'omega_max_m': 5387.82768, 'gear_ratio': 25.0, 'Kp': 0.0001, 'Kd': 74.2612444, 'm_m': 3.11411655, 'l1': 0.36347805, 'l2': 0.427674023}-->