<?xml version="1.0"?>
<robot  name="TwoLink9399582465" >
 <material  name="blue" >
  <color  rgba="0 0 0.8 1.0" />
 </material>
 <material  name="red" >
  <color  rgba="0.8 0 0 1.0" />
 </material>
 <link  name="base_link" >
  <visual >
   <origin  rpy="0 1.5707 0"  xyz="0 0 0" />
   <material  name="red" />
   <geometry >
    <cylinder  length="0.05"  radius="0.1" />
   </geometry>
  </visual>
 </link>
 <joint  name="joint1"  type="revolute" >
  <parent  link="base_link" />
  <child  link="link1" />
  <origin  rpy="0 0 0"  xyz="0 0 0" />
  <axis  xyz="1 0 0" />
 </joint>
 <link  name="link1" >
  <inertial >
   <origin  rpy="0 0 0"  xyz="0 0 0.1406151235" />
   <mass  value="1.47645879675" />
   <inertia  izz="0.010038745027648894"  ixx="0.010038745027648894"  iyz="0.0"  ixz="0.0"  ixy="0.0"  iyy="0.0006151911653125001" />
  </inertial>
  <visual >
   <origin  rpy="0 0 0"  xyz="0 0 0.1406151235" />
   <material  name="blue" />
   <geometry >
    <box  size="0.05 0.1 0.281230247" />
   </geometry>
  </visual>
 </link>
 <joint  name="joint-joint-1"  type="fixed" >
  <parent  link="link1" />
  <child  link="joint-link-1" />
  <origin  rpy="1.5707 0 0"  xyz="0 0 0.281230247" />
  <axis  xyz="1 0 0" />
 </joint>
 <link  name="joint-link-1" >
  <inertial >
   <origin  rpy="0 0 0"  xyz="0 0 0" />
   <mass  value="1.53405543" />
   <inertia  izz="0"  ixx="0"  iyz="0"  ixz="0"  ixy="0"  iyy="0" />
  </inertial>
  <visual >
   <origin  rpy="0 0 0"  xyz="0 0 0" />
   <material  name="red" />
   <geometry >
    <sphere  radius="0.05" />
   </geometry>
  </visual>
 </link>
 <joint  name="joint2"  type="revolute" >
  <parent  link="link1" />
  <child  link="link2" />
  <origin  rpy="1.5707 0 0"  xyz="0 0 0.281230247" />
  <axis  xyz="1 0 0" />
 </joint>
 <link  name="link2" >
  <inertial >
   <origin  rpy="0 0 0"  xyz="0 0 0.15397814" />
   <mass  value="1.47645879675" />
   <inertia  izz="0.01197618115244277"  ixx="0.01197618115244277"  iyz="0.0"  ixz="0.0"  ixy="0.0"  iyy="0.0006151911653125001" />
  </inertial>
  <visual >
   <origin  rpy="0 0 0"  xyz="0 0 0.15397814" />
   <material  name="blue" />
   <geometry >
    <box  size="0.05 0.1 0.30795628" />
   </geometry>
  </visual>
 </link>
 <joint  name="eef_joint"  type="fixed" >
  <parent  link="link2" />
  <child  link="eef" />
  <origin  rpy="0 0 0"  xyz="0 0 0.30795628" />
 </joint>
 <link  name="eef" >
  <inertial >
   <origin  rpy="0 0 0"  xyz="0 0 0" />
   <mass  value="1" />
   <inertia  izz="0"  ixx="0"  iyz="0"  ixz="0"  ixy="0"  iyy="0" />
  </inertial>
 </link>
 <transmission  name="motor1" >
  <type  xmltext="SimpleTransmission" >
   SimpleTransmission
  </type>
  <actuator  name="motor1" >
   <mechanicalreduction  xmltext="1" >
    1
   </mechanicalreduction>
  </actuator>
  <joint  name="joint1" />
 </transmission>
 <transmission  name="motor2" >
  <type  xmltext="SimpleTransmission" >
   SimpleTransmission
  </type>
  <actuator  name="motor2" >
   <mechanicalreduction  xmltext="1" >
    1
   </mechanicalreduction>
  </actuator>
  <joint  name="joint2" />
 </transmission>
</robot>

<!-- {'tau_mu': 0.0053, 'b0': 1.5e-05, 'k_velocity': 1.0606085407643906, 'carti': array([-0.1 ,  0.14,  0.85]), 'cartd': array([-0.1 ,  0.32,  1.29]), 'omega_max_m': 6898.57304, 'gear_ratio': 20.0458703, 'Kp': 85.3404559, 'Kd': 16.3537017, 'm_m': 1.53405543, 'l1': 0.281230247, 'l2': 0.30795628, 'tau_max_m': 8.299393936553622, 'Km': 0.2719006975076941}-->