<?xml version="1.0"?>
<robot  name="TwoLink2798264266" >
 <material  name="blue" >
  <color  rgba="0 0 0.8 1.0" />
 </material>
 <material  name="red" >
  <color  rgba="0.8 0 0 1.0" />
 </material>
 <link  name="base_link" >
  <visual >
   <origin  xyz="0 0 0"  rpy="0 1.5707 0" />
   <material  name="red" />
   <geometry >
    <cylinder  length="0.05"  radius="0.1" />
   </geometry>
  </visual>
 </link>
 <joint  type="revolute"  name="joint1" >
  <parent  link="base_link" />
  <child  link="link1" />
  <origin  xyz="0 0 0"  rpy="0 0 0" />
  <axis  xyz="1 0 0" />
 </joint>
 <link  name="link1" >
  <inertial >
   <origin  xyz="0 0 0.2240718405"  rpy="0 0 0" />
   <mass  value="2.3527543252500003" />
   <inertia  izz="0.03986600231494256"  iyy="0.0009803143021875002"  iyz="0.0"  ixz="0.0"  ixx="0.03986600231494256"  ixy="0.0" />
  </inertial>
  <visual >
   <origin  xyz="0 0 0.2240718405"  rpy="0 0 0" />
   <material  name="blue" />
   <geometry >
    <box  size="0.05 0.1 0.448143681" />
   </geometry>
  </visual>
 </link>
 <joint  type="fixed"  name="joint-joint-1" >
  <parent  link="link1" />
  <child  link="joint-link-1" />
  <origin  xyz="0 0 0.448143681"  rpy="1.5707 0 0" />
  <axis  xyz="1 0 0" />
 </joint>
 <link  name="joint-link-1" >
  <inertial >
   <origin  xyz="0 0 0"  rpy="0 0 0" />
   <mass  value="2.7123417" />
   <inertia  izz="0"  iyy="0"  iyz="0"  ixz="0"  ixx="0"  ixy="0" />
  </inertial>
  <visual >
   <origin  xyz="0 0 0"  rpy="0 0 0" />
   <material  name="red" />
   <geometry >
    <sphere  radius="0.05" />
   </geometry>
  </visual>
 </link>
 <joint  type="revolute"  name="joint2" >
  <parent  link="link1" />
  <child  link="link2" />
  <origin  xyz="0 0 0.448143681"  rpy="1.5707 0 0" />
  <axis  xyz="1 0 0" />
 </joint>
 <link  name="link2" >
  <inertial >
   <origin  xyz="0 0 0.2291434285"  rpy="0 0 0" />
   <mass  value="2.3527543252500003" />
   <inertia  izz="0.041668620816942205"  iyy="0.0009803143021875002"  iyz="0.0"  ixz="0.0"  ixx="0.041668620816942205"  ixy="0.0" />
  </inertial>
  <visual >
   <origin  xyz="0 0 0.2291434285"  rpy="0 0 0" />
   <material  name="blue" />
   <geometry >
    <box  size="0.05 0.1 0.458286857" />
   </geometry>
  </visual>
 </link>
 <joint  type="fixed"  name="eef_joint" >
  <parent  link="link2" />
  <child  link="eef" />
  <origin  xyz="0 0 0.458286857"  rpy="0 0 0" />
 </joint>
 <link  name="eef" >
  <inertial >
   <origin  xyz="0 0 0"  rpy="0 0 0" />
   <mass  value="1" />
   <inertia  izz="0"  iyy="0"  iyz="0"  ixz="0"  ixx="0"  ixy="0" />
  </inertial>
 </link>
 <transmission  name="motor1" >
  <type  xmltext="SimpleTransmission" >
   SimpleTransmission
  </type>
  <actuator  name="motor1" >
   <mechanicalreduction  xmltext="1" >
    1
   </mechanicalreduction>
  </actuator>
  <joint  name="joint1" />
 </transmission>
 <transmission  name="motor2" >
  <type  xmltext="SimpleTransmission" >
   SimpleTransmission
  </type>
  <actuator  name="motor2" >
   <mechanicalreduction  xmltext="1" >
    1
   </mechanicalreduction>
  </actuator>
  <joint  name="joint2" />
 </transmission>
</robot>

<!-- {'carti': array([-0.1 ,  0.14,  0.85]), 'cartd': array([-0.1 ,  0.32,  1.29]), 'tau_mu': 0.426186672, 'b0': 0.0, 'Km': 5.0, 'k_velocity': 58.5693845, 'tau_max_m': 5.0, 'omega_max_m': 7177.62426, 'gear_ratio': 11.7189345, 'Kp': 73.7941995, 'Kd': 17.8802672, 'm_m': 2.7123417, 'l1': 0.448143681, 'l2': 0.458286857}-->