<?xml version="1.0"?>
<robot  name="TwoLink3211834427" >
 <material  name="blue" >
  <color  rgba="0 0 0.8 1.0" />
 </material>
 <material  name="red" >
  <color  rgba="0.8 0 0 1.0" />
 </material>
 <link  name="base_link" >
  <visual >
   <origin  rpy="0 1.5707 0"  xyz="0 0 0" />
   <material  name="red" />
   <geometry >
    <cylinder  radius="0.1"  length="0.05" />
   </geometry>
  </visual>
 </link>
 <joint  type="revolute"  name="joint1" >
  <parent  link="base_link" />
  <child  link="link1" />
  <origin  rpy="0 0 0"  xyz="0 0 0" />
  <axis  xyz="1 0 0" />
 </joint>
 <link  name="link1" >
  <inertial >
   <origin  rpy="0 0 0"  xyz="0 0 0.18" />
   <mass  value="0.37347898006439206" />
   <inertia  iyz="0.0"  ixz="0.0"  iyy="0.00015561624169349673"  ixy="0.0"  ixx="0.0041113811055421825"  izz="0.0041113811055421825" />
  </inertial>
  <visual >
   <origin  rpy="0 0 0"  xyz="0 0 0.18" />
   <material  name="blue" />
   <geometry >
    <box  size="0.05 0.1 0.36" />
   </geometry>
  </visual>
 </link>
 <joint  type="fixed"  name="joint-joint-1" >
  <parent  link="link1" />
  <child  link="joint-link-1" />
  <origin  rpy="1.5707 0 0"  xyz="0 0 0.36" />
  <axis  xyz="1 0 0" />
 </joint>
 <link  name="joint-link-1" >
  <inertial >
   <origin  rpy="0 0 0"  xyz="0 0 0" />
   <mass  value="0.452" />
   <inertia  iyz="0"  ixz="0"  iyy="0"  ixy="0"  ixx="0"  izz="0" />
  </inertial>
  <visual >
   <origin  rpy="0 0 0"  xyz="0 0 0" />
   <material  name="red" />
   <geometry >
    <sphere  radius="0.05" />
   </geometry>
  </visual>
 </link>
 <joint  type="revolute"  name="joint2" >
  <parent  link="link1" />
  <child  link="link2" />
  <origin  rpy="1.5707 0 0"  xyz="0 0 0.36" />
  <axis  xyz="1 0 0" />
 </joint>
 <link  name="link2" >
  <inertial >
   <origin  rpy="0 0 0"  xyz="0 0 0.18" />
   <mass  value="0.37347898006439206" />
   <inertia  iyz="0.0"  ixz="0.0"  iyy="0.00015561624169349673"  ixy="0.0"  ixx="0.0041113811055421825"  izz="0.0041113811055421825" />
  </inertial>
  <visual >
   <origin  rpy="0 0 0"  xyz="0 0 0.18" />
   <material  name="blue" />
   <geometry >
    <box  size="0.05 0.1 0.36" />
   </geometry>
  </visual>
 </link>
 <joint  type="fixed"  name="eef_joint" >
  <parent  link="link2" />
  <child  link="eef" />
  <origin  rpy="0 0 0"  xyz="0 0 0.36" />
 </joint>
 <link  name="eef" >
  <inertial >
   <origin  rpy="0 0 0"  xyz="0 0 0" />
   <mass  value="1" />
   <inertia  iyz="0"  ixz="0"  iyy="0"  ixy="0"  ixx="0"  izz="0" />
  </inertial>
 </link>
 <transmission  name="motor1" >
  <type  xmltext="SimpleTransmission" >
   SimpleTransmission
  </type>
  <actuator  name="motor1" >
   <mechanicalreduction  xmltext="1" >
    1
   </mechanicalreduction>
  </actuator>
  <joint  name="joint1" />
 </transmission>
 <transmission  name="motor2" >
  <type  xmltext="SimpleTransmission" >
   SimpleTransmission
  </type>
  <actuator  name="motor2" >
   <mechanicalreduction  xmltext="1" >
    1
   </mechanicalreduction>
  </actuator>
  <joint  name="joint2" />
 </transmission>
</robot>

<!-- {'carti': array([-0.1 ,  0.14,  0.85]), 'cartd': array([-0.1 ,  0.32,  1.29]), 'tau_mu': 0.0053, 'b0': 1.5e-05, 'Km': 0.19, 'k_velocity': 1.0606085407643906, 'tau_max_m': 1.2, 'omega_max_m': 4750, 'gear_ratio': 10, 'Kp': 15, 'Kd': 7.745966692414834, 'm_m': 0.452, 'l1': 0.36, 'l2': 0.36, 'k1': 646.2338, 'k2': 69400000, 'k3': 56100000}-->