<?xml version="1.0"?>
<robot  name="TwoLinkStruct4720456429" >
 <material  name="blue" >
  <color  rgba="0 0 0.8 1.0" />
 </material>
 <material  name="red" >
  <color  rgba="0.8 0 0 1.0" />
 </material>
 <link  name="base_link" >
  <visual >
   <origin  rpy="0 1.5707 0"  xyz="0 0 0" />
   <material  name="red" />
   <geometry >
    <cylinder  length="0.05"  radius="0.1" />
   </geometry>
  </visual>
 </link>
 <joint  type="revolute"  name="joint1" >
  <parent  link="base_link" />
  <child  link="link1" />
  <origin  xyz="0 0 0"  rpy="0 0 0" />
  <axis  xyz="1 0 0" />
 </joint>
 <link  name="link1" >
  <inertial >
   <origin  rpy="0 0 0"  xyz="0 0 0.035896701884533484" />
   <mass  value="0.26542711375450145" />
   <inertia  ixy="0.0"  iyy="0.00011059463073104228"  izz="0.00016930473769206046"  ixz="0.0"  ixx="0.00016930473769206046"  iyz="0.0" />
  </inertial>
  <visual >
   <origin  rpy="0 0 0"  xyz="0 0 0.035896701884533484" />
   <material  name="blue" />
   <geometry >
    <box  size="0.05 0.1 0.07179340376906697" />
   </geometry>
  </visual>
 </link>
 <joint  type="fixed"  name="joint-joint-1" >
  <parent  link="link1" />
  <child  link="joint-link-1" />
  <origin  xyz="0 0 0.07179340376906697"  rpy="1.5707 0 0" />
  <axis  xyz="1 0 0" />
 </joint>
 <link  name="joint-link-1" >
  <inertial >
   <origin  rpy="0 0 0"  xyz="0 0 0" />
   <mass  value="1.0841718737724342" />
   <inertia  ixy="0"  iyy="0"  izz="0"  ixz="0"  ixx="0"  iyz="0" />
  </inertial>
  <visual >
   <origin  rpy="0 0 0"  xyz="0 0 0" />
   <material  name="red" />
   <geometry >
    <sphere  radius="0.05" />
   </geometry>
  </visual>
 </link>
 <joint  type="revolute"  name="joint2" >
  <parent  link="link1" />
  <child  link="link2" />
  <origin  xyz="0 0 0.07179340376906697"  rpy="1.5707 0 0" />
  <axis  xyz="1 0 0" />
 </joint>
 <link  name="link2" >
  <inertial >
   <origin  rpy="0 0 0"  xyz="0 0 0.01889066410004622" />
   <mass  value="0.14356776625537393" />
   <inertia  ixy="0.0"  iyy="0.00011059463073104228"  izz="8.687050669939022e-05"  ixz="0.0"  ixx="8.687050669939022e-05"  iyz="0.0" />
  </inertial>
  <visual >
   <origin  rpy="0 0 0"  xyz="0 0 0.01889066410004622" />
   <material  name="blue" />
   <geometry >
    <box  size="0.05 0.1 0.03778132820009244" />
   </geometry>
  </visual>
 </link>
 <joint  type="fixed"  name="eef_joint" >
  <parent  link="link2" />
  <child  link="eef" />
  <origin  xyz="0 0 0.03778132820009244"  rpy="0 0 0" />
 </joint>
 <link  name="eef" >
  <inertial >
   <origin  rpy="0 0 0"  xyz="0 0 0" />
   <mass  value="1" />
   <inertia  ixy="0"  iyy="0"  izz="0"  ixz="0"  ixx="0"  iyz="0" />
  </inertial>
 </link>
 <transmission  name="motor1" >
  <type  xmltext="SimpleTransmission" >
   SimpleTransmission
  </type>
  <actuator  name="motor1" >
   <mechanicalreduction  xmltext="1" >
    1
   </mechanicalreduction>
  </actuator>
  <joint  name="joint1" />
 </transmission>
 <transmission  name="motor2" >
  <type  xmltext="SimpleTransmission" >
   SimpleTransmission
  </type>
  <actuator  name="motor2" >
   <mechanicalreduction  xmltext="1" >
    1
   </mechanicalreduction>
  </actuator>
  <joint  name="joint2" />
 </transmission>
</robot>

<!-- {'carti': array([-0.1 ,  0.14,  0.85]), 'cartd': array([-0.1 ,  0.32,  1.29]), 'tau_mu': 0.6526402218559404, 'b0': 1.0, 'Km': 4.8650718489468385, 'k_velocity': 100.0, 'tau_max_m': 1.860042526267361, 'omega_max_m': 5034.093214279326, 'gear_ratio': 0.1, 'Kp': 100.0, 'Kd': 100.0, 'm_m': 1.0841718737724342, 'l1': 0.07179340376906697, 'l2': 0.03778132820009244, 'k1': 11600.249931935117, 'k2': 379000000.0, 'k3': 1000.0}-->