<?xml version="1.0"?>
<robot  name="TwoLinkStruct6176076754" >
 <material  name="blue" >
  <color  rgba="0 0 0.8 1.0" />
 </material>
 <material  name="red" >
  <color  rgba="0.8 0 0 1.0" />
 </material>
 <link  name="base_link" >
  <visual >
   <origin  rpy="0 1.5707 0"  xyz="0 0 0" />
   <material  name="red" />
   <geometry >
    <cylinder  length="0.05"  radius="0.1" />
   </geometry>
  </visual>
 </link>
 <joint  type="revolute"  name="joint1" >
  <parent  link="base_link" />
  <child  link="link1" />
  <origin  xyz="0 0 0"  rpy="0 0 0" />
  <axis  xyz="1 0 0" />
 </joint>
 <link  name="link1" >
  <inertial >
   <origin  rpy="0 0 0"  xyz="0 0 0.005" />
   <mass  value="0.0513479471206665" />
   <inertia  ixy="0.0"  iyy="2.139497796694438e-05"  izz="1.1125388542811077e-05"  ixz="0.0"  ixx="1.1125388542811077e-05"  iyz="0.0" />
  </inertial>
  <visual >
   <origin  rpy="0 0 0"  xyz="0 0 0.005" />
   <material  name="blue" />
   <geometry >
    <box  size="0.05 0.1 0.01" />
   </geometry>
  </visual>
 </link>
 <joint  type="fixed"  name="joint-joint-1" >
  <parent  link="link1" />
  <child  link="joint-link-1" />
  <origin  xyz="0 0 0.01"  rpy="1.5707 0 0" />
  <axis  xyz="1 0 0" />
 </joint>
 <link  name="joint-link-1" >
  <inertial >
   <origin  rpy="0 0 0"  xyz="0 0 0" />
   <mass  value="4.3551729722505845" />
   <inertia  ixy="0"  iyy="0"  izz="0"  ixz="0"  ixx="0"  iyz="0" />
  </inertial>
  <visual >
   <origin  rpy="0 0 0"  xyz="0 0 0" />
   <material  name="red" />
   <geometry >
    <sphere  radius="0.05" />
   </geometry>
  </visual>
 </link>
 <joint  type="revolute"  name="joint2" >
  <parent  link="link1" />
  <child  link="link2" />
  <origin  xyz="0 0 0.01"  rpy="1.5707 0 0" />
  <axis  xyz="1 0 0" />
 </joint>
 <link  name="link2" >
  <inertial >
   <origin  rpy="0 0 0"  xyz="0 0 0.3529566128874118" />
   <mass  value="2.1841230252687094" />
   <inertia  ixy="0.0"  iyy="2.139497796694438e-05"  izz="0.0021429786839733504"  ixz="0.0"  ixx="0.0021429786839733504"  iyz="0.0" />
  </inertial>
  <visual >
   <origin  rpy="0 0 0"  xyz="0 0 0.3529566128874118" />
   <material  name="blue" />
   <geometry >
    <box  size="0.05 0.1 0.7059132257748236" />
   </geometry>
  </visual>
 </link>
 <joint  type="fixed"  name="eef_joint" >
  <parent  link="link2" />
  <child  link="eef" />
  <origin  xyz="0 0 0.7059132257748236"  rpy="0 0 0" />
 </joint>
 <link  name="eef" >
  <inertial >
   <origin  rpy="0 0 0"  xyz="0 0 0" />
   <mass  value="1" />
   <inertia  ixy="0"  iyy="0"  izz="0"  ixz="0"  ixx="0"  iyz="0" />
  </inertial>
 </link>
 <transmission  name="motor1" >
  <type  xmltext="SimpleTransmission" >
   SimpleTransmission
  </type>
  <actuator  name="motor1" >
   <mechanicalreduction  xmltext="1" >
    1
   </mechanicalreduction>
  </actuator>
  <joint  name="joint1" />
 </transmission>
 <transmission  name="motor2" >
  <type  xmltext="SimpleTransmission" >
   SimpleTransmission
  </type>
  <actuator  name="motor2" >
   <mechanicalreduction  xmltext="1" >
    1
   </mechanicalreduction>
  </actuator>
  <joint  name="joint2" />
 </transmission>
</robot>

<!-- {'carti': array([-0.1 ,  0.14,  0.85]), 'cartd': array([-0.1 ,  0.32,  1.29]), 'tau_mu': 1.0, 'b0': 1.0, 'Km': 5.0, 'k_velocity': 40.27732046974374, 'tau_max_m': 3.313854420965217, 'omega_max_m': 7887.331423074183, 'gear_ratio': 9.944962086344786, 'Kp': 24.646844278058325, 'Kd': 59.90806300246394, 'm_m': 4.3551729722505845, 'l1': 0.01, 'l2': 0.7059132257748236, 'k1': 8136.459701090025, 'k2': 133277559.14150247, 'k3': 379000000.0}-->