<?xml version="1.0"?>
<robot  name="divar3v44447" >
 <material  name="blue" >
  <color  rgba="0 0 0.8 1.0" />
 </material>
 <material  name="red" >
  <color  rgba="0.8 0 0 1.0" />
 </material>
 <link  name="base_link" >
  <visual >
   <origin  xyz="0 0 0"  rpy="0 0 0" />
   <material  name="red" />
   <geometry >
    <cylinder  radius="0.1"  length="0.05" />
   </geometry>
  </visual>
 </link>
 <joint  name="joint1"  type="revolute" >
  <parent  link="base_link" />
  <child  link="link1" />
  <origin  xyz="0 0 0"  rpy="0 0 0" />
  <axis  xyz="0 0 1" />
 </joint>
 <link  name="link1" >
  <inertial >
   <origin  xyz="0 0 0.15235"  rpy="0 0 0" />
   <mass  value="2.6085632264507197" />
   <inertia  ixz="0.0"  ixy="0.0"  ixx="0.021069925608113643"  iyz="0.0"  izz="0.021069925608113643"  iyy="0.001775774242755928" />
  </inertial>
  <visual >
   <origin  xyz="0 0 0.15235"  rpy="0 0 0" />
   <material  name="blue" />
   <geometry >
    <box  size="0.06391 0.06391 0.3047" />
   </geometry>
  </visual>
  <collision >
   <origin  xyz="0 0 0.15235"  rpy="0 0 0" />
   <geometry >
    <box  size="0.06391 0.06391 0.3047" />
   </geometry>
  </collision>
 </link>
 <joint  name="joint2"  type="revolute" >
  <parent  link="link1" />
  <child  link="link2" />
  <origin  xyz="0 0 0.3047"  rpy="1.5707 0 0" />
  <axis  xyz="1 0 0" />
 </joint>
 <link  name="link2" >
  <inertial >
   <origin  xyz="0 0 0.14795053"  rpy="0 0 0" />
   <mass  value="2.5332347350961206" />
   <inertia  ixz="0.0"  ixy="0.0"  ixx="0.01934587571978997"  iyz="0.0"  izz="0.01934587571978997"  iyy="0.0017244945216677925" />
  </inertial>
  <visual >
   <origin  xyz="0 0 0.14795053"  rpy="0 0 0" />
   <material  name="blue" />
   <geometry >
    <box  size="0.06391 0.06391 0.29590106" />
   </geometry>
  </visual>
  <collision >
   <origin  xyz="0 0 0.14795053"  rpy="0 0 0" />
   <geometry >
    <box  size="0.06391 0.06391 0.29590106" />
   </geometry>
  </collision>
 </link>
 <joint  name="joint3"  type="revolute" >
  <parent  link="link2" />
  <child  link="link3" />
  <origin  xyz="0 0 0.29590106"  rpy="0 0 0" />
  <axis  xyz="0 0 1" />
 </joint>
 <link  name="link3" >
  <inertial >
   <origin  xyz="0 0 0.024949469999999998"  rpy="0 0 0" />
   <mass  value="0.42718916942195884" />
   <inertia  ixz="0.0"  ixy="0.0"  ixx="0.00023404243264144842"  iyz="0.0"  izz="0.00023404243264144842"  iyy="0.0002908081798254791" />
  </inertial>
  <visual >
   <origin  xyz="0 0 0.024949469999999998"  rpy="0 0 0" />
   <material  name="blue" />
   <geometry >
    <box  size="0.06391 0.06391 0.049898939999999996" />
   </geometry>
  </visual>
  <collision >
   <origin  xyz="0 0 0.024949469999999998"  rpy="0 0 0" />
   <geometry >
    <box  size="0.06391 0.06391 0.049898939999999996" />
   </geometry>
  </collision>
 </link>
 <joint  name="joint4"  type="revolute" >
  <parent  link="link3" />
  <child  link="link4" />
  <origin  xyz="0 0 0.049898939999999996"  rpy="0 0 0" />
  <axis  xyz="0 1 0" />
 </joint>
 <link  name="link4" >
  <inertial >
   <origin  xyz="0 0 0.06059917"  rpy="0 0 0" />
   <mass  value="0.4054352612207416" />
   <inertia  ixz="0.0"  ixy="0.0"  ixx="0.0005502107912114944"  iyz="0.0"  izz="0.0005502107912114944"  iyy="0.0001078459484160761" />
  </inertial>
  <visual >
   <origin  xyz="0 0 0.06059917"  rpy="0 0 0" />
   <material  name="blue" />
   <geometry >
    <box  size="0.03995 0.03995 0.12119834" />
   </geometry>
  </visual>
  <collision >
   <origin  xyz="0 0 0.06059917"  rpy="0 0 0" />
   <geometry >
    <box  size="0.03995 0.03995 0.12119834" />
   </geometry>
  </collision>
 </link>
 <joint  name="joint5"  type="revolute" >
  <parent  link="link4" />
  <child  link="link5" />
  <origin  xyz="0 0 0.12119834"  rpy="0 0 0" />
  <axis  xyz="0 0 1" />
 </joint>
 <link  name="link5" >
  <inertial >
   <origin  xyz="0 0 0.10130082999999998"  rpy="0 0 0" />
   <mass  value="0.6777473762912583" />
   <inertia  ixz="0.0"  ixy="0.0"  ixx="0.0024084563565522545"  iyz="0.0"  izz="0.0024084563565522545"  iyy="0.0001802810844882148" />
  </inertial>
  <visual >
   <origin  xyz="0 0 0.10130082999999998"  rpy="0 0 0" />
   <material  name="blue" />
   <geometry >
    <box  size="0.03995 0.03995 0.20260165999999996" />
   </geometry>
  </visual>
  <collision >
   <origin  xyz="0 0 0.10130082999999998"  rpy="0 0 0" />
   <geometry >
    <box  size="0.03995 0.03995 0.20260165999999996" />
   </geometry>
  </collision>
 </link>
 <joint  name="joint6"  type="revolute" >
  <parent  link="link5" />
  <child  link="link6" />
  <origin  xyz="0 0 0.20260165999999996"  rpy="0 0 0" />
  <axis  xyz="0 1 0" />
 </joint>
 <link  name="link6" >
  <inertial >
   <origin  xyz="0 0 0.005"  rpy="0 0 0" />
   <mass  value="0.0334522124" />
   <inertia  ixz="0.0"  ixy="0.0"  ixx="1.1665032058872702e-05"  iyz="0.0"  izz="1.1665032058872702e-05"  iyy="2.2772527244412068e-05" />
  </inertial>
  <visual >
   <origin  xyz="0 0 0.005"  rpy="0 0 0" />
   <material  name="blue" />
   <geometry >
    <box  size="0.03995 0.03995 0.01" />
   </geometry>
  </visual>
  <collision >
   <origin  xyz="0 0 0.005"  rpy="0 0 0" />
   <geometry >
    <box  size="0.03995 0.03995 0.01" />
   </geometry>
  </collision>
 </link>
 <joint  name="joint7"  type="revolute" >
  <parent  link="link6" />
  <child  link="link7" />
  <origin  xyz="0 0 0.01"  rpy="0 0 0" />
  <axis  xyz="1 0 0" />
 </joint>
 <link  name="link7" >
  <inertial >
   <origin  xyz="0 0 0.05"  rpy="0 0 0" />
   <mass  value="0.33452212400000003" />
   <inertia  ixz="0.0"  ixy="0.0"  ixx="0.00032325994885077595"  iyz="0.0"  izz="0.00032325994885077595"  iyy="8.898302436821834e-05" />
  </inertial>
  <visual >
   <origin  xyz="0 0 0.05"  rpy="0 0 0" />
   <material  name="blue" />
   <geometry >
    <box  size="0.03995 0.03995 0.1" />
   </geometry>
  </visual>
  <collision >
   <origin  xyz="0 0 0.05"  rpy="0 0 0" />
   <geometry >
    <box  size="0.03995 0.03995 0.1" />
   </geometry>
  </collision>
 </link>
 <joint  name="eef_joint"  type="fixed" >
  <parent  link="link7" />
  <child  link="eef" />
  <origin  xyz="0 0 0.1"  rpy="0 0 0" />
 </joint>
 <link  name="eef" />
</robot>

