<?xml version="1.0"?>
<robot  name="divar3v7757625049" >
 <material  name="blue" >
  <color  rgba="0 0 0.8 1.0" />
 </material>
 <material  name="red" >
  <color  rgba="0.8 0 0 1.0" />
 </material>
 <link  name="base_link" >
  <visual >
   <origin  xyz="0 0 0"  rpy="0 0 0" />
   <material  name="red" />
   <geometry >
    <cylinder  length="0.05"  radius="0.1" />
   </geometry>
  </visual>
 </link>
 <joint  type="revolute"  name="joint1" >
  <parent  link="base_link" />
  <child  link="link1" />
  <origin  xyz="0 0 0"  rpy="0 0 0" />
  <axis  xyz="0 0 1" />
 </joint>
 <link  name="link1" >
  <inertial >
   <origin  xyz="0 0 0.03412845061973724"  rpy="0 0 0" />
   <mass  value="0.7166974630144821" />
   <inertia  ixz="0.0"  ixy="0.0"  izz="0.0008755059486128572"  iyy="0.0011944957716908038"  ixx="0.0008755059486128572"  iyz="0.0" />
  </inertial>
  <visual >
   <origin  xyz="0 0 0.03412845061973724"  rpy="0 0 0" />
   <material  name="blue" />
   <geometry >
    <box  size="0.05 0.1 0.06825690123947448" />
   </geometry>
  </visual>
 </link>
 <joint  type="fixed"  name="joint-joint-1" >
  <parent  link="link1" />
  <child  link="joint-link-1" />
  <origin  xyz="0 0 0.06825690123947448"  rpy="1.5707 0 0" />
  <axis  xyz="1 0 0" />
 </joint>
 <link  name="joint-link-1" >
  <inertial >
   <origin  xyz="0 0 0"  rpy="0 0 0" />
   <mass  value="0.8332473971941174" />
   <inertia  ixz="0"  ixy="0"  izz="0"  iyy="0"  ixx="0"  iyz="0" />
  </inertial>
  <visual >
   <origin  xyz="0 0 0"  rpy="0 0 0" />
   <material  name="red" />
   <geometry >
    <sphere  radius="0.05" />
   </geometry>
  </visual>
 </link>
 <joint  type="revolute"  name="joint2" >
  <parent  link="link1" />
  <child  link="link2" />
  <origin  xyz="0 0 0.06825690123947448"  rpy="1.5707 0 0" />
  <axis  xyz="1 0 0" />
 </joint>
 <link  name="link2" >
  <inertial >
   <origin  xyz="0 0 0.013441497541135468"  rpy="0 0 0" />
   <mass  value="0.2822714483638449" />
   <inertia  ixz="0.0"  ixy="0.0"  izz="0.0006404107172902574"  iyy="0.0011944957716908038"  ixx="0.0006404107172902574"  iyz="0.0" />
  </inertial>
  <visual >
   <origin  xyz="0 0 0.013441497541135468"  rpy="0 0 0" />
   <material  name="blue" />
   <geometry >
    <box  size="0.05 0.1 0.026882995082270936" />
   </geometry>
  </visual>
 </link>
 <joint  type="fixed"  name="joint-joint-2" >
  <parent  link="link2" />
  <child  link="joint-link-2" />
  <origin  xyz="0 0 0.026882995082270936"  rpy="1.5707 0 0" />
  <axis  xyz="1 0 0" />
 </joint>
 <link  name="joint-link-2" >
  <inertial >
   <origin  xyz="0 0 0"  rpy="0 0 0" />
   <mass  value="0.8332473971941174" />
   <inertia  ixz="0"  ixy="0"  izz="0"  iyy="0"  ixx="0"  iyz="0" />
  </inertial>
  <visual >
   <origin  xyz="0 0 0"  rpy="0 0 0" />
   <material  name="red" />
   <geometry >
    <sphere  radius="0.05" />
   </geometry>
  </visual>
 </link>
 <joint  type="revolute"  name="joint3" >
  <parent  link="link2" />
  <child  link="link3" />
  <origin  xyz="0 0 0.026882995082270936"  rpy="0 0 0" />
  <axis  xyz="0 0 1" />
 </joint>
 <link  name="link3" >
  <inertial >
   <origin  xyz="0 0 0.0071589596197291685"  rpy="0 0 0" />
   <mass  value="0.15033815201431255" />
   <inertia  ixz="0.0"  ixy="0.0"  izz="0.0006094916354123767"  iyy="0.0011944957716908038"  ixx="0.0006094916354123767"  iyz="0.0" />
  </inertial>
  <visual >
   <origin  xyz="0 0 0.0071589596197291685"  rpy="0 0 0" />
   <material  name="blue" />
   <geometry >
    <box  size="0.05 0.1 0.014317919239458337" />
   </geometry>
  </visual>
 </link>
 <joint  type="fixed"  name="joint-joint-3" >
  <parent  link="link3" />
  <child  link="joint-link-3" />
  <origin  xyz="0 0 0.014317919239458337"  rpy="1.5707 0 0" />
  <axis  xyz="1 0 0" />
 </joint>
 <link  name="joint-link-3" >
  <inertial >
   <origin  xyz="0 0 0"  rpy="0 0 0" />
   <mass  value="0.8332473971941174" />
   <inertia  ixz="0"  ixy="0"  izz="0"  iyy="0"  ixx="0"  iyz="0" />
  </inertial>
  <visual >
   <origin  xyz="0 0 0"  rpy="0 0 0" />
   <material  name="red" />
   <geometry >
    <sphere  radius="0.05" />
   </geometry>
  </visual>
 </link>
 <joint  type="revolute"  name="joint4" >
  <parent  link="link3" />
  <child  link="link4" />
  <origin  xyz="0 0 0.014317919239458337"  rpy="0 0 0" />
  <axis  xyz="0 1 0" />
 </joint>
 <link  name="link4" >
  <inertial >
   <origin  xyz="0 0 0.10172197359446059"  rpy="0 0 0" />
   <mass  value="2.1361614454836726" />
   <inertia  ixz="0.0"  ixy="0.0"  izz="0.003069223418443352"  iyy="0.0011944957716908038"  ixx="0.003069223418443352"  iyz="0.0" />
  </inertial>
  <visual >
   <origin  xyz="0 0 0.10172197359446059"  rpy="0 0 0" />
   <material  name="blue" />
   <geometry >
    <box  size="0.05 0.1 0.20344394718892117" />
   </geometry>
  </visual>
 </link>
 <joint  type="fixed"  name="joint-joint-4" >
  <parent  link="link4" />
  <child  link="joint-link-4" />
  <origin  xyz="0 0 0.20344394718892117"  rpy="1.5707 0 0" />
  <axis  xyz="1 0 0" />
 </joint>
 <link  name="joint-link-4" >
  <inertial >
   <origin  xyz="0 0 0"  rpy="0 0 0" />
   <mass  value="0.8332473971941174" />
   <inertia  ixz="0"  ixy="0"  izz="0"  iyy="0"  ixx="0"  iyz="0" />
  </inertial>
  <visual >
   <origin  xyz="0 0 0"  rpy="0 0 0" />
   <material  name="red" />
   <geometry >
    <sphere  radius="0.05" />
   </geometry>
  </visual>
 </link>
 <joint  type="revolute"  name="joint5" >
  <parent  link="link4" />
  <child  link="link5" />
  <origin  xyz="0 0 0.20344394718892117"  rpy="0 0 0" />
  <axis  xyz="0 0 1" />
 </joint>
 <link  name="link5" >
  <inertial >
   <origin  xyz="0 0 0.011207129850475018"  rpy="0 0 0" />
   <mass  value="0.23534972685997543" />
   <inertia  ixz="0.0"  ixy="0.0"  izz="0.0006272535621715423"  iyy="0.0011944957716908038"  ixx="0.0006272535621715423"  iyz="0.0" />
  </inertial>
  <visual >
   <origin  xyz="0 0 0.011207129850475018"  rpy="0 0 0" />
   <material  name="blue" />
   <geometry >
    <box  size="0.05 0.1 0.022414259700950036" />
   </geometry>
  </visual>
 </link>
 <joint  type="fixed"  name="joint-joint-5" >
  <parent  link="link5" />
  <child  link="joint-link-5" />
  <origin  xyz="0 0 0.022414259700950036"  rpy="1.5707 0 0" />
  <axis  xyz="1 0 0" />
 </joint>
 <link  name="joint-link-5" >
  <inertial >
   <origin  xyz="0 0 0"  rpy="0 0 0" />
   <mass  value="0.8332473971941174" />
   <inertia  ixz="0"  ixy="0"  izz="0"  iyy="0"  ixx="0"  iyz="0" />
  </inertial>
  <visual >
   <origin  xyz="0 0 0"  rpy="0 0 0" />
   <material  name="red" />
   <geometry >
    <sphere  radius="0.05" />
   </geometry>
  </visual>
 </link>
 <joint  type="revolute"  name="joint6" >
  <parent  link="link5" />
  <child  link="link6" />
  <origin  xyz="0 0 0.022414259700950036"  rpy="0 0 0" />
  <axis  xyz="0 1 0" />
 </joint>
 <link  name="link6" >
  <inertial >
   <origin  xyz="0 0 0.0005"  rpy="0 0 0" />
   <mass  value="0.010500000000000002" />
   <inertia  ixz="0.0"  ixy="0.0"  izz="0.0005973076106339863"  iyy="0.0011944957716908038"  ixx="0.0005973076106339863"  iyz="0.0" />
  </inertial>
  <visual >
   <origin  xyz="0 0 0.0005"  rpy="0 0 0" />
   <material  name="blue" />
   <geometry >
    <box  size="0.05 0.1 0.001" />
   </geometry>
  </visual>
 </link>
 <joint  type="revolute"  name="joint7" >
  <parent  link="link6" />
  <child  link="link7" />
  <origin  xyz="0 0 0.001"  rpy="0 0 0" />
  <axis  xyz="1 0 0" />
 </joint>
 <link  name="link7" >
  <inertial >
   <origin  xyz="0 0 0.2126151482200836"  rpy="0 0 0" />
   <mass  value="4.464918112621756" />
   <inertia  ixz="0.0"  ixy="0.0"  izz="0.0113967322367894"  iyy="0.0011944957716908038"  ixx="0.0113967322367894"  iyz="0.0" />
  </inertial>
  <visual >
   <origin  xyz="0 0 0.2126151482200836"  rpy="0 0 0" />
   <material  name="blue" />
   <geometry >
    <box  size="0.05 0.1 0.4252302964401672" />
   </geometry>
  </visual>
 </link>
 <joint  type="fixed"  name="eef_joint" >
  <parent  link="link7" />
  <child  link="eef" />
  <origin  xyz="0 0 0.4252302964401672"  rpy="0 0 0" />
 </joint>
 <link  name="eef" >
  <inertial >
   <origin  xyz="0 0 0"  rpy="0 0 0" />
   <mass  value="1" />
   <inertia  ixz="0"  ixy="0"  izz="0"  iyy="0"  ixx="0"  iyz="0" />
  </inertial>
 </link>
 <transmission  name="motor1" >
  <type  xmltext="SimpleTransmission" >
   SimpleTransmission
  </type>
  <actuator  name="motor1" >
   <mechanicalreduction  xmltext="1" >
    1
   </mechanicalreduction>
  </actuator>
  <joint  name="joint1" />
 </transmission>
 <transmission  name="motor2" >
  <type  xmltext="SimpleTransmission" >
   SimpleTransmission
  </type>
  <actuator  name="motor2" >
   <mechanicalreduction  xmltext="1" >
    1
   </mechanicalreduction>
  </actuator>
  <joint  name="joint2" />
 </transmission>
 <transmission  name="motor3" >
  <type  xmltext="SimpleTransmission" >
   SimpleTransmission
  </type>
  <actuator  name="motor3" >
   <mechanicalreduction  xmltext="1" >
    1
   </mechanicalreduction>
  </actuator>
  <joint  name="joint3" />
 </transmission>
 <transmission  name="motor4" >
  <type  xmltext="SimpleTransmission" >
   SimpleTransmission
  </type>
  <actuator  name="motor4" >
   <mechanicalreduction  xmltext="1" >
    1
   </mechanicalreduction>
  </actuator>
  <joint  name="joint4" />
 </transmission>
 <transmission  name="motor5" >
  <type  xmltext="SimpleTransmission" >
   SimpleTransmission
  </type>
  <actuator  name="motor5" >
   <mechanicalreduction  xmltext="1" >
    1
   </mechanicalreduction>
  </actuator>
  <joint  name="joint5" />
 </transmission>
 <transmission  name="motor6" >
  <type  xmltext="SimpleTransmission" >
   SimpleTransmission
  </type>
  <actuator  name="motor6" >
   <mechanicalreduction  xmltext="1" >
    1
   </mechanicalreduction>
  </actuator>
  <joint  name="joint6" />
 </transmission>
 <transmission  name="motor7" >
  <type  xmltext="SimpleTransmission" >
   SimpleTransmission
  </type>
  <actuator  name="motor7" >
   <mechanicalreduction  xmltext="1" >
    1
   </mechanicalreduction>
  </actuator>
  <joint  name="joint7" />
 </transmission>
</robot>

<!-- {'carti': array([-0.53,  0.13,  0.81]), 'cartd': array([-0.23,  0.24,  1.03]), 'tau_mu': 0.00768963446692655, 'b0': 0.004337208913475676, 'Km': 0.7774334796506989, 'k_velocity': 39.65893327105037, 'tau_max_m': 1.1850650035108838, 'omega_max_m': 1945.8681893167607, 'gear_ratio': 18.21793810419634, 'Kp': 30.1382421816784, 'Kd': 84.60181528486508, 'm_m': 0.8332473971941174, 'a1': 0.06825690123947448, 'lua': 0.04120091432172927, 'a23_distr': 0.6524854005022142, 'lfa': 0.2258582068898712, 'a45_distr': 0.9007595959890036, 'a7': 0.4252302964401672}-->